Workbook

Sheet 打印界面
A1: 鞋城商铺缴费收据 | K1: 1
A2: 租金期间:2026.1.1-2026.1.31 | G2: =IFERROR(VLOOKUP(K1,'2026.01'!A:Y,2,0),0) -> NO:001
A3: 铺号 | B3: =IFERROR(VLOOKUP(K1,'2026.01'!A:Y,6,0),0) -> 1001-01（临一） | D3: 铺主 | E3: =IFERROR(VLOOKUP(K1,'2026.01'!A:Y,7,0),0) -> 何具达 | G3: 备注
A4: 项目 | B4: 本月读数 | C4: 上月读数 | D4: 本月用量 | E4: 单价 | F4: 本月金额 | G4: 请各商户于当月10日前到管理处交费及换单。如有疑问，请致电：020-22250555
A5: 电费 | B5: =IFERROR(VLOOKUP(K1,'2026.01'!A:Y,14,0),0) -> 21255 | C5: =IFERROR(VLOOKUP(K1,'2026.01'!A:Y,13,0),0) -> 21125 | D5: =IFERROR(VLOOKUP(K1,'2026.01'!A:Y,15,0),0) -> 130 | E5: =IFERROR(VLOOKUP(K1,'2026.01'!A:Y,18,0),0) -> 0.8 | F5: =IFERROR(VLOOKUP(K1,'2026.01'!A:Y,20,0),0) -> 104
A6: 水费 | F6: =IFERROR(VLOOKUP(K1,'2026.01'!A:Y,24,0),0) -> 34
A7: 垃圾费 | F7: =IFERROR(VLOOKUP(K1,'2026.01'!A:Y,12,0),0) -> 160
A8: 租金 | F8: =IFERROR(VLOOKUP(K1,'2026.01'!A:Y,9,0),0) -> 3052
A9: 管理费 | F9: =IFERROR(VLOOKUP(K1,'2026.01'!A:Y,10,0),0) -> 210
A10: 管理费（设施服务费1） | F10: =IFERROR(VLOOKUP(K1,'2026.01'!A:Y,19,0),0) -> 91
A11: 管理费（设施服务费2） | F11: =IFERROR(VLOOKUP(K1,'2026.01'!A:Y,22,0),0) -> 164
A12: 应交合计 | F12: =IFERROR(VLOOKUP(K1,'2026.01'!A:Y,25,0),0) -> 3815
A13: 金额大写 | B13: =IF(F12<0,"金额为负，无效",INT(F12)) -> 3815 | E13: 收款人
A15: 鞋城商铺缴费收据 | K15: 2
A16: 租金期间:2026.1.1-2026.1.31 | G16: =IFERROR(VLOOKUP(K15,'2026.01'!A:Y,2,0),0) -> NO:002
A17: 铺号 | B17: =IFERROR(VLOOKUP(K15,'2026.01'!A:Y,6,0),0) -> 1001 | D17: 铺主 | E17: =IFERROR(VLOOKUP(K15,'2026.01'!A:Y,7,0),0) -> 邓凤强 | G17: 备注
A18: 项目 | B18: 本月读数 | C18: 上月读数 | D18: 本月用量 | E18: 单价 | F18: 本月金额 | G18: 请各商户于当月10日前到管理处交费及换单。如有疑问，请致电：020-22250555
A19: 电费 | B19: =IFERROR(VLOOKUP(K15,'2026.01'!A:Y,14,0),0) -> 5545 | C19: =IFERROR(VLOOKUP(K15,'2026.01'!A:Y,13,0),0) -> 5427 | D19: =IFERROR(VLOOKUP(K15,'2026.01'!A:Y,15,0),0) -> 118 | E19: =IFERROR(VLOOKUP(K15,'2026.01'!A:Y,18,0),0) -> 0.8 | F19: =IFERROR(VLOOKUP(K15,'2026.01'!A:Y,20,0),0) -> 94
A20: 水费 | F20: =IFERROR(VLOOKUP(K15,'2026.01'!A:Y,24,0),0) -> 34
A21: 垃圾费 | F21: =IFERROR(VLOOKUP(K15,'2026.01'!A:Y,12,0),0) -> 160
A22: 租金 | F22: =IFERROR(VLOOKUP(K15,'2026.01'!A:Y,9,0),0) -> 4200
A23: 管理费 | F23: =IFERROR(VLOOKUP(K15,'2026.01'!A:Y,10,0),0) -> 500
A24: 管理费（设施服务费1） | F24: =IFERROR(VLOOKUP(K15,'2026.01'!A:Y,19,0),0) -> 83
A25: 管理费（设施服务费2） | F25: =IFERROR(VLOOKUP(K15,'2026.01'!A:Y,22,0),0) -> 183
A26: 应交合计 | F26: =IFERROR(VLOOKUP(K15,'2026.01'!A:Y,25,0),0) -> 5254
A27: 金额大写 | B27: =IF(F26<0,"金额为负，无效",INT(F26)) -> 5254 | E27: 收款人
A29: 鞋城商铺缴费收据 | K29: 3
A30: 租金期间:2026.1.1-2026.1.31 | G30: =IFERROR(VLOOKUP(K29,'2026.01'!A:Y,2,0),0) -> NO:003
A31: 铺号 | B31: =IFERROR(VLOOKUP(K29,'2026.01'!A:Y,6,0),0) -> 1002 | D31: 铺主 | E31: =IFERROR(VLOOKUP(K29,'2026.01'!A:Y,7,0),0) -> 苏建柳 | G31: 备注
A32: 项目 | B32: 本月读数 | C32: 上月读数 | D32: 本月用量 | E32: 单价 | F32: 本月金额 | G32: 请各商户于当月10日前到管理处交费及换单。如有疑问，请致电：020-22250555
A33: 电费 | B33: =IFERROR(VLOOKUP(K29,'2026.01'!A:Y,14,0),0) -> 8503 | C33: =IFERROR(VLOOKUP(K29,'2026.01'!A:Y,13,0),0) -> 8496 | D33: =IFERROR(VLOOKUP(K29,'2026.01'!A:Y,15,0),0) -> 7 | E33: =IFERROR(VLOOKUP(K29,'2026.01'!A:Y,18,0),0) -> 0.8 | F33: =IFERROR(VLOOKUP(K29,'2026.01'!A:Y,20,0),0) -> 6
A34: 水费 | F34: =IFERROR(VLOOKUP(K29,'2026.01'!A:Y,24,0),0) -> 34
A35: 垃圾费 | F35: =IFERROR(VLOOKUP(K29,'2026.01'!A:Y,12,0),0) -> 160
A36: 租金 | F36: =IFERROR(VLOOKUP(K29,'2026.01'!A:Y,9,0),0) -> 1500
A37: 管理费 | F37: =IFERROR(VLOOKUP(K29,'2026.01'!A:Y,10,0),0) -> 0
A38: 管理费（设施服务费1） | F38: =IFERROR(VLOOKUP(K29,'2026.01'!A:Y,19,0),0) -> 5
A39: 管理费（设施服务费2） | F39: =IFERROR(VLOOKUP(K29,'2026.01'!A:Y,22,0),0) -> 183
A40: 应交合计 | F40: =IFERROR(VLOOKUP(K29,'2026.01'!A:Y,25,0),0) -> 1888
A41: 金额大写 | B41: =IF(F40<0,"金额为负，无效",INT(F40)) -> 1888 | E41: 收款人
A43: 鞋城商铺缴费收据 | K43: 4
...

Sheet 2026.01
A1: 国大鞋城2026年1月份收费明细表 | M1: 1 2 3楼有中央空调 要分摊电费 | N1: 1 2 3楼有中央空调 要分摊电费
B2: 序号 | C2: 楼层 | F2: 档口号 | G2: 商户名 | H2: 面积 | I2: 租金 | J2: 管理费 | M2: 上月电表读数 | N2: 本月电表读数 | O2: 用电量 | P2: 电费分摊 | Q2: 本月用电 | R2: 电费单价 | S2: 市场服务费 | T2: 用电金额 | U2: 照明+空调公摊 | V2: 金额 | W2: 水费公摊 | X2: 水费 | Y2: 本月合计 | Z2: 前期欠款 | AA2: 折扣金额 | AE2: 预交款 | AI2: 应交合计 | AJ2: 滞纳金 | AK2: 实收款 | AQ2: 其他折扣 | AV2: 未交金额
D3: 档口 | E3: 面积 | K3: 租金及管理费 | L3: 垃圾费 | AA3: 租金 | AB3: 管理费 | AC3: 水电费 | AD3: 小计 | AE3: 期初 | AF3: 本月预收 | AG3: 本月抵扣 | AH3: 期末（剩余未抵） | AK3: 收款日期 | AL3: 现金 | AM3: 微信 | AN3: 银行 | AO3: 建行 | AP3: 小计 | AQ3: 协议减免 | AR3: 租金折扣 | AS3: 空调折扣 | AT3: 押金抵扣 | AU3: 小计 | AW3: 备注
A4: =SUBTOTAL(2,$Y$4:Y4) -> 1 | B4: NO:001 | C4: 一楼商铺 | D4: 1001-01（临一） | E4: 19.5 | F4: 1001-01（临一） | G4: 何具达 | H4: =E4 -> 19.5 | I4: 3052 | J4: 210 | K4: =I4+J4 -> 3262 | L4: 160 | M4: 21125 | N4: 21255 | O4: =N4-M4 -> 130 | P4: =ROUND(H4*0,0) -> 0 | Q4: =O4+P4 -> 130 | R4: 0.8 | S4: =ROUND(Q4*0.7,0) -> 91 | T4: =ROUND(Q4*R4,0) -> 104 | U4: =ROUND(H4*5.6,0) -> 109 | V4: =ROUND(U4*1.5,0) -> 164 | W4: =ROUND(H4*0.2,0) -> 4 | X4: =ROUND(W4*8.5,0) -> 34 | Y4: =I4+J4+L4+S4+T4+V4+X4 -> 3815 | AD4: =AA4+AB4+AC4 -> 0 | AH4: =AE4+AF4-AG4 -> 0 | AI4: =Y4+Z4+AJ4-AD4-AG4 -> 3815 | AP4: =AL4+AN4+AM4+AO4 -> 0 | AU4: =SUM(AQ4:AT4) -> 0 | AV4: =AI4-AP4-AU4 -> 3815
A5: =SUBTOTAL(2,$Y$4:Y5) -> 2 | B5: NO:002 | C5: 一楼商铺 | D5: 1001 | E5: 21.87 | F5: 1001 | G5: 邓凤强 | H5: =E5 -> 21.87 | I5: 4200 | J5: 500 | K5: =I5+J5 -> 4700 | L5: 160 | M5: 5427 | N5: 5545 | O5: =N5-M5 -> 118 | P5: =ROUND(H5*0,0) -> 0 | Q5: =O5+P5 -> 118 | R5: 0.8 | S5: =ROUND(Q5*0.7,0) -> 83 | T5: =ROUND(Q5*R5,0) -> 94 | U5: =ROUND(H5*5.6,0) -> 122 | V5: =ROUND(U5*1.5,0) -> 183 | W5: =ROUND(H5*0.2,0) -> 4 | X5: =ROUND(W5*8.5,0) -> 34 | Y5: =I5+J5+L5+S5+T5+V5+X5 -> 5254 | AD5: =AA5+AB5+AC5 -> 0 | AH5: =AE5+AF5-AG5 -> 0 | AI5: =Y5+Z5+AJ5-AD5-AG5 -> 5254 | AP5: =AL5+AN5+AM5+AO5 -> 0 | AU5: =SUM(AQ5:AT5) -> 0 | AV5: =AI5-AP5-AU5 -> 5254
A6: =SUBTOTAL(2,$Y$4:Y6) -> 3 | B6: NO:003 | C6: 一楼商铺 | D6: 1002 | E6: 21.87 | F6: 1002 | G6: 苏建柳 | H6: =E6 -> 21.87 | I6: 1500 | K6: =I6+J6 -> 1500 | L6: 160 | M6: 8496 | N6: 8503 | O6: =N6-M6 -> 7 | P6: =ROUND(H6*0,0) -> 0 | Q6: =O6+P6 -> 7 | R6: 0.8 | S6: =ROUND(Q6*0.7,0) -> 5 | T6: =ROUND(Q6*R6,0) -> 6 | U6: =ROUND(H6*5.6,0) -> 122 | V6: =ROUND(U6*1.5,0) -> 183 | W6: =ROUND(H6*0.2,0) -> 4 | X6: =ROUND(W6*8.5,0) -> 34 | Y6: =I6+J6+L6+S6+T6+V6+X6 -> 1888 | AD6: =AA6+AB6+AC6 -> 0 | AH6: =AE6+AF6-AG6 -> 0 | AI6: =Y6+Z6+AJ6-AD6-AG6 -> 1888 | AP6: =AL6+AN6+AM6+AO6 -> 0 | AU6: =SUM(AQ6:AT6) -> 0 | AV6: =AI6-AP6-AU6 -> 1888
A7: =SUBTOTAL(2,$Y$4:Y7) -> 4 | B7: NO:004 | C7: 一楼商铺 | D7: 1003-1004 | E7: =21.87+27.15 -> 49.02 | F7: 1003/1004 | G7: 李鹏飞 | H7: 49.02 | I7: 3000 | K7: =I7+J7 -> 3000 | L7: 320 | M7: =7009+9610 -> 16619 | N7: =7029+9610 -> 16639 | O7: =N7-M7 -> 20 | P7: =ROUND(H7*0,0) -> 0 | Q7: =O7+P7 -> 20 | R7: 0.8 | S7: =ROUND(Q7*0.7,0) -> 14 | T7: =ROUND(Q7*R7,0) -> 16 | U7: =ROUND(H7*5.6,0) -> 275 | V7: =ROUND(U7*1.5,0) -> 413 | W7: =ROUND(H7*0.2,0) -> 10 | X7: =ROUND(W7*8.5,0) -> 85 | Y7: =I7+J7+L7+S7+T7+V7+X7 -> 3848 | AD7: =AA7+AB7+AC7 -> 0 | AH7: =AE7+AF7-AG7 -> 0 | AI7: =Y7+Z7+AJ7-AD7-AG7 -> 3848 | AP7: =AL7+AN7+AM7+AO7 -> 0 | AU7: =SUM(AQ7:AT7) -> 0 | AV7: =AI7-AP7-AU7 -> 3848
A8: =SUBTOTAL(2,$Y$4:Y8) -> 5 | B8: NO:005 | C8: 一楼商铺 | D8: 1005 | E8: 27.15 | F8: 1005 | G8: 黄腾凌 | H8: 27.15 | I8: 1200 | J8: 200 | K8: =I8+J8 -> 1400 | L8: 160 | M8: 3318 | N8: 3354 | O8: =N8-M8 -> 36 | P8: =ROUND(H8*0,0) -> 0 | Q8: =O8+P8 -> 36 | R8: 0.8 | S8: =ROUND(Q8*0.7,0) -> 25 | T8: =ROUND(Q8*R8,0) -> 29 | U8: =ROUND(H8*5.6,0) -> 152 | V8: =ROUND(U8*1.5,0) -> 228 | W8: =ROUND(H8*0.2,0) -> 5 | X8: =ROUND(W8*8.5,0) -> 43 | Y8: =I8+J8+L8+S8+T8+V8+X8 -> 1885 | AD8: =AA8+AB8+AC8 -> 0 | AH8: =AE8+AF8-AG8 -> 0 | AI8: =Y8+Z8+AJ8-AD8-AG8 -> 1885 | AP8: =AL8+AN8+AM8+AO8 -> 0 | AU8: =SUM(AQ8:AT8) -> 0 | AV8: =AI8-AP8-AU8 -> 1885
A9: =SUBTOTAL(2,$Y$4:Y9) -> 6 | B9: NO:006 | C9: 一楼商铺 | D9: 1006 | E9: 27.15 | F9: 1006 | G9: 刘展 | H9: 27.15 | I9: 1200 | J9: 200 | K9: =I9+J9 -> 1400 | L9: 160 | M9: 4555 | N9: 4587 | O9: =N9-M9 -> 32 | P9: =ROUND(H9*0,0) -> 0 | Q9: =O9+P9 -> 32 | R9: 0.8 | S9: =ROUND(Q9*0.7,0) -> 22 | T9: =ROUND(Q9*R9,0) -> 26 | U9: =ROUND(H9*5.6,0) -> 152 | V9: =ROUND(U9*1.5,0) -> 228 | W9: 0 | X9: =ROUND(W9*8.5,0) -> 0 | Y9: =I9+J9+L9+S9+T9+V9+X9 -> 1836 | AD9: =AA9+AB9+AC9 -> 0 | AH9: =AE9+AF9-AG9 -> 0 | AI9: =Y9+Z9+AJ9-AD9-AG9 -> 1836 | AP9: =AL9+AN9+AM9+AO9 -> 0 | AU9: =SUM(AQ9:AT9) -> 0 | AV9: =AI9-AP9-AU9 -> 1836
A10: =SUBTOTAL(2,$Y$4:Y10) -> 7 | B10: NO:007 | C10: 一楼商铺 | D10: 1007 | E10: 27.15 | F10: 1007 | G10: 王正庚 | H10: =E10 -> 27.15 | I10: 1200 | K10: =I10+J10 -> 1200 | L10: 160 | M10: 759 | N10: 765 | O10: =N10-M10 -> 6 | P10: =ROUND(H10*0,0) -> 0 | Q10: =O10+P10 -> 6 | R10: 0.8 | S10: =ROUND(Q10*0.7,0) -> 4 | T10: =ROUND(Q10*R10,0) -> 5 | U10: =ROUND(H10*5.6,0) -> 152 | V10: =ROUND(U10*1.5,0) -> 228 | W10: =ROUND(H10*0.2,0) -> 5 | X10: =ROUND(W10*8.5,0) -> 43 | Y10: =I10+J10+L10+S10+T10+V10+X10 -> 1640 | AD10: =AA10+AB10+AC10 -> 0 | AH10: =AE10+AF10-AG10 -> 0 | AI10: =Y10+Z10+AJ10-AD10-AG10 -> 1640 | AP10: =AL10+AN10+AM10+AO10 -> 0 | AU10: =SUM(AQ10:AT10) -> 0 | AV10: =AI10-AP10-AU10 -> 1640
A11: =SUBTOTAL(2,$Y$4:Y11) -> 8 | B11: NO:008 | C11: 一楼商铺 | D11: 1008 | E11: 27.15 | F11: 1008/1009 | G11: 潭日标 | H11: =E11*2 -> 54.3 | I11: 2500 | K11: =I11+J11 -> 2500 | L11: 320 | M11: 3460 | N11: 3682 | O11: =N11-M11 -> 222 | P11: =ROUND(H11*0,0) -> 0 | Q11: =O11+P11 -> 222 | R11: 0.8 | S11: =ROUND(Q11*0.7,0) -> 155 | T11: =ROUND(Q11*R11,0) -> 178 | U11: =ROUND(H11*0,0) -> 0 | V11: =ROUND(U11*1.5,0) -> 0 | W11: =ROUND(H11*0.2,0) -> 11 | X11: =ROUND(W11*8.5,0) -> 94 | Y11: =I11+J11+L11+S11+T11+V11+X11 -> 3247 | AD11: =AA11+AB11+AC11 -> 0 | AH11: =AE11+AF11-AG11 -> 0 | AI11: =Y11+Z11+AJ11-AD11-AG11 -> 3247 | AP11: =AL11+AN11+AM11+AO11 -> 0 | AU11: =SUM(AQ11:AT11) -> 0 | AV11: =AI11-AP11-AU11 -> 3247
A12: =SUBTOTAL(2,$Y$4:Y12) -> 9 | B12: NO:009 | C12: 一楼商铺 | D12: 1009 | E12: 27.15 | F12: 1009 | G12: 潭日标 | K12: =I12+J12 -> 0 | L12: 0 | M12: 3552 | N12: 3625 | O12: =N12-M12 -> 73 | P12: =ROUND(H12*0,0) -> 0 | Q12: =O12+P12 -> 73 | R12: 0.8 | S12: =ROUND(Q12*0.7,0) -> 51 | T12: =ROUND(Q12*R12,0) -> 58 | U12: =ROUND(H12*5.6,0) -> 0 | V12: =ROUND(U12*1.5,0) -> 0 | W12: =ROUND(H12*0.2,0) -> 0 | X12: =ROUND(W12*8.5,0) -> 0 | Y12: =I12+J12+L12+S12+T12+V12+X12 -> 109 | AD12: =AA12+AB12+AC12 -> 0 | AH12: =AE12+AF12-AG12 -> 0 | AI12: =Y12+Z12+AJ12-AD12-AG12 -> 109 | AP12: =AL12+AN12+AM12+AO12 -> 0 | AU12: =SUM(AQ12:AT12) -> 0 | AV12: =AI12-AP12-AU12 -> 109
A13: =SUBTOTAL(2,$Y$4:Y13) -> 10 | B13: NO:010 | C13: 一楼商铺 | D13: 1010 | E13: 23.77 | F13: 1010 | G13: 王长梅 | H13: =E13 -> 23.77 | I13: 1500 | K13: =I13+J13 -> 1500 | L13: 160 | M13: 8464 | N13: 8551 | O13: =N13-M13 -> 87 | P13: =ROUND(H13*0,0) -> 0 | Q13: =O13+P13 -> 87 | R13: 0.8 | S13: =ROUND(Q13*0.7,0) -> 61 | T13: =ROUND(Q13*R13,0) -> 70 | U13: =ROUND(H13*5.6,0) -> 133 | V13: =ROUND(U13*1.5,0) -> 200 | W13: =ROUND(H13*0.2,0) -> 5 | X13: =ROUND(W13*8.5,0) -> 43 | Y13: =I13+J13+L13+S13+T13+V13+X13 -> 2034 | AD13: =AA13+AB13+AC13 -> 0 | AH13: =AE13+AF13-AG13 -> 0 | AI13: =Y13+Z13+AJ13-AD13-AG13 -> 2034 | AP13: =AL13+AN13+AM13+AO13 -> 0 | AU13: =SUM(AQ13:AT13) -> 0 | AV13: =AI13-AP13-AU13 -> 2034
A14: =SUBTOTAL(2,$Y$4:Y14) -> 11 | B14: NO:011 | C14: 一楼商铺 | D14: 1011 | E14: 27.15 | F14: 1011 | G14: 段邦彦 | H14: 27.15 | I14: 750 | K14: =I14+J14 -> 750 | L14: 160 | M14: 2210 | N14: 2260 | O14: =N14-M14 -> 50 | P14: =ROUND(H14*0,0) -> 0 | Q14: =O14+P14 -> 50 | R14: 0.8 | S14: =ROUND(Q14*0.7,0) -> 35 | T14: =ROUND(Q14*R14,0) -> 40 | U14: =ROUND(H14*0,0) -> 0 | V14: =ROUND(U14*1.5,0) -> 0 | W14: =ROUND(H14*0.2,0) -> 5 | X14: =ROUND(W14*8.5,0) -> 43 | Y14: =I14+J14+L14+S14+T14+V14+X14 -> 1028 | AD14: =AA14+AB14+AC14 -> 0 | AH14: =AE14+AF14-AG14 -> 0 | AI14: =Y14+Z14+AJ14-AD14-AG14 -> 1028 | AP14: =AL14+AN14+AM14+AO14 -> 0 | AU14: =SUM(AQ14:AT14) -> 0 | AV14: =AI14-AP14-AU14 -> 1028
A15: =SUBTOTAL(2,$Y$4:Y15) -> 12 | B15: NO:012 | C15: 一楼商铺 | D15: 1012 | E15: 27.5 | F15: 1012 | G15: 李文学 | H15: 27.5 | I15: 750 | J15: 0 | K15: =I15+J15 -> 750 | L15: 160 | M15: 2479 | N15: 2584 | O15: =N15-M15 -> 105 | P15: =ROUND(H15*0,0) -> 0 | Q15: =O15+P15 -> 105 | R15: 0.8 | S15: =ROUND(Q15*0.7,0) -> 74 | T15: =ROUND(Q15*R15,0) -> 84 | U15: =ROUND(H15*0,0) -> 0 | V15: =ROUND(U15*1.5,0) -> 0 | W15: =ROUND(H15*0.2,0) -> 6 | X15: =ROUND(W15*8.5,0) -> 51 | Y15: =I15+J15+L15+S15+T15+V15+X15 -> 1119 | AD15: =AA15+AB15+AC15 -> 0 | AH15: =AE15+AF15-AG15 -> 0 | AI15: =Y15+Z15+AJ15-AD15-AG15 -> 1119 | AP15: =AL15+AN15+AM15+AO15 -> 0 | AU15: =SUM(AQ15:AT15) -> 0 | AV15: =AI15-AP15-AU15 -> 1119
A16: =SUBTOTAL(2,$Y$4:Y16) -> 13 | B16: NO:013 | C16: 一楼商铺 | D16: 1013 | E16: 27.15 | F16: 1013 | G16: 揭英祥 | H16: =E16 -> 27.15 | I16: 1200 | K16: =I16+J16 -> 1200 | L16: 160 | M16: 4343 | N16: 4410 | O16: =N16-M16 -> 67 | P16: =ROUND(H16*0,0) -> 0 | Q16: =O16+P16 -> 67 | R16: 0.8 | S16: =ROUND(Q16*0.7,0) -> 47 | T16: =ROUND(Q16*R16,0) -> 54 | U16: =ROUND(H16*5.6,0) -> 152 | V16: =ROUND(U16*1.5,0) -> 228 | W16: =ROUND(H16*0.2,0) -> 5 | X16: =ROUND(W16*8.5,0) -> 43 | Y16: =I16+J16+L16+S16+T16+V16+X16 -> 1732 | AD16: =AA16+AB16+AC16 -> 0 | AH16: =AE16+AF16-AG16 -> 0 | AI16: =Y16+Z16+AJ16-AD16-AG16 -> 1732 | AP16: =AL16+AN16+AM16+AO16 -> 0 | AU16: =SUM(AQ16:AT16) -> 0 | AV16: =AI16-AP16-AU16 -> 1732
A17: =SUBTOTAL(2,$Y$4:Y17) -> 14 | B17: NO:014 | C17: 一楼商铺 | D17: 1014 | E17: 27.15 | F17: 1014 | G17: 陈文彬 | H17: 27.15 | I17: 1500 | J17: 0 | K17: =I17+J17 -> 1500 | L17: 160 | M17: 5894 | N17: 6102 | O17: =N17-M17 -> 208 | P17: =ROUND(H17*0,0) -> 0 | Q17: =O17+P17 -> 208 | R17: 0.8 | S17: =ROUND(Q17*0.7,0) -> 146 | T17: =ROUND(Q17*R17,0) -> 166 | U17: =ROUND(H17*5.6,0) -> 152 | V17: =ROUND(U17*1.5,0) -> 228 | W17: =ROUND(H17*0.2,0) -> 5 | X17: =ROUND(W17*8.5,0) -> 43 | Y17: =I17+J17+L17+S17+T17+V17+X17 -> 2243 | AD17: =AA17+AB17+AC17 -> 0 | AH17: =AE17+AF17-AG17 -> 0 | AI17: =Y17+Z17+AJ17-AD17-AG17 -> 2243 | AP17: =AL17+AN17+AM17+AO17 -> 0 | AU17: =SUM(AQ17:AT17) -> 0 | AV17: =AI17-AP17-AU17 -> 2243
A18: =SUBTOTAL(2,$Y$4:Y18) -> 15 | B18: NO:015 | C18: 一楼商铺 | D18: 1015 | E18: 27.15 | F18: 1015 | G18: 张平君 | H18: 27.15 | I18: 1200 | J18: 0 | K18: =I18+J18 -> 1200 | L18: 160 | M18: 5484 | N18: 5506 | O18: =N18-M18 -> 22 | P18: =ROUND(H18*0,0) -> 0 | Q18: =O18+P18 -> 22 | R18: 0.8 | S18: =ROUND(Q18*0.7,0) -> 15 | T18: =ROUND(Q18*R18,0) -> 18 | U18: =ROUND(H18*5.6,0) -> 152 | V18: =ROUND(U18*1.5,0) -> 228 | W18: =ROUND(H18*0.2,0) -> 5 | X18: =ROUND(W18*8.5,0) -> 43 | Y18: =I18+J18+L18+S18+T18+V18+X18 -> 1664 | AD18: =AA18+AB18+AC18 -> 0 | AH18: =AE18+AF18-AG18 -> 0 | AI18: =Y18+Z18+AJ18-AD18-AG18 -> 1664 | AP18: =AL18+AN18+AM18+AO18 -> 0 | AU18: =SUM(AQ18:AT18) -> 0 | AV18: =AI18-AP18-AU18 -> 1664
A19: =SUBTOTAL(2,$Y$4:Y19) -> 16 | B19: NO:016 | C19: 一楼商铺 | D19: 1016-1017 | E19: =27.15+27.5 -> 54.65 | F19: 1016/1017 | G19: 卢汉总 | H19: =E19 -> 54.65 | I19: 2800 | J19: 200 | K19: =I19+J19 -> 3000 | L19: 320 | M19: =5382+1645 -> 7027 | N19: =5413+1699 -> 7112 | O19: =N19-M19 -> 85 | P19: =ROUND(H19*0,0) -> 0 | Q19: =O19+P19 -> 85 | R19: 0.8 | S19: =ROUND(Q19*0.7,0) -> 60 | T19: =ROUND(Q19*R19,0) -> 68 | U19: =ROUND(H19*5.6,0) -> 306 | V19: =ROUND(U19*1.5,0) -> 459 | W19: =ROUND(H19*0.2,0) -> 11 | X19: =ROUND(W19*8.5,0) -> 94 | Y19: =I19+J19+L19+S19+T19+V19+X19 -> 4001 | AD19: =AA19+AB19+AC19 -> 0 | AH19: =AE19+AF19-AG19 -> 0 | AI19: =Y19+Z19+AJ19-AD19-AG19 -> 4001 | AP19: =AL19+AN19+AM19+AO19 -> 0 | AU19: =SUM(AQ19:AT19) -> 0 | AV19: =AI19-AP19-AU19 -> 4001
A20: =SUBTOTAL(2,$Y$4:Y20) -> 17 | B20: NO:017 | C20: 一楼商铺 | D20: 1018 | E20: 27.5 | F20: 1018 | G20: 白成滔 | H20: =E20 -> 27.5 | I20: 2000 | J20: 0 | K20: =I20+J20 -> 2000 | L20: 160 | M20: 4204 | N20: 4239 | O20: =N20-M20 -> 35 | P20: =ROUND(H20*0,0) -> 0 | Q20: =O20+P20 -> 35 | R20: 0.8 | S20: =ROUND(Q20*0.7,0) -> 25 | T20: =ROUND(Q20*R20,0) -> 28 | U20: =ROUND(H20*5.6,0) -> 154 | V20: =ROUND(U20*1.5,0) -> 231 | W20: =ROUND(H20*0.2,0) -> 6 | X20: =ROUND(W20*8.5,0) -> 51 | Y20: =I20+J20+L20+S20+T20+V20+X20 -> 2495 | AD20: =AA20+AB20+AC20 -> 0 | AH20: =AE20+AF20-AG20 -> 0 | AI20: =Y20+Z20+AJ20-AD20-AG20 -> 2495 | AP20: =AL20+AN20+AM20+AO20 -> 0 | AU20: =SUM(AQ20:AT20) -> 0 | AV20: =AI20-AP20-AU20 -> 2495
A21: =SUBTOTAL(2,$Y$4:Y21) -> 18 | B21: NO:018 | C21: 一楼商铺 | D21: 1019 | E21: 27.15 | F21: 1019 | G21: 王长梅 | H21: 27.15 | I21: 1200 | K21: =I21+J21 -> 1200 | L21: 160 | M21: 1623 | N21: 1634 | O21: =N21-M21 -> 11 | P21: =ROUND(H21*0,0) -> 0 | Q21: =O21+P21 -> 11 | R21: 0.8 | S21: =ROUND(Q21*0.7,0) -> 8 | T21: =ROUND(Q21*R21,0) -> 9 | U21: =ROUND(H21*5.6,0) -> 152 | V21: =ROUND(U21*1.5,0) -> 228 | W21: 5 | X21: =ROUND(W21*8.5,0) -> 43 | Y21: =I21+J21+L21+S21+T21+V21+X21 -> 1648 | AD21: =AA21+AB21+AC21 -> 0 | AH21: =AE21+AF21-AG21 -> 0 | AI21: =Y21+Z21+AJ21-AD21-AG21 -> 1648 | AP21: =AL21+AN21+AM21+AO21 -> 0 | AU21: =SUM(AQ21:AT21) -> 0 | AV21: =AI21-AP21-AU21 -> 1648
A22: =SUBTOTAL(2,$Y$4:Y22) -> 19 | B22: NO:019 | C22: 一楼商铺 | D22: 1020 | E22: 27.15 | F22: 1020 | G22: 张爱玲 | H22: =E22 -> 27.15 | I22: 1200 | J22: 0 | K22: =I22+J22 -> 1200 | L22: 160 | M22: 9421 | N22: 9455 | O22: =N22-M22 -> 34 | P22: =ROUND(H22*0,0) -> 0 | Q22: =O22+P22 -> 34 | R22: 0.8 | S22: =ROUND(Q22*0.7,0) -> 24 | T22: =ROUND(Q22*R22,0) -> 27 | U22: =ROUND(H22*5.6,0) -> 152 | V22: =ROUND(U22*1.5,0) -> 228 | W22: =ROUND(H22*0.2,0) -> 5 | X22: =ROUND(W22*8.5,0) -> 43 | Y22: =I22+J22+L22+S22+T22+V22+X22 -> 1682 | AD22: =AA22+AB22+AC22 -> 0 | AH22: =AE22+AF22-AG22 -> 0 | AI22: =Y22+Z22+AJ22-AD22-AG22 -> 1682 | AP22: =AL22+AN22+AM22+AO22 -> 0 | AU22: =SUM(AQ22:AT22) -> 0 | AV22: =AI22-AP22-AU22 -> 1682
A23: =SUBTOTAL(2,$Y$4:Y23) -> 20 | B23: NO:020 | C23: 一楼商铺 | D23: 1021 | E23: 27.15 | F23: 1021 | G23: 刘光全 | H23: =E23 -> 27.15 | I23: 1200 | J23: 200 | K23: =I23+J23 -> 1400 | L23: 160 | M23: 6380 | N23: 6424 | O23: =N23-M23 -> 44 | P23: =ROUND(H23*0,0) -> 0 | Q23: =O23+P23 -> 44 | R23: 0.8 | S23: =ROUND(Q23*0.7,0) -> 31 | T23: =ROUND(Q23*R23,0) -> 35 | U23: =ROUND(H23*5.6,0) -> 152 | V23: =ROUND(U23*1.5,0) -> 228 | W23: =ROUND(H23*0.2,0) -> 5 | X23: =ROUND(W23*8.5,0) -> 43 | Y23: =I23+J23+L23+S23+T23+V23+X23 -> 1897 | AD23: =AA23+AB23+AC23 -> 0 | AH23: =AE23+AF23-AG23 -> 0 | AI23: =Y23+Z23+AJ23-AD23-AG23 -> 1897 | AP23: =AL23+AN23+AM23+AO23 -> 0 | AU23: =SUM(AQ23:AT23) -> 0 | AV23: =AI23-AP23-AU23 -> 1897
A24: =SUBTOTAL(2,$Y$4:Y24) -> 21 | B24: NO:021 | C24: 一楼商铺 | D24: 1022 | E24: 56.26 | F24: 1022 | G24: 庄诗霖 | H24: =E24 -> 56.26 | I24: 2200 | K24: =I24+J24 -> 2200 | L24: 160 | M24: 3123 | N24: 3147 | O24: =N24-M24 -> 24 | P24: =ROUND(H24*0,0) -> 0 | Q24: =O24+P24 -> 24 | R24: 0.8 | S24: =ROUND(Q24*0.7,0) -> 17 | T24: =ROUND(Q24*R24,0) -> 19 | U24: =ROUND(H24*0,0) -> 0 | V24: =ROUND(U24*1.5,0) -> 0 | W24: =ROUND(H24*0.2,0) -> 11 | X24: =ROUND(W24*8.5,0) -> 94 | Y24: =I24+J24+L24+S24+T24+V24+X24 -> 2490 | AD24: =AA24+AB24+AC24 -> 0 | AH24: =AE24+AF24-AG24 -> 0 | AI24: =Y24+Z24+AJ24-AD24-AG24 -> 2490 | AP24: =AL24+AN24+AM24+AO24 -> 0 | AU24: =SUM(AQ24:AT24) -> 0 | AV24: =AI24-AP24-AU24 -> 2490
A25: =SUBTOTAL(2,$Y$4:Y25) -> 22 | B25: NO:022 | C25: 一楼商铺 | D25: 1023 | E25: 31.79 | F25: 1023 | G25: 黎培健 | H25: =E25 -> 31.79 | I25: 600 | J25: 0 | K25: =I25+J25 -> 600 | L25: 160 | M25: 2500 | N25: 2568 | O25: =N25-M25 -> 68 | P25: =ROUND(H25*0,0) -> 0 | Q25: =O25+P25 -> 68 | R25: 0.8 | S25: =ROUND(Q25*0.7,0) -> 48 | T25: =ROUND(Q25*R25,0) -> 54 | U25: =ROUND(H25*0,0) -> 0 | V25: =ROUND(U25*1.5,0) -> 0 | W25: =ROUND(H25*0.2,0) -> 6 | X25: =ROUND(W25*8.5,0) -> 51 | Y25: =I25+J25+L25+S25+T25+V25+X25 -> 913 | AD25: =AA25+AB25+AC25 -> 0 | AH25: =AE25+AF25-AG25 -> 0 | AI25: =Y25+Z25+AJ25-AD25-AG25 -> 913 | AP25: =AL25+AN25+AM25+AO25 -> 0 | AU25: =SUM(AQ25:AT25) -> 0 | AV25: =AI25-AP25-AU25 -> 913
A26: =SUBTOTAL(2,$Y$4:Y26) -> 23 | B26: NO:023 | C26: 一楼商铺 | D26: 1024 | E26: 43.89 | F26: 1024 | G26: 王小军 | H26: =E26 -> 43.89 | I26: 1448 | K26: =I26+J26 -> 1448 | L26: 160 | M26: 593 | N26: 628 | O26: =N26-M26 -> 35 | P26: =ROUND(H26*0,0) -> 0 | Q26: =O26+P26 -> 35 | R26: 0.8 | S26: =ROUND(Q26*0.7,0) -> 25 | T26: =ROUND(Q26*R26,0) -> 28 | U26: =ROUND(H26*0,0) -> 0 | V26: =ROUND(U26*1.5,0) -> 0 | W26: =ROUND(H26*0.2,0) -> 9 | X26: =ROUND(W26*8.5,0) -> 77 | Y26: =I26+J26+L26+S26+T26+V26+X26 -> 1738 | AD26: =AA26+AB26+AC26 -> 0 | AH26: =AE26+AF26-AG26 -> 0 | AI26: =Y26+Z26+AJ26-AD26-AG26 -> 1738 | AP26: =AL26+AN26+AM26+AO26 -> 0 | AU26: =SUM(AQ26:AT26) -> 0 | AV26: =AI26-AP26-AU26 -> 1738
A27: =SUBTOTAL(2,$Y$4:Y27) -> 24 | B27: NO:024 | C27: 一楼商铺 | D27: 1025 | E27: 27.15 | F27: 1025 | G27: 李雄辉 | H27: =E27 -> 27.15 | I27: 4200 | J27: 500 | K27: =I27+J27 -> 4700 | L27: 160 | M27: 1436 | N27: 1448 | O27: =N27-M27 -> 12 | P27: =ROUND(H27*0,0) -> 0 | Q27: =O27+P27 -> 12 | R27: 0.8 | S27: =ROUND(Q27*0.7,0) -> 8 | T27: =ROUND(Q27*R27,0) -> 10 | U27: =ROUND(H27*5.6,0) -> 152 | V27: =ROUND(U27*1.5,0) -> 228 | W27: =ROUND(H27*0.2,0) -> 5 | X27: =ROUND(W27*8.5,0) -> 43 | Y27: =I27+J27+L27+S27+T27+V27+X27 -> 5149 | AD27: =AA27+AB27+AC27 -> 0 | AH27: =AE27+AF27-AG27 -> 0 | AI27: =Y27+Z27+AJ27-AD27-AG27 -> 5149 | AP27: =AL27+AN27+AM27+AO27 -> 0 | AU27: =SUM(AQ27:AT27) -> 0 | AV27: =AI27-AP27-AU27 -> 5149
A28: =SUBTOTAL(2,$Y$4:Y28) -> 25 | B28: NO:025 | C28: 一楼商铺 | D28: 1025-A | E28: 26.45 | F28: 1025-A | G28: 苏建柳 | H28: =E28 -> 26.45 | I28: 2206 | J28: 250 | K28: =I28+J28 -> 2456 | L28: 160 | M28: 4759 | N28: 4859 | O28: =N28-M28 -> 100 | P28: =ROUND(H28*0,0) -> 0 | Q28: =O28+P28 -> 100 | R28: 0.8 | S28: =ROUND(Q28*0.7,0) -> 70 | T28: =ROUND(Q28*R28,0) -> 80 | U28: =ROUND(H28*5.6,0) -> 148 | V28: =ROUND(U28*1.5,0) -> 222 | W28: =ROUND(H28*0.2,0) -> 5 | X28: =ROUND(W28*8.5,0) -> 43 | Y28: =I28+J28+L28+S28+T28+V28+X28 -> 3031 | AD28: =AA28+AB28+AC28 -> 0 | AH28: =AE28+AF28-AG28 -> 0 | AI28: =Y28+Z28+AJ28-AD28-AG28 -> 3031 | AP28: =AL28+AN28+AM28+AO28 -> 0 | AU28: =SUM(AQ28:AT28) -> 0 | AV28: =AI28-AP28-AU28 -> 3031
A29: =SUBTOTAL(2,$Y$4:Y29) -> 26 | B29: NO:026 | C29: 一楼商铺 | D29: 1026 | E29: 27.15 | F29: 1026 | G29: 马旦 | H29: =E29 -> 27.15 | I29: 4202 | J29: 500 | K29: =I29+J29 -> 4702 | L29: 160 | M29: 4176 | N29: 4216 | O29: =N29-M29 -> 40 | P29: =ROUND(H29*0,0) -> 0 | Q29: =O29+P29 -> 40 | R29: 0.8 | S29: =ROUND(Q29*0.7,0) -> 28 | T29: =ROUND(Q29*R29,0) -> 32 | U29: =ROUND(H29*5.6,0) -> 152 | V29: =ROUND(U29*1.5,0) -> 228 | W29: =ROUND(H29*0.2,0) -> 5 | X29: =ROUND(W29*8.5,0) -> 43 | Y29: =I29+J29+L29+S29+T29+V29+X29 -> 5193 | AD29: =AA29+AB29+AC29 -> 0 | AH29: =AE29+AF29-AG29 -> 0 | AI29: =Y29+Z29+AJ29-AD29-AG29 -> 5193 | AP29: =AL29+AN29+AM29+AO29 -> 0 | AU29: =SUM(AQ29:AT29) -> 0 | AV29: =AI29-AP29-AU29 -> 5193
A30: =SUBTOTAL(2,$Y$4:Y30) -> 27 | B30: NO:027 | C30: 一楼商铺 | D30: 1027 | E30: 27.15 | F30: 1027 | G30: 范宏成 | H30: =E30 -> 27.15 | I30: 4200 | J30: 500 | K30: =I30+J30 -> 4700 | L30: 160 | M30: 3392 | N30: 3403 | O30: =N30-M30 -> 11 | P30: =ROUND(H30*0,0) -> 0 | Q30: =O30+P30 -> 11 | R30: 0.8 | S30: =ROUND(Q30*0.7,0) -> 8 | T30: =ROUND(Q30*R30,0) -> 9 | U30: =ROUND(H30*5.6,0) -> 152 | V30: =ROUND(U30*1.5,0) -> 228 | W30: =ROUND(H30*0.2,0) -> 5 | X30: =ROUND(W30*8.5,0) -> 43 | Y30: =I30+J30+L30+S30+T30+V30+X30 -> 5148 | AD30: =AA30+AB30+AC30 -> 0 | AH30: =AE30+AF30-AG30 -> 0 | AI30: =Y30+Z30+AJ30-AD30-AG30 -> 5148 | AP30: =AL30+AN30+AM30+AO30 -> 0 | AU30: =SUM(AQ30:AT30) -> 0 | AV30: =AI30-AP30-AU30 -> 5148
A31: =SUBTOTAL(2,$Y$4:Y31) -> 28 | B31: NO:028 | C31: 一楼商铺 | D31: 1028 | E31: 27.15 | F31: 1028 | G31: 阮文彬 | H31: 27.15 | I31: 4200 | J31: 500 | K31: =I31+J31 -> 4700 | L31: 160 | M31: 8257 | N31: 8298 | O31: =N31-M31 -> 41 | P31: =ROUND(H31*0,0) -> 0 | Q31: =O31+P31 -> 41 | R31: 0.8 | S31: =ROUND(Q31*0.7,0) -> 29 | T31: =ROUND(Q31*R31,0) -> 33 | U31: =ROUND(H31*5.6,0) -> 152 | V31: =ROUND(U31*1.5,0) -> 228 | W31: =ROUND(H31*0.2,0) -> 5 | X31: =ROUND(W31*8.5,0) -> 43 | Y31: =I31+J31+L31+S31+T31+V31+X31 -> 5193 | AD31: =AA31+AB31+AC31 -> 0 | AH31: =AE31+AF31-AG31 -> 0 | AI31: =Y31+Z31+AJ31-AD31-AG31 -> 5193 | AP31: =AL31+AN31+AM31+AO31 -> 0 | AU31: =SUM(AQ31:AT31) -> 0 | AV31: =AI31-AP31-AU31 -> 5193
A32: =SUBTOTAL(2,$Y$4:Y32) -> 29 | B32: NO:029 | C32: 一楼商铺 | D32: 1029 | E32: 27.15 | F32: 1029 | G32: 钟玲玲 | H32: =E32 -> 27.15 | I32: 4200 | J32: 500 | K32: =I32+J32 -> 4700 | L32: 160 | M32: 5452 | N32: 5489 | O32: =N32-M32 -> 37 | P32: =ROUND(H32*0,0) -> 0 | Q32: =O32+P32 -> 37 | R32: 0.8 | S32: =ROUND(Q32*0.7,0) -> 26 | T32: =ROUND(Q32*R32,0) -> 30 | U32: =ROUND(H32*5.6,0) -> 152 | V32: =ROUND(U32*1.5,0) -> 228 | W32: =ROUND(H32*0.2,0) -> 5 | X32: =ROUND(W32*8.5,0) -> 43 | Y32: =I32+J32+L32+S32+T32+V32+X32 -> 5187 | AD32: =AA32+AB32+AC32 -> 0 | AH32: =AE32+AF32-AG32 -> 0 | AI32: =Y32+Z32+AJ32-AD32-AG32 -> 5187 | AP32: =AL32+AN32+AM32+AO32 -> 0 | AU32: =SUM(AQ32:AT32) -> 0 | AV32: =AI32-AP32-AU32 -> 5187
A33: =SUBTOTAL(2,$Y$4:Y33) -> 30 | B33: NO:030 | C33: 一楼商铺 | D33: 1030 | E33: 27.15 | F33: 1030 | G33: 覃燕芬 | H33: =E33 -> 27.15 | I33: 4200 | J33: 500 | K33: =I33+J33 -> 4700 | L33: 160 | M33: 5699 | N33: 5761 | O33: =N33-M33 -> 62 | P33: =ROUND(H33*0,0) -> 0 | Q33: =O33+P33 -> 62 | R33: 0.8 | S33: =ROUND(Q33*0.7,0) -> 43 | T33: =ROUND(Q33*R33,0) -> 50 | U33: =ROUND(H33*5.6,0) -> 152 | V33: =ROUND(U33*1.5,0) -> 228 | W33: =ROUND(H33*0.2,0) -> 5 | X33: =ROUND(W33*8.5,0) -> 43 | Y33: =I33+J33+L33+S33+T33+V33+X33 -> 5224 | AD33: =AA33+AB33+AC33 -> 0 | AH33: =AE33+AF33-AG33 -> 0 | AI33: =Y33+Z33+AJ33-AD33-AG33 -> 5224 | AP33: =AL33+AN33+AM33+AO33 -> 0 | AU33: =SUM(AQ33:AT33) -> 0 | AV33: =AI33-AP33-AU33 -> 5224
A34: =SUBTOTAL(2,$Y$4:Y34) -> 31 | B34: NO:031 | C34: 一楼商铺 | D34: 1031 | E34: 23.77 | F34: 1031 | G34: 陈恳 | H34: 23.77 | I34: 4200 | J34: 500 | K34: =I34+J34 -> 4700 | L34: 160 | M34: 6328 | N34: 6375 | O34: =N34-M34 -> 47 | P34: =ROUND(H34*0,0) -> 0 | Q34: =O34+P34 -> 47 | R34: 0.8 | S34: =ROUND(Q34*0.7,0) -> 33 | T34: =ROUND(Q34*R34,0) -> 38 | U34: =ROUND(H34*5.6,0) -> 133 | V34: =ROUND(U34*1.5,0) -> 200 | W34: =ROUND(H34*0.2,0) -> 5 | X34: =ROUND(W34*8.5,0) -> 43 | Y34: =I34+J34+L34+S34+T34+V34+X34 -> 5174 | AD34: =AA34+AB34+AC34 -> 0 | AH34: =AE34+AF34-AG34 -> 0 | AI34: =Y34+Z34+AJ34-AD34-AG34 -> 5174 | AP34: =AL34+AN34+AM34+AO34 -> 0 | AU34: =SUM(AQ34:AT34) -> 0 | AV34: =AI34-AP34-AU34 -> 5174
A35: =SUBTOTAL(2,$Y$4:Y35) -> 32 | B35: NO:032 | C35: 一楼商铺 | D35: 1032 | E35: 27.15 | F35: 1032 | G35: 范琼静 | H35: =E35 -> 27.15 | I35: 4200 | J35: 500 | K35: =I35+J35 -> 4700 | L35: 160 | M35: 5983 | N35: 6025 | O35: =N35-M35 -> 42 | P35: =ROUND(H35*0,0) -> 0 | Q35: =O35+P35 -> 42 | R35: 0.8 | S35: =ROUND(Q35*0.7,0) -> 29 | T35: =ROUND(Q35*R35,0) -> 34 | U35: =ROUND(H35*5.6,0) -> 152 | V35: =ROUND(U35*1.5,0) -> 228 | W35: =ROUND(H35*0.2,0) -> 5 | X35: =ROUND(W35*8.5,0) -> 43 | Y35: =I35+J35+L35+S35+T35+V35+X35 -> 5194 | AD35: =AA35+AB35+AC35 -> 0 | AH35: =AE35+AF35-AG35 -> 0 | AI35: =Y35+Z35+AJ35-AD35-AG35 -> 5194 | AP35: =AL35+AN35+AM35+AO35 -> 0 | AU35: =SUM(AQ35:AT35) -> 0 | AV35: =AI35-AP35-AU35 -> 5194
A36: =SUBTOTAL(2,$Y$4:Y36) -> 33 | B36: NO:033 | C36: 一楼商铺 | D36: 1033 | E36: 27.15 | F36: 1033 | G36: 蔡安琦 | H36: =E36 -> 27.15 | I36: 4200 | J36: 500 | K36: =I36+J36 -> 4700 | L36: 160 | M36: 9222 | N36: 9253 | O36: =N36-M36 -> 31 | P36: =ROUND(H36*0,0) -> 0 | Q36: =O36+P36 -> 31 | R36: 0.8 | S36: =ROUND(Q36*0.7,0) -> 22 | T36: =ROUND(Q36*R36,0) -> 25 | U36: =ROUND(H36*5.6,0) -> 152 | V36: =ROUND(U36*1.5,0) -> 228 | W36: =ROUND(H36*0.2,0) -> 5 | X36: =ROUND(W36*8.5,0) -> 43 | Y36: =I36+J36+L36+S36+T36+V36+X36 -> 5178 | AD36: =AA36+AB36+AC36 -> 0 | AH36: =AE36+AF36-AG36 -> 0 | AI36: =Y36+Z36+AJ36-AD36-AG36 -> 5178 | AP36: =AL36+AN36+AM36+AO36 -> 0 | AU36: =SUM(AQ36:AT36) -> 0 | AV36: =AI36-AP36-AU36 -> 5178
A37: =SUBTOTAL(2,$Y$4:Y37) -> 34 | B37: NO:034 | C37: 一楼商铺 | D37: 1034 | E37: 27.15 | F37: 1034 | G37: 杨志鸿 | H37: =E37 -> 27.15 | I37: 4200 | J37: 500 | K37: =I37+J37 -> 4700 | L37: 160 | M37: 2989 | N37: 3002 | O37: =N37-M37 -> 13 | P37: =ROUND(H37*0,0) -> 0 | Q37: =O37+P37 -> 13 | R37: 0.8 | S37: =ROUND(Q37*0.7,0) -> 9 | T37: =ROUND(Q37*R37,0) -> 10 | U37: =ROUND(H37*5.6,0) -> 152 | V37: =ROUND(U37*1.5,0) -> 228 | W37: =ROUND(H37*0.2,0) -> 5 | X37: =ROUND(W37*8.5,0) -> 43 | Y37: =I37+J37+L37+S37+T37+V37+X37 -> 5150 | AD37: =AA37+AB37+AC37 -> 0 | AH37: =AE37+AF37-AG37 -> 0 | AI37: =Y37+Z37+AJ37-AD37-AG37 -> 5150 | AP37: =AL37+AN37+AM37+AO37 -> 0 | AU37: =SUM(AQ37:AT37) -> 0 | AV37: =AI37-AP37-AU37 -> 5150
A38: =SUBTOTAL(2,$Y$4:Y38) -> 35 | B38: NO:035 | C38: 一楼商铺 | D38: 1035 | E38: 27.15 | F38: 1035 | G38: 王正庚 | H38: =E38 -> 27.15 | I38: 4200 | J38: 500 | K38: =I38+J38 -> 4700 | L38: 160 | M38: 10414 | N38: =20900/2 -> 10450 | O38: =N38-M38 -> 36 | P38: =ROUND(H38*0,0) -> 0 | Q38: =O38+P38 -> 36 | R38: 0.8 | S38: =ROUND(Q38*0.7,0) -> 25 | T38: =ROUND(Q38*R38,0) -> 29 | U38: =ROUND(H38*5.6,0) -> 152 | V38: =ROUND(U38*1.5,0) -> 228 | W38: =ROUND(H38*0.2,0) -> 5 | X38: =ROUND(W38*8.5,0) -> 43 | Y38: =I38+J38+L38+S38+T38+V38+X38 -> 5185 | AD38: =AA38+AB38+AC38 -> 0 | AH38: =AE38+AF38-AG38 -> 0 | AI38: =Y38+Z38+AJ38-AD38-AG38 -> 5185 | AP38: =AL38+AN38+AM38+AO38 -> 0 | AU38: =SUM(AQ38:AT38) -> 0 | AV38: =AI38-AP38-AU38 -> 5185
A39: =SUBTOTAL(2,$Y$4:Y39) -> 36 | B39: NO:036 | C39: 一楼商铺 | D39: 1036 | E39: 27.15 | F39: 1036 | G39: 李耿坚 | H39: =E39 -> 27.15 | I39: 4200 | J39: 500 | K39: =I39+J39 -> 4700 | L39: 160 | M39: 10414 | N39: 10450 | O39: =N39-M39 -> 36 | P39: =ROUND(H39*0,0) -> 0 | Q39: =O39+P39 -> 36 | R39: 0.8 | S39: =ROUND(Q39*0.7,0) -> 25 | T39: =ROUND(Q39*R39,0) -> 29 | U39: =ROUND(H39*5.6,0) -> 152 | V39: =ROUND(U39*1.5,0) -> 228 | W39: =ROUND(H39*0.2,0) -> 5 | X39: =ROUND(W39*8.5,0) -> 43 | Y39: =I39+J39+L39+S39+T39+V39+X39 -> 5185 | AD39: =AA39+AB39+AC39 -> 0 | AH39: =AE39+AF39-AG39 -> 0 | AI39: =Y39+Z39+AJ39-AD39-AG39 -> 5185 | AP39: =AL39+AN39+AM39+AO39 -> 0 | AU39: =SUM(AQ39:AT39) -> 0 | AV39: =AI39-AP39-AU39 -> 5185
A40: =SUBTOTAL(2,$Y$4:Y40) -> 37 | B40: NO:037 | C40: 一楼商铺 | D40: 1037 | E40: 27.15 | F40: 1037 | G40: 范宏健 | H40: =E40 -> 27.15 | I40: 4200 | J40: 500 | K40: =I40+J40 -> 4700 | L40: 160 | M40: 3570 | N40: 3615 | O40: =N40-M40 -> 45 | P40: =ROUND(H40*0,0) -> 0 | Q40: =O40+P40 -> 45 | R40: 0.8 | S40: =ROUND(Q40*0.7,0) -> 32 | T40: =ROUND(Q40*R40,0) -> 36 | U40: =ROUND(H40*5.6,0) -> 152 | V40: =ROUND(U40*1.5,0) -> 228 | W40: =ROUND(H40*0.2,0) -> 5 | X40: =ROUND(W40*8.5,0) -> 43 | Y40: =I40+J40+L40+S40+T40+V40+X40 -> 5199 | AD40: =AA40+AB40+AC40 -> 0 | AH40: =AE40+AF40-AG40 -> 0 | AI40: =Y40+Z40+AJ40-AD40-AG40 -> 5199 | AP40: =AL40+AN40+AM40+AO40 -> 0 | AU40: =SUM(AQ40:AT40) -> 0 | AV40: =AI40-AP40-AU40 -> 5199
...

Sheet Sheet6
A1: 合同
A2: 档号 | B2: 档主名 | H2: 档口号 | I2: 商户名 | J2: 租金 | K2: 管理费
C3: 月租 | D3: 管理费
A4: 1001-01（临一） | B4: 何具达 | C4: 3052 | D4: 210 | H4: 1001-01（临一） | I4: 何具达 | J4: 3052 | K4: 210 | L4: =C4-J4 -> 0 | M4: =D4-K4 -> 0
A5: 1001 | B5: 邓凤强 | C5: 4200 | D5: 500 | H5: 1001 | I5: 邓凤强 | J5: 4200 | K5: 500
A6: 1002 | B6: 苏建柳 | C6: 1500 | H6: 1002 | I6: 苏建柳 | J6: 1500
A7: 1003 | B7: 李鹏飞 | C7: 3000 | D7: 0 | H7: 1003/1004 | I7: 李鹏飞 | J7: 3000
A8: 1005 | B8: 黄腾凌 | C8: 1200 | D8: 200 | H8: 1005 | I8: 黄腾凌 | J8: 1200 | K8: 200
A9: 1006 | B9: 刘展 | C9: 1200 | D9: 200 | H9: 1006 | I9: 刘展 | J9: 1200 | K9: 200
A10: 1007 | B10: 王正庚 | C10: 1200 | D10: 0 | H10: 1007 | I10: 王正庚 | J10: 1200
A11: 1008 | B11: 潭日标 | C11: 2500 | D11: 0 | H11: 1008/1009 | I11: 潭日标 | J11: 2500
A12: 1009 | B12: 潭日标 | H12: 1009 | I12: 潭日标
A13: 1010 | B13: 王长梅 | C13: 1500 | H13: 1010 | I13: 王长梅 | J13: 1500
A14: 1011 | B14: 段邦彦 | C14: 750 | H14: 1011 | I14: 段邦彦 | J14: 750
A15: 1012 | B15: 李文学 | C15: 750 | H15: 1012 | I15: 李文学 | J15: 750 | K15: 0
A16: 1013 | B16: 揭英祥 | C16: 1200 | H16: 1013 | I16: 揭英祥 | J16: 1200
A17: 1014 | B17: 陈文彬 | C17: 1500 | H17: 1014 | I17: 陈文彬 | J17: 1500 | K17: 0
A18: 1015 | B18: 张平君 | C18: 1200 | H18: 1015 | I18: 张平君 | J18: 1200 | K18: 0
A19: 1016 | B19: 卢汉总 | C19: 2800 | D19: 200 | H19: 1016/1017 | I19: 卢汉总 | J19: 2800 | K19: 200
A20: 1018 | B20: 白成滔 | C20: 2000 | H20: 1018 | I20: 白成滔 | J20: 2000 | K20: 0
A21: 1019 | B21: 王长梅 | C21: 1200 | H21: 1019 | I21: 王长梅 | J21: 1200
A22: 1020 | B22: 张爱玲 | C22: 1200 | H22: 1020 | I22: 张爱玲 | J22: 1200 | K22: 0
A23: 1021 | B23: 刘光全 | C23: 1200 | D23: 200 | H23: 1021 | I23: 刘光全 | J23: 1200 | K23: 200
A24: 1022 | B24: 庄诗霖 | C24: 2200 | H24: 1022 | I24: 庄诗霖 | J24: 2200
A25: 1023 | B25: 黎培健 | C25: 600 | D25: 0 | H25: 1023 | I25: 黎培健 | J25: 600 | K25: 0
A26: 1024 | B26: 王小军 | C26: 1448 | H26: 1024 | I26: 王小军 | J26: 1448
A27: 1025 | B27: 李雄辉 | C27: 4200 | D27: 500 | H27: 1025 | I27: 林小武 | J27: 4200 | K27: 500
A28: 1025-A | B28: 苏建柳 | C28: 2206 | D28: 250 | H28: 1025-A | I28: 苏建柳 | J28: 2206 | K28: 250
A29: 1026 | B29: 马旦 | C29: 4202 | D29: 500 | H29: 1026 | I29: 马旦 | J29: 4202 | K29: 500
A30: 1027 | B30: 范宏成 | C30: 4200 | D30: 500 | H30: 1027 | I30: 范宏成 | J30: 4200 | K30: 500
A31: 1028 | B31: 阮文彬 | C31: 4200 | D31: 500 | H31: 1028 | I31: 阮文彬 | J31: 4200 | K31: 500
A32: 1029 | B32: 钟玲玲 | C32: 4200 | D32: 500 | H32: 1029 | I32: 钟玲玲 | J32: 4200 | K32: 500
A33: 1030 | B33: 覃燕芬 | C33: 4200 | D33: 500 | H33: 1030 | I33: 覃燕芬 | J33: 4200 | K33: 500
A34: 1031 | B34: 陈恳 | C34: 4200 | D34: 500 | H34: 1031 | I34: 陈恳 | J34: 4200 | K34: 500
A35: 1032 | B35: 范琼静 | C35: 4200 | D35: 500 | H35: 1032 | I35: 范琼静 | J35: 4200 | K35: 500
A36: 1033 | B36: 蔡安琦 | C36: 4200 | D36: 500 | H36: 1033 | I36: 蔡安琦 | J36: 4200 | K36: 500
A37: 1034 | B37: 杨志鸿 | C37: 4200 | D37: 500 | H37: 1034 | I37: 杨志鸿 | J37: 4200 | K37: 500
A38: 1035 | B38: 王正庚 | C38: 4200 | D38: 500 | H38: 1035 | I38: 廖文怀 | J38: 4200 | K38: 500
A39: 1036 | B39: 李耿坚 | C39: 4200 | D39: 500 | H39: 1036 | I39: 李耿坚 | J39: 4200 | K39: 500
A40: 1037 | B40: 范宏健 | C40: 4200 | D40: 500 | H40: 1037 | I40: 范宏健 | J40: 4200 | K40: 500
...

Sheet Sheet7
A2: 档口号 | B2: 商户名
A4: 1001-01（临一） | B4: 何具达
A5: 1001 | B5: 邓凤强
A6: 1002 | B6: 苏建柳
A7: 1003/1004 | B7: 李鹏飞
A8: 1005 | B8: 黄腾凌
A9: 1006 | B9: 刘展
A10: 1007 | B10: 王正庚
A11: 1008/1009 | B11: 潭日标
A12: 1009 | B12: 潭日标
A13: 1010 | B13: 王长梅
A14: 1011 | B14: 段邦彦
A15: 1012 | B15: 李文学
A16: 1013 | B16: 揭英祥
A17: 1014 | B17: 陈文彬
A18: 1015 | B18: 张平君
A19: 1016/1017 | B19: 卢汉总
A20: 1018 | B20: 白成滔
A21: 1019 | B21: 王长梅
A22: 1020 | B22: 张爱玲
A23: 1021 | B23: 刘光全
A24: 1022 | B24: 庄诗霖
A25: 1023 | B25: 黎培健
A26: 1024 | B26: 王小军
A27: 1025 | B27: 李雄辉
A28: 1025-A | B28: 苏建柳
A29: 1026 | B29: 马旦
A30: 1027 | B30: 范宏成
A31: 1028 | B31: 阮文彬
A32: 1029 | B32: 钟玲玲
A33: 1030 | B33: 覃燕芬
A34: 1031 | B34: 陈恳
A35: 1032 | B35: 范琼静
A36: 1033 | B36: 蔡安琦
A37: 1034 | B37: 杨志鸿
A38: 1035 | B38: 王正庚
A39: 1036 | B39: 李耿坚
A40: 1037 | B40: 范宏健
... A68: 1066 | B68: 卢永润
A69: 1067展柜(全包） | B69: 章芳琴
...

Sheet 电表
A2: 档口号 | B2: 商铺号 | C2: 11月份 | D2: 12月份 | E2: 1月份 | F2: 2月份 | G2: 3月份 | H2: 4月份 | I2: 5月份 | J2: 6月份 | K2: 7月份 | L2: 8月份 | M2: 9月份
A4: 1001-01（临一） | B4: 1001-01（临一） | C4: 19518 | D4: 19645
A5: 1001 | B5: 1001 | C5: 3340 | D5: 3491
A6: 1002 | B6: 1002 | C6: 8431 | D6: 8436
A7: 1003/1004 | B7: 1003/1004 | C7: =5652+9610 -> 15262 | D7: =9610+5974 -> 15584
A8: 1005 | B8: 1005 | C8: 2696 | D8: 2746
A9: 1006 | B9: 1006 | C9: 4133 | D9: 4186
A10: 1007 | B10: 1007 | C10: 370 | D10: 450
A11: 1008/1009 | B11: 1008/1009 | C11: 1417 | D11: 1565
A12: 1009 | B12: 1009 | C12: 2986 | D12: 3050
A13: 1010 | B13: 1010 | C13: 7204 | D13: 7317
A14: 1011 | B14: 1011 | C14: 1903 | D14: 1913
A15: 1012 | B15: 1012 | C15: 778 | D15: 841
A16: 1013 | B16: 1013 | C16: 2705 | D16: 2775
A17: 1014 | B17: 1014 | C17: 2040 | D17: 2226
A18: 1015 | B18: 1015 | C18: 5248 | D18: 5267
A19: 1016/1017 | B19: 1016/1017 | C19: =4907+728 -> 5635 | D19: =4966+860 -> 5826
A20: 1018 | B20: 1018 | C20: 3664 | D20: 3710
A21: 1019 | B21: 1019 | C21: 1395 | D21: 1411
A22: 1020 | B22: 1020 | C22: 9151 | D22: 9247
A23: 1021 | B23: 1021 | C23: 5429 | D23: 5573
A24: 1022 | B24: 1022 | C24: 2613 | D24: 2647
A25: 1023 | B25: 1023 | C25: 1839 | D25: 1851
A26: 1024 | B26: 1024 | C26: 186 | D26: 225
A27: 1025 | B27: 1025 | C27: 1219 | D27: 1233
A28: 1025-A | B28: 1025-A | C28: 2817 | D28: 2877
A29: 1026 | B29: 1026 | C29: 3230 | D29: 3345
A30: 1027 | B30: 1027 | C30: 3120 | D30: 3151
A31: 1028 | B31: 1028 | C31: 7768 | D31: 7816
A32: 1029 | B32: 1029 | C32: 4820 | D32: 4912
A33: 1030 | B33: 1030 | C33: 4863 | D33: 4948
A34: 1031 | B34: 1031 | C34: 5641 | D34: 5728
A35: 1032 | B35: 1032 | C35: 5380 | D35: 5477
A36: 1033 | B36: 1033 | C36: 8359 | D36: 8452
A37: 1034 | B37: 1034 | C37: 2652 | D37: 2692
A38: 1035 | B38: 1035 | C38: 9842 | D38: 9894
A39: 1036 | B39: 1036 | C39: 9842 | D39: 9894
A40: 1037 | B40: 1037 | C40: 3158 | D40: 3207
... A68: 1066 | B68: 1066 | C68: 7977 | D68: 8185
A69: 1067展柜(全包） | B69: 1067展柜(全包）
...

Sheet Sheet5
A2: 档口号 | B2: 商户名 | C2: 租金 | F2: 档号 | G2: 档主名
H3: 月租
A4: 1002 | B4: 苏建柳 | C4: 1500 | F4: 1002 | G4: 苏建柳 | H4: 1500 | I4: =C4-H4 -> 0
A5: 1025-A | B5: 苏建柳 | C5: 2206 | F5: 1025-A | G5: 苏建柳 | H5: 4202 | I5: =C5-H5 -> -1996
A6: 1037 | B6: 范宏健 | C6: 4200 | F6: 1037 | G6: 范宏健 | H6: 4200 | I6: =C6-H6 -> 0
A7: 1040 | B7: 陈少华 | C7: 4202 | F7: 1040 | G7: 陈少华 | H7: 4202 | I7: =C7-H7 -> 0
A8: 1055 | B8: 梁中梅 | C8: 4200 | F8: 1055 | G8: 梁中梅 | H8: 4200 | I8: =C8-H8 -> 0
A9: 2002 | B9: 孙标然 | C9: 2300 | F9: 2002 | G9: 孙标然 | H9: 2300 | I9: =C9-H9 -> 0
A10: 2006 | B10: 周丽红 | C10: 2300 | F10: 2006 | G10: 周丽红 | H10: 2300 | I10: =C10-H10 -> 0
A11: 2009 | B11: 冯世豪 | C11: 2300 | F11: 2009 | G11: 冯世豪 | H11: 2300 | I11: =C11-H11 -> 0
A12: 2014 | B12: 张顶 | C12: 2300 | F12: 2014 | G12: 张顶 | H12: 2300 | I12: =C12-H12 -> 0
A13: 2016 | B13: 黎慧敏 | C13: 2300 | F13: 2016 | G13: 黎慧敏 | H13: 2300 | I13: =C13-H13 -> 0
A14: 2017 | B14: 黎慧敏 | C14: 2300 | F14: 2017 | G14: 黎慧敏 | H14: 2300 | I14: =C14-H14 -> 0
A15: 2021 | B15: 吴桂华 | C15: 2300 | F15: 2021 | G15: 吴桂华 | H15: 2300 | I15: =C15-H15 -> 0
A16: 2029 | B16: 郭林红 | C16: 2300 | F16: 2029 | G16: 郭林红 | H16: 2300 | I16: =C16-H16 -> 0
A17: 2039 | B17: 蔡玉琴 | C17: 2300 | F17: 2039 | G17: 蔡玉琴 | H17: 2300 | I17: =C17-H17 -> 0
A18: 2043/2044 | B18: 林晓玲 | C18: 4600 | F18: 2043 | G18: 林晓玲 | H18: 4600 | I18: =C18-H18 -> 0
A19: 2044 | B19: 林晓玲 | F19: 2044 | G19: 林晓玲 | I19: =C19-H19 -> 0
A20: 2047 | B20: 郭红林 | C20: 2000 | F20: 2047 | G20: 郭红林 | H20: 2000 | I20: =C20-H20 -> 0
A21: 2054 | B21: 孙瑜 | C21: 2300 | F21: 2054（2053A) | G21: 孙瑜 | H21: 4600 | I21: =C21-H21 -> -2300
A22: 2055 | B22: 孙瑜 | C22: 2300 | F22: 2055 | G22: 孙瑜 | I22: =C22-H22 -> 2300
A23: 2057 | B23: 牟军 | C23: 2300 | F23: 2057 | G23: 牟军 | H23: 2300 | I23: =C23-H23 -> 0
A24: 2063/2064 | B24: 吴彬辉 | C24: 4600 | F24: 2063 | G24: 吴彬辉 | H24: 4600 | I24: =C24-H24 -> 0
A25: 2064 | B25: 吴彬辉 | F25: 2064 | G25: 吴彬辉 | I25: =C25-H25 -> 0
A26: 2074 | B26: 刘丽秀 | C26: 2300 | F26: 2075A(2074) | G26: 刘丽秀 | H26: 2300 | I26: =C26-H26 -> 0
A27: 2082 | B27: 叶雪梅 | C27: 2300 | F27: 2082 | G27: 叶雪梅 | H27: 2300 | I27: =C27-H27 -> 0
A28: 2084 | B28: 梁彬 | C28: 2300 | F28: 2084 | G28: 梁彬 | H28: 2300 | I28: =C28-H28 -> 0
A29: 2086 | B29: 张维原 | C29: 2300 | F29: 2086 | G29: 张维原 | H29: 2300 | I29: =C29-H29 -> 0
A30: 2088 | B30: 林香超 | C30: 2300 | F30: 2088 | G30: 林香超 | H30: 2300 | I30: =C30-H30 -> 0
A31: 3011 | B31: 王海亮 | C31: 5000 | F31: 3011 | G31: 王海亮 | H31: 5000 | I31: =C31-H31 -> 0
A32: 3017 | B32: 张顶 | C32: 5000 | F32: 3017 | G32: 张顶 | H32: 5000 | I32: =C32-H32 -> 0
A33: 3022 | B33: 陈娇丽 | C33: 5000 | F33: 3022 | G33: 陈娇丽 | H33: 5000 | I33: =C33-H33 -> 0
A34: 3048 | B34: 刘德政 | C34: 5000 | F34: 3028/3053/3054 | G34: 张智森 | H34: 6000 | I34: =C34-H34 -> -1000
A35: 3049 | B35: 林香科 | C35: 5000 | F35: 3048 | G35: 刘德政 | H35: 5000 | I35: =C35-H35 -> 0
A36: 3028/3053/3054 | B36: 张智森 | C36: 6000 | F36: 3049 | G36: 林香科 | H36: 5000 | I36: =C36-H36 -> 1000
A37: 4006 | B37: 刘德政 | C37: 4500 | F37: 4006 | G37: 刘德政 | H37: 4500 | I37: =C37-H37 -> 0
A38: 4025 | B38: 黄保军 | C38: 4500 | F38: 4025 | G38: 黄保军 | H38: 4500 | I38: =C38-H38 -> 0
A39: 4043 | B39: 黄杰清 | C39: 4500 | F39: 4043 | G39: 黄杰清 | H39: 4500 | I39: =C39-H39 -> 0
A40: 5001 | B40: 沈阳俊 | C40: 4000 | F40: 5001 | G40: 沈阳俊 | H40: 4000 | I40: =C40-H40 -> 0
A41: 5006 | B41: 陈淡吟 | C41: 4000 | F41: 5006 | G41: 陈淡吟 | H41: 4000 | I41: =C41-H41 -> 0
...

Sheet Sheet2
B3: 商铺号 | C3: 商户名 | D3: 面积 | E3: 租金 | F3: 管理费
B5: 2001 | C5: 黄廉廷（临租） | E5: 1500 | H5: 2001 | I5: 黄廉廷 | J5: 1500 | L5: =E5-J5 -> 0
B6: 2022 | C6: 白成涛 | E6: 2000 | H6: 2022 | I6: 白成涛 | J6: 2000 | L6: =E6-J6 -> 0
B7: 2044 | C7: 钟日生 | D7: 16.54 | E7: 2000 | H7: 2044 | I7: 钟日生 | J7: 2000 | L7: =E7-J7 -> 0
B8: 3009半档 | C8: 罗春兰 | D8: 32.425 | E8: 2540 | F8: 200 | H8: 3009 | I8: 罗春兰 | J8: 2540 | K8: 200 | L8: =E8-J8 -> 0
B9: 3040半档 | C9: 庄智杨 | D9: 32.425 | E9: 2788 | F9: 200 | H9: 3040 | I9: 庄智杨 | J9: 2788 | K9: 200 | L9: =E9-J9 -> 0
B10: 3045半档 | C10: 张朝花 | D10: 32.425 | E10: 2662 | F10: 200 | H10: 3045 | I10: 张朝花 | J10: 2662 | K10: 200 | L10: =E10-J10 -> 0
B11: 4006半档 | C11: 刘德政 | D11: 32.425 | E11: 2800 | F11: 200 | H11: 4006 | I11: 刘德政 | J11: 2800 | K11: 200 | L11: =E11-J11 -> 0
B12: 4011半档 | C12: 赖文杰 | D12: 32.425 | E12: 2800 | F12: 200 | H12: 4011 | I12: 赖文杰 | J12: 2800 | K12: 200 | L12: =E12-J12 -> 0
B13: 4016半档 | C13: 蔡祖莹 | D13: 32.425 | E13: 2697 | F13: 200 | H13: 4016 | I13: 蔡祖莹 | J13: 2697 | K13: 200 | L13: =E13-J13 -> 0
B14: 4018半档 | C14: 张朝帅 | D14: 32.425 | L14: =E14-J14 -> 0
B15: 4021半档 | C15: 张丽风 | D15: 32.425 | E15: 2800 | F15: 200 | H15: 4021 | I15: 张丽风 | J15: 2800 | K15: 200 | L15: =E15-J15 -> 0
B16: 4026半档 | C16: 张朝凯 | D16: 32.425 | E16: 2691 | F16: 200 | H16: 4026 | I16: 张朝凯 | J16: 2691 | K16: 200 | L16: =E16-J16 -> 0
B17: 4030半档 | C17: 王丽枝 | D17: 32.425 | E17: 3500 | F17: 250 | H17: 4030 | I17: 王丽枝 | J17: 3500 | K17: 250 | L17: =E17-J17 -> 0
B18: 4035半档 | C18: 黄廉兴 | D18: 32.425 | E18: 2800 | F18: 200 | H18: 4035 | I18: 黄廉兴 | J18: 2800 | K18: 200 | L18: =E18-J18 -> 0
B19: 4038半档 | C19: 陈超 | D19: 32.425 | E19: 2800 | F19: 200 | H19: 4038 | I19: 陈超 | J19: 2800 | K19: 200 | L19: =E19-J19 -> 0
B20: 4040半档 | C20: 刘航 | D20: 32.425 | E20: 2800 | F20: 200 | H20: 4040 | I20: 刘航 | J20: 2800 | K20: 200 | L20: =E20-J20 -> 0
B21: 4043半档 | C21: 卢永润 | D21: 32.425 | E21: 3500 | F21: 200 | H21: 4043 | I21: 卢永润 | J21: 3500 | K21: 200 | L21: =E21-J21 -> 0
B22: 4044半档 | C22: 张虎 | D22: 32.425 | E22: 2800 | F22: 200 | H22: 4044 | I22: 张虎 | J22: 2800 | K22: 200 | L22: =E22-J22 -> 0
B23: 4046半档 | C23: 李义中 | D23: 32.425 | E23: 3250 | F23: 200 | H23: 4046 | I23: 李义中 | J23: 3250 | K23: 200 | L23: =E23-J23 -> 0
B24: 4046A半档 | C24: 李太焕 | D24: 32.425 | E24: 2758 | F24: 200 | H24: 4046A | I24: 李太焕 | J24: 2758 | K24: 200 | L24: =E24-J24 -> 0

Sheet Sheet3
A1: 商铺号 | B1: 商户名 | C1: 面积 | D1: 租金 | E1: 管理费 | H1: 档号 | I1: 档主名 | L1: 递增日（2021） | M1: 递增金额
J2: 月租 | K2: 管理费
A3: 1001-01（临一） | B3: 陈良伟 | C3: 19.5 | D3: 3052 | E3: 210 | H3: 1001-01（临一） | I3: 陈良伟 | J3: 3052 | K3: 210 | L3: 44256 | M3: 2906 | N3: =D3-J3 -> 0
A4: 1001 | B4: 邓凤强 | C4: 21.87 | D4: 4202 | E4: 500 | H4: 1001 | I4: 邓凤强 | J4: 4202 | K4: 500 | N4: =D4-J4 -> 0
A5: 1002 | B5: 苏建柳 | C5: 27.87 | D5: 3000 | H5: 1002 | I5: 苏建柳 | J5: 3000 | N5: =D5-J5 -> 0
A6: 1003/1004 | B6: 陈汉真 | C6: 49.02 | D6: 2851 | E6: 400 | H6: 1003 | I6: 陈汉真 | J6: 2851 | K6: 400 | N6: =D6-J6 -> 0
A7: 1005 | B7: 林翠侠 | C7: 27.15 | D7: 2000 | H7: 1005 | I7: 林翠侠 | J7: 2000 | N7: =D7-J7 -> 0
A8: 1006 | H8: 1006 | N8: =D8-J8 -> 0
A9: 1007 | H9: 1007 | N9: =D9-J9 -> 0
A10: 1008 | B10: 陈汉真（临租） | C10: 27.15 | D10: 1600 | H10: 1008 | I10: 陈汉真 | J10: 1600 | K10: 0 | N10: =D10-J10 -> 0
A11: 1009 | B11: 林丽情 | C11: 27.15 | D11: 4202 | E11: 500 | H11: 1009 | I11: 林丽情 | J11: 4202 | K11: 500 | N11: =D11-J11 -> 0
A12: 1010 | B12: 包君威 | C12: 23.77 | D12: 4202 | E12: 500 | H12: 1010 | I12: 包君威 | J12: 4202 | K12: 500 | N12: =D12-J12 -> 0
A13: 1011 | B13: 赵德花 | C13: 27.15 | D13: 2500 | H13: 1011 | I13: 赵德花 | J13: 2500 | N13: =D13-J13 -> 0
A14: 1012 | B14: 薛扬 | C14: 27.5 | D14: 2500 | H14: 1012 | I14: 薛扬 | J14: 2500 | N14: =D14-J14 -> 0
A15: 1013 | B15: 陈金俊 | C15: 27.15 | D15: 2500 | H15: 1013 | I15: 陈金俊 | J15: 2500 | N15: =D15-J15 -> 0
A16: 1014/1015 | B16: 王奎（临租） | C16: 54.3 | D16: 3000 | H16: 1014 | I16: 王奎 | J16: 3000 | N16: =D16-J16 -> 0
A17: 1016/1017 | B17: 王燕华 | C17: 54.3 | D17: 3800 | E17: 400 | H17: 1016 | I17: 王燕华 | J17: 3800 | K17: 400 | N17: =D17-J17 -> 0
A18: 1018 | B18: 白成滔 | C18: 27.5 | D18: 2000 | H18: 1018 | I18: 白成滔 | J18: 2700 | N18: =D18-J18 -> -700
A19: 1019 | B19: 杨桂芹（临） | C19: 27.15 | D19: 1600 | E19: 200 | H19: 1019 | I19: 杨桂芹 | J19: 1600 | K19: 200 | N19: =D19-J19 -> 0
A20: 1020 | H20: 1020 | N20: =D20-J20 -> 0
A21: 1021 | B21: 林春铸 | C21: 27.15 | D21: 4226 | E21: 500 | H21: 1021 | I21: 林春铸 | J21: =M24 -> 4226 | K21: 500 | N21: =D21-J21 -> 0
A22: 1022 | B22: 庄诗霖（临租） | C22: 56.26 | D22: 2531 | H22: 1022 | I22: 庄诗霖 | J22: 2531 | N22: =D22-J22 -> 0
A23: 1023 | B23: 赵德花（临仓） | C23: 31.79 | D23: 1000 | H23: 1023 | I23: 赵德花 | J23: 1000 | N23: =D23-J23 -> 0
A24: 1024 | B24: 王小军（临仓） | C24: 43.89 | D24: 1448 | H24: 1024 | I24: 王小军 | J24: 1448 | L24: 44413 | M24: 4226 | N24: =D24-J24 -> 0
A25: 1025 | B25: 林小武 | C25: 27.15 | D25: 4202 | E25: 500 | H25: 1025 | I25: 林小武 | J25: 4202 | K25: 500 | N25: =D25-J25 -> 0
A26: 1025-A | B26: 苏建柳 | C26: 26.45 | D26: 4202 | E26: 500 | H26: 1025-A | I26: 苏建柳 | J26: 4202 | K26: 500 | N26: =D26-J26 -> 0
A27: 1026 | B27: 林百光 | C27: 27.15 | D27: 4202 | E27: 500 | H27: 1026 | I27: 林百光 | J27: 4202 | K27: 500 | N27: =D27-J27 -> 0
A28: 1027 | H28: 1027 | N28: =D28-J28 -> 0
A29: 1028 | B29: 阮文宾 | C29: 27.15 | D29: 4202 | E29: 500 | H29: 1028 | I29: 阮文彬 | J29: 4202 | K29: 500 | N29: =D29-J29 -> 0
A30: 1029 | B30: 陈文超 | C30: 27.15 | D30: 4202 | E30: 500 | H30: 1029 | I30: 陈文超 | J30: 4202 | K30: 500 | N30: =D30-J30 -> 0
A31: 1030 | B31: 覃燕芬 | C31: 27.15 | D31: 4202 | E31: 500 | H31: 1030 | I31: 覃燕芬 | J31: =M34 -> 4202 | K31: 500 | N31: =D31-J31 -> 0
A32: 1031 | B32: 方海潮 | C32: 23.77 | D32: 4202 | E32: 500 | H32: 1031 | I32: 方海潮 | J32: 4202 | K32: 500 | N32: =D32-J32 -> 0
A33: 1032 | B33: 范琼静 | C33: 27.15 | D33: 4202 | E33: 500 | H33: 1032 | I33: 范琼静 | J33: 4202 | K33: 500 | N33: =D33-J33 -> 0
A34: 1033 | H34: 1033 | L34: 44470 | M34: 4202 | N34: =D34-J34 -> 0
A35: 1034 | H35: 1034 | N35: =D35-J35 -> 0
A36: 1035 | B36: 廖文怀 | C36: 27.15 | D36: 4202 | E36: 500 | H36: 1035 | I36: 廖文怀 | J36: 4202 | K36: 500 | N36: =D36-J36 -> 0
A37: 1036 | B37: 谢玲华 | C37: 27.15 | D37: 4202 | E37: 500 | H37: 1036 | I37: 谢玲华 | J37: 4202 | K37: 500 | N37: =D37-J37 -> 0
A38: 1037 | B38: 杨志鸿 | C38: 27.15 | D38: 4202 | E38: 500 | H38: 1037 | I38: 杨志鸿 | J38: 4202 | K38: 500 | N38: =D38-J38 -> 0
A39: 1038 | B39: 黄夏琼 | C39: 27.15 | D39: 4202 | E39: 500 | H39: 1038 | I39: 黄夏琼 | J39: 4202 | K39: 500 | N39: =D39-J39 -> 0
A40: 1039 | B40: 吴玉荡 | C40: 27.15 | D40: 4624 | E40: 500 | H40: 1039 | I40: 吴玉荡 | J40: 4624 | K40: 500 | N40: =D40-J40 -> 0
...

Sheet Sheet4
K9: 4月 | L9: 5月 | M9: 6月 | N9: 7月
J10: 实际折扣 | K10: 6折 | L10: 5折 | M10: 5折 | N10: 5折
F12: 1021 | G12: 林春铸 | H12: 27.15 | I12: 4226 | K12: =ROUND(I12*0.4,0) -> 1690 | L12: =ROUND(I12*0.5,0) -> 2113 | M12: =ROUND(I12*0.5,0) -> 2113 | N12: =I12*0.5 -> 2113
F13: 1044 | G13: 陈秋香 | H13: 27.15 | I13: 4202 | K13: =ROUND(I13*0.4,0) -> 1681 | L13: =ROUND(I13*0.5,0) -> 2101 | M13: =ROUND(I13*0.5,0) -> 2101 | N13: =I13*0.5 -> 2101
F14: 1065 | G14: 章芳琴 | H14: 6.21 | I14: 2240 | K14: =ROUND(I14*0.4,0) -> 896 | L14: =ROUND(I14*0.5,0) -> 1120 | M14: =ROUND(I14*0.5,0) -> 1120 | N14: =I14*0.5 -> 1120
K16: 4月 | L16: 5月 | M16: 6月 | N16: 7月
J17: 市场折扣 | K17: 8折 | L17: 6折 | M17: 7折 | N17: 8折
K18: =ROUND(4226*0.2,0) -> 845 | L18: =ROUND(4226*0.4,0) -> 1690 | M18: =ROUND(4226*0.3,0) -> 1268 | N18: =ROUND(4226*0.2,0) -> 845
K19: =ROUND(4202*0.2,0) -> 840 | L19: =ROUND(4202*0.4,0) -> 1681 | M19: =ROUND(4202*0.3,0) -> 1261 | N19: =ROUND(4202*0.2,0) -> 840
K20: =ROUND(2240*0.2,0) -> 448 | L20: =ROUND(2240*0.4,0) -> 896 | M20: =ROUND(2240*0.3,0) -> 672 | N20: =ROUND(2240*0.2,0) -> 448
J22: 差额 | K22: =K12-K18 -> 845 | L22: =L12-L18 -> 423 | M22: =M12-M18 -> 845 | N22: =N12-N18 -> 1268 | P22: =SUM(K22:N22) -> 3381
K23: =K13-K19 -> 841 | L23: =L13-L19 -> 420 | M23: =M13-M19 -> 840 | N23: =N13-N19 -> 1261 | P23: =SUM(K23:N23) -> 3362
K24: =K14-K20 -> 448 | L24: =L14-L20 -> 224 | M24: =M14-M20 -> 448 | N24: =N14-N20 -> 672 | P24: =SUM(K24:N24) -> 1792

Sheet 电表数

Sheet 空档数
C2: 截止空档数3.30
C3: 一楼商铺 | D3: 1034
C4: 一楼商铺 | D4: 1061
C5: 一楼展柜 | D5: 1068展柜(全包）
C6: 一楼展柜 | D6: 1069展柜(全包）
C7: 二楼档口 | D7: 2001 | E7: 被占用 | G7: 3.31号到期未续签 | I7: 2019
C8: 二楼档口 | D8: 2044 | G8: 1028 | I8: 2040
C9: 二楼档口 | D9: 2045 | G9: 1033 | I9: 2052
C10: 二楼档口 | D10: 2061 | G10: 1037 | I10: 4010
C11: 二楼档口 | D11: 2062 | G11: 1041 | I11: 4019 | M11: -
C12: 二楼档口 | D12: 2064 | G12: 1058 | M12: 2019 | N12: 林建婵（临） | O12: 19.54 | P12: 4000 | R12: 2019 | S12: 林建婵（临）
C13: 二楼档口 | D13: 2066 | G13: 2078 | M13: 2040 | N13: 钟士梅 | O13: 16.54 | P13: 4000 | R13: 2040 | S13: 钟士梅
C14: 二楼档口 | D14: 2067 | G14: 2081 | M14: 2052 | N14: 赖鑫（临） | O14: 16.54 | P14: 4000 | R14: 2052 | S14: 赖鑫（临）
C15: 二楼档口 | D15: 2070 | G15: 2088 | M15: 2063 | N15: 王金保 | O15: 16.54 | P15: 4000 | R15: 2063 | S15: 李恒耀
C16: 二楼档口 | D16: 2084 | G16: 3011 | M16: 3009 | N16: 陈强 | O16: 32.425 | P16: 5080 | R16: 3009 | S16: 陈强
C17: 二楼档口 | D17: 2086 | G17: 4040 | H17: 待定先不出 | M17: 4007 | N17: 刘艳霞 | O17: 32.425 | P17: 6378 | R17: 4007 | S17: 刘艳霞
C18: 二楼档口 | D18: 2087 | M18: 4010 | N18: 李声亮 | O18: 32.425 | P18: 5650 | R18: 4010 | S18: 李声亮
C19: 二楼展柜 | D19: 2093展柜 | M19: 4011 | N19: 申俊强 | O19: 32.425 | P19: 6560 | R19: 4011 | S19: 申俊强
C20: 二楼展柜 | D20: 2095展柜 | M20: 4015 | N20: 罗银送 | O20: 32.425 | P20: 5792 | R20: 4015 | S20: 罗银送
C21: 二楼展柜 | D21: 2096展柜 | M21: 4018 | N21: 唐雄英 | O21: 32.425 | P21: 6560 | R21: 4018 | S21: 唐雄英
C22: 三楼档口 | D22: 3023 | M22: 4019 | N22: 黄叶乐 | O22: 32.425 | P22: 5650 | R22: 4019 | S22: 黄叶乐
C23: 三楼档口 | D23: 3030 | M23: 4030 | N23: 余海城 | O23: 32.425 | P23: 6558 | R23: 4030 | S23: 余海城
C24: 三楼档口 | D24: 3040 | M24: 5020 | N24: 刘艳林 | O24: 32.425 | P24: 6102 | R24: 5020 | S24: 刘艳林
C25: 三楼展柜 | D25: 三楼自编展柜 | M25: 5023 | N25: 宋丽丽 | O25: 32.425 | P25: 6102 | R25: 5023 | S25: 宋丽丽
C26: 四楼档口 | D26: 4004
C27: 四楼档口 | D27: 4006
C28: 四楼档口 | D28: 4016
C29: 四楼档口 | D29: 4023
C30: 四楼档口 | D30: 4026
C31: 四楼档口 | D31: 4033
C32: 四楼档口 | D32: 4044
C33: 四楼展柜 | D33: 四楼展柜
C34: 五楼档口 | D34: 5011
C35: 五楼档口 | D35: 5013A
C36: 五楼档口 | D36: 5018
C37: 五楼档口 | D37: 5019
C38: 五楼档口 | D38: 5021
C39: 五楼档口 | D39: 5026
C40: 五楼档口 | D40: 5027
C41: 五楼档口 | D41: 5037
...

Sheet Sheet1
A3: 楼层 | B3: 商铺号 | C3: 商户名 | D3: 面积 | E3: 租金 | F3: 管理费 | H3: 档号 | I3: 档主名 | Q3: 计租日 | R3: 递增日（2021） | S3: 递增金额 | T3: 递增日（2022） | U3: 递增金额
J4: 总租金 | K4: 管理费
A5: 一楼商铺 | B5: 1001-01（临一） | C5: 陈良伟 | D5: 19.5 | E5: 3052 | F5: 210 | H5: 1001-01（临一） | I5: 陈良伟 | J5: =U5 -> 3052 | K5: 210 | M5: =E5-J5 -> 0 | N5: =F5-K5 -> 0 | Q5: 43891 | R5: 44256 | S5: 2906 | T5: 44621 | U5: 3052
A6: 一楼商铺 | B6: 1001 | C6: 邓凤强 | D6: 21.87 | E6: 4202 | F6: 500 | H6: 1001 | I6: 邓凤强 | J6: 4202 | K6: 500 | M6: =E6-J6 -> 0 | N6: =F6-K6 -> 0 | Q6: 44652
A7: 一楼商铺 | B7: 1002 | C7: 苏建柳 | D7: 27.87 | E7: 3000 | H7: 1002 | I7: 苏建柳 | J7: 3000 | M7: =E7-J7 -> 0 | N7: =F7-K7 -> 0 | Q7: 44348
A8: 一楼商铺 | B8: 1003/1004 | C8: 陈汉真 | D8: 49.02 | E8: 2851 | F8: 400 | H8: 1003-1004 | I8: 陈汉真 | J8: 2851 | K8: 400 | M8: =E8-J8 -> 0 | N8: =F8-K8 -> 0 | Q8: 44348
A9: 一楼商铺 | B9: 1005 | C9: 林翠侠 | D9: 27.15 | E9: 2000 | H9: 1005 | I9: 林翠侠 | J9: 2000 | M9: =E9-J9 -> 0 | N9: =F9-K9 -> 0 | Q9: 44548
A10: 一楼商铺 | B10: 1006 | C10: 谢伟明 | D10: 27.15 | E10: 4412 | F10: 500 | H10: 1006 | I10: 谢伟明 | J10: =U10 -> 4412 | K10: 500 | M10: =E10-J10 -> 0 | N10: =F10-K10 -> 0 | Q10: 44440 | T10: 44652 | U10: 4412
A11: 一楼商铺 | B11: 1007 | C11: 苏碧兰 | D11: 27.15 | E11: 3994 | F11: 500 | H11: 1007 | I11: 苏碧兰 | J11: 3994 | K11: 500 | M11: =E11-J11 -> 0 | N11: =F11-K11 -> 0 | Q11: 44378 | T11: 44743 | U11: =1997*2 -> 3994
A12: 一楼商铺 | B12: 1008 | C12: 陈汉真（临租） | D12: 27.15 | E12: 1600 | H12: 1008 | I12: 陈汉真 | J12: 1600 | K12: 0 | M12: =E12-J12 -> 0 | N12: =F12-K12 -> 0 | Q12: 44640
A13: 一楼商铺 | B13: 1009 | C13: 林丽情 | D13: 27.15 | E13: 4202 | F13: 500 | H13: 1009 | I13: 林丽情 | J13: 4202 | K13: 500 | M13: =E13-J13 -> 0 | N13: =F13-K13 -> 0 | Q13: 44621
A14: 一楼商铺 | B14: 1010 | C14: 包君威 | D14: 23.77 | E14: 4202 | F14: 500 | H14: 1010 | I14: 魏丽绚 | J14: =S14 -> 4202 | K14: 500 | M14: =E14-J14 -> 0 | N14: =F14-K14 -> 0 | Q14: 43556 | R14: 44287 | S14: 4202
A15: 一楼商铺 | B15: 1011 | C15: 唐丹凤 | D15: 27.15 | E15: 3000 | H15: 1011 | I15: 唐丹凤 | J15: 3000 | M15: =E15-J15 -> 0 | N15: =F15-K15 -> 0 | Q15: 44531
A16: 一楼商铺 | B16: 1012 | C16: 薛扬 | D16: 27.5 | E16: 2500 | H16: 1012 | I16: 薛扬 | J16: 2500 | M16: =E16-J16 -> 0 | N16: =F16-K16 -> 0 | Q16: 44531
A17: 一楼商铺 | B17: 1013 | C17: 陈金俊 | D17: 27.15 | E17: 2500 | H17: 1013 | I17: 陈金俊 | J17: 2500 | M17: =E17-J17 -> 0 | N17: =F17-K17 -> 0 | Q17: 44378 | T17: 44743 | U17: 2500
A18: 一楼商铺 | B18: 1014/1015 | C18: 王奎（临租） | D18: 54.3 | E18: 3000 | H18: 1014-15 | I18: 王奎 | J18: 3000 | M18: =E18-J18 -> 0 | N18: =F18-K18 -> 0 | Q18: 43937
A19: 一楼商铺 | B19: 1016/1017 | C19: 王燕华 | D19: 54.3 | E19: 3800 | F19: 400 | H19: 1016-17 | I19: 王燕华 | J19: 3800 | K19: 400 | M19: =E19-J19 -> 0 | N19: =F19-K19 -> 0 | Q19: 44423
A20: 一楼商铺 | B20: 1018 | C20: 白成滔 | D20: 27.5 | E20: 2700 | H20: 1018 | I20: 白成滔 | J20: 2700 | M20: =E20-J20 -> 0 | N20: =F20-K20 -> 0 | Q20: 44348
A21: 一楼商铺 | B21: 1019 | C21: 杨桂芹（临） | D21: 27.15 | E21: 1600 | F21: 200 | H21: 1019 | I21: 杨桂芹 | J21: 1600 | K21: 200 | M21: =E21-J21 -> 0 | N21: =F21-K21 -> 0
A22: 一楼商铺 | B22: 1020 | C22: 林茂 | D22: 27.15 | E22: 4000 | H22: 1020 | I22: 林茂 | J22: 4000 | M22: =E22-J22 -> 0 | N22: =F22-K22 -> 0 | Q22: 44362 | T22: 44727 | U22: 4000
A23: 一楼商铺 | B23: 1021 | C23: 林春铸 | D23: 27.15 | E23: 4226 | F23: 500 | H23: 1021 | I23: 林春铸 | J23: =S23 -> 4226 | K23: 500 | M23: =E23-J23 -> 0 | N23: =F23-K23 -> 0 | Q23: 43682 | R23: 44413 | S23: 4226
A24: 一楼商铺 | B24: 1022 | C24: 庄诗霖（临租） | D24: 56.26 | E24: 2531 | H24: 1022 | I24: 庄诗霖 | J24: 2531 | M24: =E24-J24 -> 0 | N24: =F24-K24 -> 0
A25: 一楼商铺 | B25: 1023 | C25: 赵德花（临仓） | D25: 31.79 | E25: 1000 | H25: 1023 | I25: 赵德花 | J25: 1000 | M25: =E25-J25 -> 0 | N25: =F25-K25 -> 0 | Q25: 43831
A26: 一楼商铺 | B26: 1024 | C26: 王小军（临仓） | D26: 43.89 | E26: 1448 | H26: 1024 | I26: 王小军 | J26: 1448 | M26: =E26-J26 -> 0 | N26: =F26-K26 -> 0
A27: 一楼商铺 | B27: 1025 | C27: 林小武 | D27: 27.15 | E27: 4202 | F27: 500 | H27: 1025 | I27: 林小武 | J27: 4202 | K27: 500 | M27: =E27-J27 -> 0 | N27: =F27-K27 -> 0 | Q27: 44652
A28: 一楼商铺 | B28: 1025-A | C28: 苏建柳 | D28: 26.45 | E28: 4202 | F28: 500 | H28: 1025-A | I28: 苏建柳 | J28: 4202 | K28: 500 | M28: =E28-J28 -> 0 | N28: =F28-K28 -> 0 | Q28: 44621
A29: 一楼商铺 | B29: 1026 | C29: 林百光 | D29: 27.15 | E29: 4202 | F29: 500 | H29: 1026 | I29: 林百光 | J29: 4202 | K29: 500 | M29: =E29-J29 -> 0 | N29: =F29-K29 -> 0 | Q29: 44652
A30: 一楼商铺 | B30: 1027 | C30: 吴建忠 | D30: 27.15 | E30: 4202 | F30: 500 | H30: 1027 | I30: 吴建忠 | J30: =S30 -> 4202 | K30: 500 | M30: =E30-J30 -> 0 | N30: =F30-K30 -> 0 | Q30: 43739 | R30: 44287 | S30: 4202
A31: 一楼商铺 | B31: 1028 | C31: 李晓彩 | D31: 27.15 | E31: 4202 | F31: 500 | H31: 1028 | I31: 李晓彩 | J31: =S31 -> 4202 | K31: 500 | M31: =E31-J31 -> 0 | N31: =F31-K31 -> 0 | Q31: 43556 | R31: 44287 | S31: 4202
A32: 一楼商铺 | B32: 1029 | C32: 陈文超 | D32: 27.15 | E32: 4202 | F32: 500 | H32: 1029 | I32: 陈文超 | J32: 4202 | K32: 500 | M32: =E32-J32 -> 0 | N32: =F32-K32 -> 0 | Q32: 44652
A33: 一楼商铺 | B33: 1030 | C33: 覃燕芬 | D33: 27.15 | E33: 4202 | F33: 500 | H33: 1030 | I33: 覃燕芬 | J33: =S33 -> 4202 | K33: 500 | M33: =E33-J33 -> 0 | N33: =F33-K33 -> 0 | Q33: 43739 | R33: 44470 | S33: 4202
A34: 一楼商铺 | B34: 1031 | C34: 方海潮 | D34: 23.77 | E34: 4202 | F34: 500 | H34: 1031 | I34: 方海潮 | J34: 4202 | K34: 500 | M34: =E34-J34 -> 0 | N34: =F34-K34 -> 0 | Q34: 44652
A35: 一楼商铺 | B35: 1032 | C35: 范琼静 | D35: 27.15 | E35: 4202 | F35: 500 | H35: 1032 | I35: 范琼静 | J35: 4202 | K35: 500 | M35: =E35-J35 -> 0 | N35: =F35-K35 -> 0 | Q35: 44652
A36: 一楼商铺 | B36: 1033 | C36: 文千红 | D36: 27.15 | E36: 4202 | F36: 500 | H36: 1033 | I36: 文千红 | J36: =S36 -> 4202 | K36: 500 | M36: =E36-J36 -> 0 | N36: =F36-K36 -> 0 | Q36: 43556 | R36: 44287 | S36: 4202
A37: 一楼商铺 | B37: 1034 | H37: 1034 | M37: =E37-J37 -> 0 | N37: =F37-K37 -> 0
A38: 一楼商铺 | B38: 1035 | C38: 廖文怀 | D38: 27.15 | E38: 4202 | F38: 500 | H38: 1035 | I38: 廖文怀 | J38: 4202 | K38: 500 | M38: =E38-J38 -> 0 | N38: =F38-K38 -> 0 | Q38: 44652
A39: 一楼商铺 | B39: 1036 | C39: 谢玲华 | D39: 27.15 | E39: 4202 | F39: 500 | H39: 1036 | I39: 谢玲华 | J39: 4202 | K39: 500 | M39: =E39-J39 -> 0 | N39: =F39-K39 -> 0 | Q39: 44652
A40: 一楼商铺 | B40: 1037 | C40: 杨志鸿 | D40: 27.15 | E40: 4202 | H40: 1037 | I40: 杨志鸿 | J40: =S40 -> 4202 | K40: 500 | M40: =E40-J40 -> 0 | N40: =F40-K40 -> -500 | Q40: 43556 | R40: 44287 | S40: 4202
A41: 一楼商铺 | B41: 1038 | C41: 黄夏琼 | D41: 27.15 | E41: 4202 | F41: 500 | H41: 1038 | I41: 黄夏琼 | J41: 4202 | K41: 500 | M41: =E41-J41 -> 0 | N41: =F41-K41 -> 0 | Q41: 44652
A42: 一楼商铺 | B42: 1039 | C42: 吴玉荡 | D42: 27.15 | E42: 4624 | F42: 500 | H42: 1039 | I42: 吴玉荡 | J42: =U42 -> 4624 | K42: 500 | M42: =E42-J42 -> 0 | N42: =F42-K42 -> 0 | Q42: 44228 | T42: 44593 | U42: 4624
...
