Workbook

Sheet 1月
A1: 姓名 | B1: 性别 | C1: 合同种类 | D1: 基本工资 | E1: 岗位工资 | F1: 工龄工资 | G1: 补贴 | H1: 医疗补助 | I1: 奖金 | J1: 考勤扣款 | K1: 住房公积金 | L1: 养老保险 | M1: 医疗保险 | N1: 失业保险 | O1: 个人所得税 | P1: 应发合计 | Q1: 应扣合计 | R1: 实发合计
A2: A001 | B2: =VLOOKUP(A2,员工资料!A:C,2,FALSE) -> 男 | C2: =VLOOKUP(A2,员工资料!A:C,3,FALSE) -> 合同工 | D2: 2975 | E2: 441 | F2: 60 | G2: 900 | H2: 354 | I2: 332 | J2: 100 | K2: 404.96 | L2: 303.72 | M2: 43.74 | N2: 139.68 | O2: =IF(P2-SUM(K2:N2)<=2000,0,IF(P2-SUM(K2:N2)<=4000,0+(P2-SUM(K2:N2)-2000)*0.03,IF(P2-SUM(K2:N2)<=8000,0+2000*0.03+(P2-SUM(K2:N2)-4000)*0.08,0+2000*0.03+4000*0.08+(P2-SUM(K2:N2)-8000)*0.1))) -> 65.592 | P2: =D2+E2+F2+G2+H2+I2-J2 -> 4962 | Q2: =K2+L2+M2+N2+O2 -> 957.692 | R2: =P2-Q2 -> 4004.308
A3: A002 | B3: =VLOOKUP(A3,员工资料!A:C,2,FALSE) -> 男 | C3: =VLOOKUP(A3,员工资料!A:C,3,FALSE) -> 合同工 | D3: 2637 | E3: 429 | F3: 110 | G3: 835 | H3: 594 | I3: 568 | J3: 81 | K3: 413.84 | L3: 310.38 | M3: 50.72 | N3: 168.56 | O3: =IF(P3-SUM(K3:N3)<=2000,0,IF(P3-SUM(K3:N3)<=4000,0+(P3-SUM(K3:N3)-2000)*0.03,IF(P3-SUM(K3:N3)<=8000,0+2000*0.03+(P3-SUM(K3:N3)-4000)*0.08,0+2000*0.03+4000*0.08+(P3-SUM(K3:N3)-8000)*0.1))) -> 71.88 | P3: =D3+E3+F3+G3+H3+I3-J3 -> 5092 | Q3: =K3+L3+M3+N3+O3 -> 1015.38 | R3: =P3-Q3 -> 4076.62
A4: A005 | B4: =VLOOKUP(A4,员工资料!A:C,2,FALSE) -> 女 | C4: =VLOOKUP(A4,员工资料!A:C,3,FALSE) -> 合同工 | D4: 4691 | E4: 320 | F4: 210 | G4: 1229 | H4: 277 | I4: 494 | J4: 16 | K4: 577.68 | L4: 433.26 | M4: 50.6 | N4: 176.8 | O4: =IF(P4-SUM(K4:N4)<=2000,0,IF(P4-SUM(K4:N4)<=4000,0+(P4-SUM(K4:N4)-2000)*0.03,IF(P4-SUM(K4:N4)<=8000,0+2000*0.03+(P4-SUM(K4:N4)-4000)*0.08,0+2000*0.03+4000*0.08+(P4-SUM(K4:N4)-8000)*0.1))) -> 217.3328 | P4: =D4+E4+F4+G4+H4+I4-J4 -> 7205 | Q4: =K4+L4+M4+N4+O4 -> 1455.6728 | R4: =P4-Q4 -> 5749.3272
A5: A006 | B5: =VLOOKUP(A5,员工资料!A:C,2,FALSE) -> 女 | C5: =VLOOKUP(A5,员工资料!A:C,3,FALSE) -> 合同工 | D5: 5282 | E5: 323 | F5: 270 | G5: 910 | H5: 492 | I5: 255 | J5: 62 | K5: 602.56 | L5: 451.92 | M5: 46.24 | N5: 159.12 | O5: =IF(P5-SUM(K5:N5)<=2000,0,IF(P5-SUM(K5:N5)<=4000,0+(P5-SUM(K5:N5)-2000)*0.03,IF(P5-SUM(K5:N5)<=8000,0+2000*0.03+(P5-SUM(K5:N5)-4000)*0.08,0+2000*0.03+4000*0.08+(P5-SUM(K5:N5)-8000)*0.1))) -> 236.8128 | P5: =D5+E5+F5+G5+H5+I5-J5 -> 7470 | Q5: =K5+L5+M5+N5+O5 -> 1496.6528 | R5: =P5-Q5 -> 5973.3472
A6: A008 | B6: =VLOOKUP(A6,员工资料!A:C,2,FALSE) -> 男 | C6: =VLOOKUP(A6,员工资料!A:C,3,FALSE) -> 合同工 | D6: 4233 | E6: 549 | F6: 230 | G6: 1032 | H6: 248 | I6: 414 | J6: 53 | K6: 536.48 | L6: 402.36 | M6: 50.52 | N6: 158.16 | O6: =IF(P6-SUM(K6:N6)<=2000,0,IF(P6-SUM(K6:N6)<=4000,0+(P6-SUM(K6:N6)-2000)*0.03,IF(P6-SUM(K6:N6)<=8000,0+2000*0.03+(P6-SUM(K6:N6)-4000)*0.08,0+2000*0.03+4000*0.08+(P6-SUM(K6:N6)-8000)*0.1))) -> 180.4384 | P6: =D6+E6+F6+G6+H6+I6-J6 -> 6653 | Q6: =K6+L6+M6+N6+O6 -> 1327.9584 | R6: =P6-Q6 -> 5325.0416
A7: A010 | B7: =VLOOKUP(A7,员工资料!A:C,2,FALSE) -> 男 | C7: =VLOOKUP(A7,员工资料!A:C,3,FALSE) -> 合同工 | D7: 4765 | E7: 374 | F7: 170 | G7: 714 | H7: 331 | I7: 463 | J7: 29 | K7: 545.36 | L7: 409.02 | M7: 41.04 | N7: 134.24 | O7: =IF(P7-SUM(K7:N7)<=2000,0,IF(P7-SUM(K7:N7)<=4000,0+(P7-SUM(K7:N7)-2000)*0.03,IF(P7-SUM(K7:N7)<=8000,0+2000*0.03+(P7-SUM(K7:N7)-4000)*0.08,0+2000*0.03+4000*0.08+(P7-SUM(K7:N7)-8000)*0.1))) -> 192.6672 | P7: =D7+E7+F7+G7+H7+I7-J7 -> 6788 | Q7: =K7+L7+M7+N7+O7 -> 1322.3272 | R7: =P7-Q7 -> 5465.6728
A8: A016 | B8: =VLOOKUP(A8,员工资料!A:C,2,FALSE) -> 女 | C8: =VLOOKUP(A8,员工资料!A:C,3,FALSE) -> 合同工 | D8: 4519 | E8: 534 | F8: 260 | G8: 1162 | H8: 277 | I8: 367 | J8: 130 | K8: 569.52 | L8: 427.14 | M8: 52.96 | N8: 173.36 | O8: =IF(P8-SUM(K8:N8)<=2000,0,IF(P8-SUM(K8:N8)<=4000,0+(P8-SUM(K8:N8)-2000)*0.03,IF(P8-SUM(K8:N8)<=8000,0+2000*0.03+(P8-SUM(K8:N8)-4000)*0.08,0+2000*0.03+4000*0.08+(P8-SUM(K8:N8)-8000)*0.1))) -> 201.2816 | P8: =D8+E8+F8+G8+H8+I8-J8 -> 6989 | Q8: =K8+L8+M8+N8+O8 -> 1424.2616 | R8: =P8-Q8 -> 5564.7384
A9: A003 | B9: =VLOOKUP(A9,员工资料!A:C,2,FALSE) -> 女 | C9: =VLOOKUP(A9,员工资料!A:C,3,FALSE) -> 劳务工 | D9: 5688 | E9: 279 | F9: 290 | G9: 963 | H9: 493 | I9: 242 | J9: 0 | K9: 636.4 | L9: 477.3 | M9: 45.34 | N9: 159.04 | O9: =IF(P9-SUM(K9:N9)<=2000,0,IF(P9-SUM(K9:N9)<=4000,0+(P9-SUM(K9:N9)-2000)*0.03,IF(P9-SUM(K9:N9)<=8000,0+2000*0.03+(P9-SUM(K9:N9)-4000)*0.08,0+2000*0.03+4000*0.08+(P9-SUM(K9:N9)-8000)*0.1))) -> 270.9536 | P9: =D9+E9+F9+G9+H9+I9-J9 -> 7955 | Q9: =K9+L9+M9+N9+O9 -> 1589.0336 | R9: =P9-Q9 -> 6365.9664
A10: A004 | B10: =VLOOKUP(A10,员工资料!A:C,2,FALSE) -> 男 | C10: =VLOOKUP(A10,员工资料!A:C,3,FALSE) -> 劳务工 | D10: 2981 | E10: 296 | F10: 200 | G10: 778 | H10: 595 | I10: 383 | J10: 54 | K10: 418.64 | L10: 313.98 | M10: 45.04 | N10: 159.6 | O10: =IF(P10-SUM(K10:N10)<=2000,0,IF(P10-SUM(K10:N10)<=4000,0+(P10-SUM(K10:N10)-2000)*0.03,IF(P10-SUM(K10:N10)<=8000,0+2000*0.03+(P10-SUM(K10:N10)-4000)*0.08,0+2000*0.03+4000*0.08+(P10-SUM(K10:N10)-8000)*0.1))) -> 79.3392 | P10: =D10+E10+F10+G10+H10+I10-J10 -> 5179 | Q10: =K10+L10+M10+N10+O10 -> 1016.5992 | R10: =P10-Q10 -> 4162.4008
A11: A007 | B11: =VLOOKUP(A11,员工资料!A:C,2,FALSE) -> 男 | C11: =VLOOKUP(A11,员工资料!A:C,3,FALSE) -> 劳务工 | D11: 5642 | E11: 242 | F11: 170 | G11: 1029 | H11: 453 | I11: 382 | J11: 76 | K11: 633.44 | L11: 475.08 | M11: 47.04 | N11: 168.8 | O11: =IF(P11-SUM(K11:N11)<=2000,0,IF(P11-SUM(K11:N11)<=4000,0+(P11-SUM(K11:N11)-2000)*0.03,IF(P11-SUM(K11:N11)<=8000,0+2000*0.03+(P11-SUM(K11:N11)-4000)*0.08,0+2000*0.03+4000*0.08+(P11-SUM(K11:N11)-8000)*0.1))) -> 261.4112 | P11: =D11+E11+F11+G11+H11+I11-J11 -> 7842 | Q11: =K11+L11+M11+N11+O11 -> 1585.7712 | R11: =P11-Q11 -> 6256.2288
A12: A009 | B12: =VLOOKUP(A12,员工资料!A:C,2,FALSE) -> 男 | C12: =VLOOKUP(A12,员工资料!A:C,3,FALSE) -> 劳务工 | D12: 2863 | E12: 260 | F12: 220 | G12: 884 | H12: 201 | I12: 415 | J12: 51 | K12: 387.44 | L12: 290.58 | M12: 40.38 | N12: 141.68 | O12: =IF(P12-SUM(K12:N12)<=2000,0,IF(P12-SUM(K12:N12)<=4000,0+(P12-SUM(K12:N12)-2000)*0.03,IF(P12-SUM(K12:N12)<=8000,0+2000*0.03+(P12-SUM(K12:N12)-4000)*0.08,0+2000*0.03+4000*0.08+(P12-SUM(K12:N12)-8000)*0.1))) -> 57.9576 | P12: =D12+E12+F12+G12+H12+I12-J12 -> 4792 | Q12: =K12+L12+M12+N12+O12 -> 918.0376 | R12: =P12-Q12 -> 3873.9624
A13: A011 | B13: =VLOOKUP(A13,员工资料!A:C,2,FALSE) -> 女 | C13: =VLOOKUP(A13,员工资料!A:C,3,FALSE) -> 劳务工 | D13: 4622 | E13: 444 | F13: 50 | G13: 1250 | H13: 431 | I13: 504 | J13: 46 | K13: 584.08 | L13: 438.06 | M13: 53.58 | N13: 178.8 | O13: =IF(P13-SUM(K13:N13)<=2000,0,IF(P13-SUM(K13:N13)<=4000,0+(P13-SUM(K13:N13)-2000)*0.03,IF(P13-SUM(K13:N13)<=8000,0+2000*0.03+(P13-SUM(K13:N13)-4000)*0.08,0+2000*0.03+4000*0.08+(P13-SUM(K13:N13)-8000)*0.1))) -> 220.0384 | P13: =D13+E13+F13+G13+H13+I13-J13 -> 7255 | Q13: =K13+L13+M13+N13+O13 -> 1474.5584 | R13: =P13-Q13 -> 5780.4416
... A17: A015 | B17: =VLOOKUP(A17,员工资料!A:C,2,FALSE) -> 男 | C17: =VLOOKUP(A17,员工资料!A:C,3,FALSE) -> 劳务工 | D17: 3040 | E17: 543 | F17: 280 | G17: 1013 | H17: 211 | I17: 596 | J17: 87 | K17: 454.64 | L17: 340.98 | M17: 52.86 | N17: 174.96 | O17: =IF(P17-SUM(K17:N17)<=2000,0,IF(P17-SUM(K17:N17)<=4000,0+(P17-SUM(K17:N17)-2000)*0.03,IF(P17-SUM(K17:N17)<=8000,0+2000*0.03+(P17-SUM(K17:N17)-4000)*0.08,0+2000*0.03+4000*0.08+(P17-SUM(K17:N17)-8000)*0.1))) -> 105.8048 | P17: =D17+E17+F17+G17+H17+I17-J17 -> 5596 | Q17: =K17+L17+M17+N17+O17 -> 1129.2448 | R17: =P17-Q17 -> 4466.7552

Sheet 2月
A1: 姓名 | B1: 性别 | C1: 合同种类 | D1: 基本工资 | E1: 岗位工资 | F1: 工龄工资 | G1: 补贴 | H1: 医疗补助 | I1: 奖金 | J1: 考勤扣款 | K1: 住房公积金 | L1: 养老保险 | M1: 医疗保险 | N1: 失业保险 | O1: 个人所得税 | P1: 应发合计 | Q1: 应扣合计 | R1: 实发合计
A2: A001 | B2: =VLOOKUP(A2,员工资料!A:C,2,FALSE) -> 男 | C2: =VLOOKUP(A2,员工资料!A:C,3,FALSE) -> 合同工 | D2: 3619 | E2: 330 | F2: 90 | G2: 1079 | H2: 414 | I2: 318 | J2: 100 | K2: 468 | L2: 351 | M2: 46.62 | N2: 160.08 | O2: =IF(P2-SUM(K2:N2)<=2000,0,IF(P2-SUM(K2:N2)<=4000,0+(P2-SUM(K2:N2)-2000)*0.03,IF(P2-SUM(K2:N2)<=8000,0+2000*0.03+(P2-SUM(K2:N2)-4000)*0.08,0+2000*0.03+4000*0.08+(P2-SUM(K2:N2)-8000)*0.1))) -> 117.944 | P2: =D2+E2+F2+G2+H2+I2-J2 -> 5750 | Q2: =K2+L2+M2+N2+O2 -> 1143.644 | R2: =P2-Q2 -> 4606.356
A3: A002 | B3: =VLOOKUP(A3,员工资料!A:C,2,FALSE) -> 男 | C3: =VLOOKUP(A3,员工资料!A:C,3,FALSE) -> 合同工 | D3: 5303 | E3: 597 | F3: 90 | G3: 747 | H3: 228 | I3: 377 | J3: 81 | K3: 587.36 | L3: 440.52 | M3: 40.78 | N3: 115.36 | O3: =IF(P3-SUM(K3:N3)<=2000,0,IF(P3-SUM(K3:N3)<=4000,0+(P3-SUM(K3:N3)-2000)*0.03,IF(P3-SUM(K3:N3)<=8000,0+2000*0.03+(P3-SUM(K3:N3)-4000)*0.08,0+2000*0.03+4000*0.08+(P3-SUM(K3:N3)-8000)*0.1))) -> 226.1584 | P3: =D3+E3+F3+G3+H3+I3-J3 -> 7261 | Q3: =K3+L3+M3+N3+O3 -> 1410.1784 | R3: =P3-Q3 -> 5850.8216
A4: A005 | B4: =VLOOKUP(A4,员工资料!A:C,2,FALSE) -> 女 | C4: =VLOOKUP(A4,员工资料!A:C,3,FALSE) -> 合同工 | D4: 3638 | E4: 312 | F4: 170 | G4: 1096 | H4: 541 | I4: 372 | J4: 16 | K4: 490.32 | L4: 367.74 | M4: 49.82 | N4: 174.32 | O4: =IF(P4-SUM(K4:N4)<=2000,0,IF(P4-SUM(K4:N4)<=4000,0+(P4-SUM(K4:N4)-2000)*0.03,IF(P4-SUM(K4:N4)<=8000,0+2000*0.03+(P4-SUM(K4:N4)-4000)*0.08,0+2000*0.03+4000*0.08+(P4-SUM(K4:N4)-8000)*0.1))) -> 142.464 | P4: =D4+E4+F4+G4+H4+I4-J4 -> 6113 | Q4: =K4+L4+M4+N4+O4 -> 1224.664 | R4: =P4-Q4 -> 4888.336
A5: A006 | B5: =VLOOKUP(A5,员工资料!A:C,2,FALSE) -> 女 | C5: =VLOOKUP(A5,员工资料!A:C,3,FALSE) -> 合同工 | D5: 5878 | E5: 506 | F5: 120 | G5: 927 | H5: 286 | I5: 555 | J5: 62 | K5: 661.76 | L5: 496.32 | M5: 49.12 | N5: 156 | O5: =IF(P5-SUM(K5:N5)<=2000,0,IF(P5-SUM(K5:N5)<=4000,0+(P5-SUM(K5:N5)-2000)*0.03,IF(P5-SUM(K5:N5)<=8000,0+2000*0.03+(P5-SUM(K5:N5)-4000)*0.08,0+2000*0.03+4000*0.08+(P5-SUM(K5:N5)-8000)*0.1))) -> 287.744 | P5: =D5+E5+F5+G5+H5+I5-J5 -> 8210 | Q5: =K5+L5+M5+N5+O5 -> 1650.944 | R5: =P5-Q5 -> 6559.056
A6: A008 | B6: =VLOOKUP(A6,员工资料!A:C,2,FALSE) -> 男 | C6: =VLOOKUP(A6,员工资料!A:C,3,FALSE) -> 合同工 | D6: 3505 | E6: 307 | F6: 240 | G6: 1001 | H6: 372 | I6: 234 | J6: 53 | K6: 452.72 | L6: 339.54 | M6: 44.14 | N6: 152 | O6: =IF(P6-SUM(K6:N6)<=2000,0,IF(P6-SUM(K6:N6)<=4000,0+(P6-SUM(K6:N6)-2000)*0.03,IF(P6-SUM(K6:N6)<=8000,0+2000*0.03+(P6-SUM(K6:N6)-4000)*0.08,0+2000*0.03+4000*0.08+(P6-SUM(K6:N6)-8000)*0.1))) -> 109.408 | P6: =D6+E6+F6+G6+H6+I6-J6 -> 5606 | Q6: =K6+L6+M6+N6+O6 -> 1097.808 | R6: =P6-Q6 -> 4508.192
A7: A010 | B7: =VLOOKUP(A7,员工资料!A:C,2,FALSE) -> 男 | C7: =VLOOKUP(A7,员工资料!A:C,3,FALSE) -> 合同工 | D7: 6147 | E7: 374 | F7: 250 | G7: 772 | H7: 389 | I7: 534 | J7: 29 | K7: 677.28 | L7: 507.96 | M7: 46.38 | N7: 155.6 | O7: =IF(P7-SUM(K7:N7)<=2000,0,IF(P7-SUM(K7:N7)<=4000,0+(P7-SUM(K7:N7)-2000)*0.03,IF(P7-SUM(K7:N7)<=8000,0+2000*0.03+(P7-SUM(K7:N7)-4000)*0.08,0+2000*0.03+4000*0.08+(P7-SUM(K7:N7)-8000)*0.1))) -> 303.9824 | P7: =D7+E7+F7+G7+H7+I7-J7 -> 8437 | Q7: =K7+L7+M7+N7+O7 -> 1691.2024 | R7: =P7-Q7 -> 6745.7976
A8: A016 | B8: =VLOOKUP(A8,员工资料!A:C,2,FALSE) -> 女 | C8: =VLOOKUP(A8,员工资料!A:C,3,FALSE) -> 合同工 | D8: 3998 | E8: 204 | F8: 240 | G8: 1209 | H8: 227 | I8: 600 | J8: 130 | K8: 518.24 | L8: 388.68 | M8: 50.56 | N8: 190.16 | O8: =IF(P8-SUM(K8:N8)<=2000,0,IF(P8-SUM(K8:N8)<=4000,0+(P8-SUM(K8:N8)-2000)*0.03,IF(P8-SUM(K8:N8)<=8000,0+2000*0.03+(P8-SUM(K8:N8)-4000)*0.08,0+2000*0.03+4000*0.08+(P8-SUM(K8:N8)-8000)*0.1))) -> 156.0288 | P8: =D8+E8+F8+G8+H8+I8-J8 -> 6348 | Q8: =K8+L8+M8+N8+O8 -> 1303.6688 | R8: =P8-Q8 -> 5044.3312
A9: A003 | B9: =VLOOKUP(A9,员工资料!A:C,2,FALSE) -> 女 | C9: =VLOOKUP(A9,员工资料!A:C,3,FALSE) -> 劳务工 | D9: 4904 | E9: 546 | F9: 150 | G9: 714 | H9: 412 | I9: 508 | J9: 0 | K9: 578.72 | L9: 434.04 | M9: 46.6 | N9: 142.72 | O9: =IF(P9-SUM(K9:N9)<=2000,0,IF(P9-SUM(K9:N9)<=4000,0+(P9-SUM(K9:N9)-2000)*0.03,IF(P9-SUM(K9:N9)<=8000,0+2000*0.03+(P9-SUM(K9:N9)-4000)*0.08,0+2000*0.03+4000*0.08+(P9-SUM(K9:N9)-8000)*0.1))) -> 222.5536 | P9: =D9+E9+F9+G9+H9+I9-J9 -> 7234 | Q9: =K9+L9+M9+N9+O9 -> 1424.6336 | R9: =P9-Q9 -> 5809.3664
A10: A004 | B10: =VLOOKUP(A10,员工资料!A:C,2,FALSE) -> 男 | C10: =VLOOKUP(A10,员工资料!A:C,3,FALSE) -> 劳务工 | D10: 5784 | E10: 380 | F10: 110 | G10: 976 | H10: 366 | I10: 560 | J10: 54 | K10: 654.08 | L10: 490.56 | M10: 47.84 | N10: 164.08 | O10: =IF(P10-SUM(K10:N10)<=2000,0,IF(P10-SUM(K10:N10)<=4000,0+(P10-SUM(K10:N10)-2000)*0.03,IF(P10-SUM(K10:N10)<=8000,0+2000*0.03+(P10-SUM(K10:N10)-4000)*0.08,0+2000*0.03+4000*0.08+(P10-SUM(K10:N10)-8000)*0.1))) -> 281.2352 | P10: =D10+E10+F10+G10+H10+I10-J10 -> 8122 | Q10: =K10+L10+M10+N10+O10 -> 1637.7952 | R10: =P10-Q10 -> 6484.2048
A11: A007 | B11: =VLOOKUP(A11,员工资料!A:C,2,FALSE) -> 男 | C11: =VLOOKUP(A11,员工资料!A:C,3,FALSE) -> 劳务工 | D11: 4590 | E11: 324 | F11: 60 | G11: 987 | H11: 470 | I11: 502 | J11: 76 | K11: 554.64 | L11: 415.98 | M11: 48.38 | N11: 167.6 | O11: =IF(P11-SUM(K11:N11)<=2000,0,IF(P11-SUM(K11:N11)<=4000,0+(P11-SUM(K11:N11)-2000)*0.03,IF(P11-SUM(K11:N11)<=8000,0+2000*0.03+(P11-SUM(K11:N11)-4000)*0.08,0+2000*0.03+4000*0.08+(P11-SUM(K11:N11)-8000)*0.1))) -> 193.632 | P11: =D11+E11+F11+G11+H11+I11-J11 -> 6857 | Q11: =K11+L11+M11+N11+O11 -> 1380.232 | R11: =P11-Q11 -> 5476.768
A12: A009 | B12: =VLOOKUP(A12,员工资料!A:C,2,FALSE) -> 男 | C12: =VLOOKUP(A12,员工资料!A:C,3,FALSE) -> 劳务工 | D12: 2574 | E12: 546 | F12: 280 | G12: 880 | H12: 229 | I12: 253 | J12: 51 | K12: 380.96 | L12: 285.72 | M12: 44.54 | N12: 135.44 | O12: =IF(P12-SUM(K12:N12)<=2000,0,IF(P12-SUM(K12:N12)<=4000,0+(P12-SUM(K12:N12)-2000)*0.03,IF(P12-SUM(K12:N12)<=8000,0+2000*0.03+(P12-SUM(K12:N12)-4000)*0.08,0+2000*0.03+4000*0.08+(P12-SUM(K12:N12)-8000)*0.1))) -> 55.9302 | P12: =D12+E12+F12+G12+H12+I12-J12 -> 4711 | Q12: =K12+L12+M12+N12+O12 -> 902.5902 | R12: =P12-Q12 -> 3808.4098
A13: A011 | B13: =VLOOKUP(A13,员工资料!A:C,2,FALSE) -> 女 | C13: =VLOOKUP(A13,员工资料!A:C,3,FALSE) -> 劳务工 | D13: 2620 | E13: 508 | F13: 160 | G13: 979 | H13: 222 | I13: 416 | J13: 46 | K13: 392.4 | L13: 294.3 | M13: 45.7 | N13: 142.16 | O13: =IF(P13-SUM(K13:N13)<=2000,0,IF(P13-SUM(K13:N13)<=4000,0+(P13-SUM(K13:N13)-2000)*0.03,IF(P13-SUM(K13:N13)<=8000,0+2000*0.03+(P13-SUM(K13:N13)-4000)*0.08,0+2000*0.03+4000*0.08+(P13-SUM(K13:N13)-8000)*0.1))) -> 59.5332 | P13: =D13+E13+F13+G13+H13+I13-J13 -> 4859 | Q13: =K13+L13+M13+N13+O13 -> 934.0932 | R13: =P13-Q13 -> 3924.9068
... A17: A015 | B17: =VLOOKUP(A17,员工资料!A:C,2,FALSE) -> 男 | C17: =VLOOKUP(A17,员工资料!A:C,3,FALSE) -> 劳务工 | D17: 4812 | E17: 282 | F17: 60 | G17: 1062 | H17: 390 | I17: 460 | J17: 87 | K17: 565.28 | L17: 423.96 | M17: 45.08 | N17: 164.72 | O17: =IF(P17-SUM(K17:N17)<=2000,0,IF(P17-SUM(K17:N17)<=4000,0+(P17-SUM(K17:N17)-2000)*0.03,IF(P17-SUM(K17:N17)<=8000,0+2000*0.03+(P17-SUM(K17:N17)-4000)*0.08,0+2000*0.03+4000*0.08+(P17-SUM(K17:N17)-8000)*0.1))) -> 202.3968 | P17: =D17+E17+F17+G17+H17+I17-J17 -> 6979 | Q17: =K17+L17+M17+N17+O17 -> 1401.4368 | R17: =P17-Q17 -> 5577.5632

Sheet 3月
A1: 姓名 | B1: 性别 | C1: 合同种类 | D1: 基本工资 | E1: 岗位工资 | F1: 工龄工资 | G1: 补贴 | H1: 医疗补助 | I1: 奖金 | J1: 考勤扣款 | K1: 住房公积金 | L1: 养老保险 | M1: 医疗保险 | N1: 失业保险 | O1: 个人所得税 | P1: 应发合计 | Q1: 应扣合计 | R1: 实发合计
A2: A001 | B2: =VLOOKUP(A2,员工资料!A:C,2,FALSE) -> 男 | C2: =VLOOKUP(A2,员工资料!A:C,3,FALSE) -> 合同工 | D2: 6398 | E2: 386 | F2: 120 | G2: 1069 | H2: 226 | I2: 448 | J2: 100 | K2: 691.76 | L2: 518.82 | M2: 46.98 | N2: 157.04 | O2: =IF(P2-SUM(K2:N2)<=2000,0,IF(P2-SUM(K2:N2)<=4000,0+(P2-SUM(K2:N2)-2000)*0.03,IF(P2-SUM(K2:N2)<=8000,0+2000*0.03+(P2-SUM(K2:N2)-4000)*0.08,0+2000*0.03+4000*0.08+(P2-SUM(K2:N2)-8000)*0.1))) -> 310.592 | P2: =D2+E2+F2+G2+H2+I2-J2 -> 8547 | Q2: =K2+L2+M2+N2+O2 -> 1725.192 | R2: =P2-Q2 -> 6821.808
A3: A002 | B3: =VLOOKUP(A3,员工资料!A:C,2,FALSE) -> 男 | C3: =VLOOKUP(A3,员工资料!A:C,3,FALSE) -> 合同工 | D3: 5950 | E3: 369 | F3: 290 | G3: 733 | H3: 490 | I3: 410 | J3: 81 | K3: 659.36 | L3: 494.52 | M3: 45.84 | N3: 153.84 | O3: =IF(P3-SUM(K3:N3)<=2000,0,IF(P3-SUM(K3:N3)<=4000,0+(P3-SUM(K3:N3)-2000)*0.03,IF(P3-SUM(K3:N3)<=8000,0+2000*0.03+(P3-SUM(K3:N3)-4000)*0.08,0+2000*0.03+4000*0.08+(P3-SUM(K3:N3)-8000)*0.1))) -> 284.5952 | P3: =D3+E3+F3+G3+H3+I3-J3 -> 8161 | Q3: =K3+L3+M3+N3+O3 -> 1638.1552 | R3: =P3-Q3 -> 6522.8448
A4: A005 | B4: =VLOOKUP(A4,员工资料!A:C,2,FALSE) -> 女 | C4: =VLOOKUP(A4,员工资料!A:C,3,FALSE) -> 合同工 | D4: 4871 | E4: 488 | F4: 240 | G4: 817 | H4: 475 | I4: 584 | J4: 16 | K4: 598 | L4: 448.5 | M4: 52.08 | N4: 169.28 | O4: =IF(P4-SUM(K4:N4)<=2000,0,IF(P4-SUM(K4:N4)<=4000,0+(P4-SUM(K4:N4)-2000)*0.03,IF(P4-SUM(K4:N4)<=8000,0+2000*0.03+(P4-SUM(K4:N4)-4000)*0.08,0+2000*0.03+4000*0.08+(P4-SUM(K4:N4)-8000)*0.1))) -> 235.2912 | P4: =D4+E4+F4+G4+H4+I4-J4 -> 7459 | Q4: =K4+L4+M4+N4+O4 -> 1503.1512 | R4: =P4-Q4 -> 5955.8488
A5: A006 | B5: =VLOOKUP(A5,员工资料!A:C,2,FALSE) -> 女 | C5: =VLOOKUP(A5,员工资料!A:C,3,FALSE) -> 合同工 | D5: 4495 | E5: 349 | F5: 270 | G5: 788 | H5: 597 | I5: 315 | J5: 62 | K5: 545.12 | L5: 408.84 | M5: 47.62 | N5: 162.56 | O5: =IF(P5-SUM(K5:N5)<=2000,0,IF(P5-SUM(K5:N5)<=4000,0+(P5-SUM(K5:N5)-2000)*0.03,IF(P5-SUM(K5:N5)<=8000,0+2000*0.03+(P5-SUM(K5:N5)-4000)*0.08,0+2000*0.03+4000*0.08+(P5-SUM(K5:N5)-8000)*0.1))) -> 187.0288 | P5: =D5+E5+F5+G5+H5+I5-J5 -> 6752 | Q5: =K5+L5+M5+N5+O5 -> 1351.1688 | R5: =P5-Q5 -> 5400.8312
A6: A008 | B6: =VLOOKUP(A6,员工资料!A:C,2,FALSE) -> 男 | C6: =VLOOKUP(A6,员工资料!A:C,3,FALSE) -> 合同工 | D6: 5803 | E6: 386 | F6: 290 | G6: 998 | H6: 551 | I6: 410 | J6: 53 | K6: 675.04 | L6: 506.28 | M6: 53.76 | N6: 184.16 | O6: =IF(P6-SUM(K6:N6)<=2000,0,IF(P6-SUM(K6:N6)<=4000,0+(P6-SUM(K6:N6)-2000)*0.03,IF(P6-SUM(K6:N6)<=8000,0+2000*0.03+(P6-SUM(K6:N6)-4000)*0.08,0+2000*0.03+4000*0.08+(P6-SUM(K6:N6)-8000)*0.1))) -> 297.2608 | P6: =D6+E6+F6+G6+H6+I6-J6 -> 8385 | Q6: =K6+L6+M6+N6+O6 -> 1716.5008 | R6: =P6-Q6 -> 6668.4992
A7: A010 | B7: =VLOOKUP(A7,员工资料!A:C,2,FALSE) -> 男 | C7: =VLOOKUP(A7,员工资料!A:C,3,FALSE) -> 合同工 | D7: 3537 | E7: 333 | F7: 270 | G7: 1055 | H7: 213 | I7: 540 | J7: 29 | K7: 475.84 | L7: 356.88 | M7: 48.22 | N7: 166.24 | O7: =IF(P7-SUM(K7:N7)<=2000,0,IF(P7-SUM(K7:N7)<=4000,0+(P7-SUM(K7:N7)-2000)*0.03,IF(P7-SUM(K7:N7)<=8000,0+2000*0.03+(P7-SUM(K7:N7)-4000)*0.08,0+2000*0.03+4000*0.08+(P7-SUM(K7:N7)-8000)*0.1))) -> 129.7456 | P7: =D7+E7+F7+G7+H7+I7-J7 -> 5919 | Q7: =K7+L7+M7+N7+O7 -> 1176.9256 | R7: =P7-Q7 -> 4742.0744
A8: A016 | B8: =VLOOKUP(A8,员工资料!A:C,2,FALSE) -> 女 | C8: =VLOOKUP(A8,员工资料!A:C,3,FALSE) -> 合同工 | D8: 3696 | E8: 419 | F8: 290 | G8: 875 | H8: 302 | I8: 219 | J8: 130 | K8: 464.08 | L8: 348.06 | M8: 43.06 | N8: 142.96 | O8: =IF(P8-SUM(K8:N8)<=2000,0,IF(P8-SUM(K8:N8)<=4000,0+(P8-SUM(K8:N8)-2000)*0.03,IF(P8-SUM(K8:N8)<=8000,0+2000*0.03+(P8-SUM(K8:N8)-4000)*0.08,0+2000*0.03+4000*0.08+(P8-SUM(K8:N8)-8000)*0.1))) -> 113.8272 | P8: =D8+E8+F8+G8+H8+I8-J8 -> 5671 | Q8: =K8+L8+M8+N8+O8 -> 1111.9872 | R8: =P8-Q8 -> 4559.0128
A9: A003 | B9: =VLOOKUP(A9,员工资料!A:C,2,FALSE) -> 女 | C9: =VLOOKUP(A9,员工资料!A:C,3,FALSE) -> 劳务工 | D9: 5562 | E9: 372 | F9: 80 | G9: 697 | H9: 297 | I9: 459 | J9: 0 | K9: 597.36 | L9: 448.02 | M9: 38.1 | N9: 122.64 | O9: =IF(P9-SUM(K9:N9)<=2000,0,IF(P9-SUM(K9:N9)<=4000,0+(P9-SUM(K9:N9)-2000)*0.03,IF(P9-SUM(K9:N9)<=8000,0+2000*0.03+(P9-SUM(K9:N9)-4000)*0.08,0+2000*0.03+4000*0.08+(P9-SUM(K9:N9)-8000)*0.1))) -> 240.8704 | P9: =D9+E9+F9+G9+H9+I9-J9 -> 7467 | Q9: =K9+L9+M9+N9+O9 -> 1446.9904 | R9: =P9-Q9 -> 6020.0096
A10: A004 | B10: =VLOOKUP(A10,员工资料!A:C,2,FALSE) -> 男 | C10: =VLOOKUP(A10,员工资料!A:C,3,FALSE) -> 劳务工 | D10: 3582 | E10: 541 | F10: 190 | G10: 825 | H10: 294 | I10: 415 | J10: 54 | K10: 467.76 | L10: 350.82 | M10: 45.3 | N10: 141.04 | O10: =IF(P10-SUM(K10:N10)<=2000,0,IF(P10-SUM(K10:N10)<=4000,0+(P10-SUM(K10:N10)-2000)*0.03,IF(P10-SUM(K10:N10)<=8000,0+2000*0.03+(P10-SUM(K10:N10)-4000)*0.08,0+2000*0.03+4000*0.08+(P10-SUM(K10:N10)-8000)*0.1))) -> 123.0464 | P10: =D10+E10+F10+G10+H10+I10-J10 -> 5793 | Q10: =K10+L10+M10+N10+O10 -> 1127.9664 | R10: =P10-Q10 -> 4665.0336
A11: A007 | B11: =VLOOKUP(A11,员工资料!A:C,2,FALSE) -> 男 | C11: =VLOOKUP(A11,员工资料!A:C,3,FALSE) -> 劳务工 | D11: 4963 | E11: 592 | F11: 160 | G11: 1201 | H11: 593 | I11: 457 | J11: 76 | K11: 637.28 | L11: 477.96 | M11: 61.58 | N11: 198.96 | O11: =IF(P11-SUM(K11:N11)<=2000,0,IF(P11-SUM(K11:N11)<=4000,0+(P11-SUM(K11:N11)-2000)*0.03,IF(P11-SUM(K11:N11)<=8000,0+2000*0.03+(P11-SUM(K11:N11)-4000)*0.08,0+2000*0.03+4000*0.08+(P11-SUM(K11:N11)-8000)*0.1))) -> 261.1376 | P11: =D11+E11+F11+G11+H11+I11-J11 -> 7890 | Q11: =K11+L11+M11+N11+O11 -> 1636.9176 | R11: =P11-Q11 -> 6253.0824
A12: A009 | B12: =VLOOKUP(A12,员工资料!A:C,2,FALSE) -> 男 | C12: =VLOOKUP(A12,员工资料!A:C,3,FALSE) -> 劳务工 | D12: 5184 | E12: 547 | F12: 210 | G12: 763 | H12: 451 | I12: 440 | J12: 51 | K12: 607.6 | L12: 455.7 | M12: 49 | N12: 153.2 | O12: =IF(P12-SUM(K12:N12)<=2000,0,IF(P12-SUM(K12:N12)<=4000,0+(P12-SUM(K12:N12)-2000)*0.03,IF(P12-SUM(K12:N12)<=8000,0+2000*0.03+(P12-SUM(K12:N12)-4000)*0.08,0+2000*0.03+4000*0.08+(P12-SUM(K12:N12)-8000)*0.1))) -> 242.28 | P12: =D12+E12+F12+G12+H12+I12-J12 -> 7544 | Q12: =K12+L12+M12+N12+O12 -> 1507.78 | R12: =P12-Q12 -> 6036.22
A13: A011 | B13: =VLOOKUP(A13,员工资料!A:C,2,FALSE) -> 女 | C13: =VLOOKUP(A13,员工资料!A:C,3,FALSE) -> 劳务工 | D13: 3874 | E13: 353 | F13: 150 | G13: 1047 | H13: 389 | I13: 336 | J13: 46 | K13: 491.92 | L13: 368.94 | M13: 45.5 | N13: 153.76 | O13: =IF(P13-SUM(K13:N13)<=2000,0,IF(P13-SUM(K13:N13)<=4000,0+(P13-SUM(K13:N13)-2000)*0.03,IF(P13-SUM(K13:N13)<=8000,0+2000*0.03+(P13-SUM(K13:N13)-4000)*0.08,0+2000*0.03+4000*0.08+(P13-SUM(K13:N13)-8000)*0.1))) -> 143.4304 | P13: =D13+E13+F13+G13+H13+I13-J13 -> 6103 | Q13: =K13+L13+M13+N13+O13 -> 1203.5504 | R13: =P13-Q13 -> 4899.4496
... A17: A015 | B17: =VLOOKUP(A17,员工资料!A:C,2,FALSE) -> 男 | C17: =VLOOKUP(A17,员工资料!A:C,3,FALSE) -> 劳务工 | D17: 5174 | E17: 598 | F17: 50 | G17: 721 | H17: 223 | I17: 384 | J17: 87 | K17: 572 | L17: 429 | M17: 39.52 | N17: 117.2 | O17: =IF(P17-SUM(K17:N17)<=2000,0,IF(P17-SUM(K17:N17)<=4000,0+(P17-SUM(K17:N17)-2000)*0.03,IF(P17-SUM(K17:N17)<=8000,0+2000*0.03+(P17-SUM(K17:N17)-4000)*0.08,0+2000*0.03+4000*0.08+(P17-SUM(K17:N17)-8000)*0.1))) -> 212.4224 | P17: =D17+E17+F17+G17+H17+I17-J17 -> 7063 | Q17: =K17+L17+M17+N17+O17 -> 1370.1424 | R17: =P17-Q17 -> 5692.8576

Sheet 4月
A1: 姓名 | B1: 性别 | C1: 合同种类 | D1: 基本工资 | E1: 岗位工资 | F1: 工龄工资 | G1: 补贴 | H1: 医疗补助 | I1: 奖金 | J1: 考勤扣款 | K1: 住房公积金 | L1: 养老保险 | M1: 医疗保险 | N1: 失业保险 | O1: 个人所得税 | P1: 应发合计 | Q1: 应扣合计 | R1: 实发合计
A2: A001 | B2: =VLOOKUP(A2,员工资料!A:C,2,FALSE) -> 男 | C2: =VLOOKUP(A2,员工资料!A:C,3,FALSE) -> 合同工 | D2: 4295 | E2: 463 | F2: 260 | G2: 973 | H2: 528 | I2: 387 | J2: 100 | K2: 552.48 | L2: 414.36 | M2: 54.22 | N2: 179.84 | O2: =IF(P2-SUM(K2:N2)<=2000,0,IF(P2-SUM(K2:N2)<=4000,0+(P2-SUM(K2:N2)-2000)*0.03,IF(P2-SUM(K2:N2)<=8000,0+2000*0.03+(P2-SUM(K2:N2)-4000)*0.08,0+2000*0.03+4000*0.08+(P2-SUM(K2:N2)-8000)*0.1))) -> 188.408 | P2: =D2+E2+F2+G2+H2+I2-J2 -> 6806 | Q2: =K2+L2+M2+N2+O2 -> 1389.308 | R2: =P2-Q2 -> 5416.692
A3: A004 | B3: =VLOOKUP(A3,员工资料!A:C,2,FALSE) -> 男 | C3: =VLOOKUP(A3,员工资料!A:C,3,FALSE) -> 劳务工 | D3: 6408 | E3: 498 | F3: 140 | G3: 620 | H3: 372 | I3: 594 | J3: 81 | K3: 690.56 | L3: 517.92 | M3: 44.48 | N3: 138.08 | O3: =IF(P3-SUM(K3:N3)<=2000,0,IF(P3-SUM(K3:N3)<=4000,0+(P3-SUM(K3:N3)-2000)*0.03,IF(P3-SUM(K3:N3)<=8000,0+2000*0.03+(P3-SUM(K3:N3)-4000)*0.08,0+2000*0.03+4000*0.08+(P3-SUM(K3:N3)-8000)*0.1))) -> 312.7968 | P3: =D3+E3+F3+G3+H3+I3-J3 -> 8551 | Q3: =K3+L3+M3+N3+O3 -> 1703.8368 | R3: =P3-Q3 -> 6847.1632
A4: A005 | B4: =VLOOKUP(A4,员工资料!A:C,2,FALSE) -> 女 | C4: =VLOOKUP(A4,员工资料!A:C,3,FALSE) -> 合同工 | D4: 4329 | E4: 275 | F4: 200 | G4: 1017 | H4: 525 | I4: 451 | J4: 16 | K4: 543.76 | L4: 407.82 | M4: 49.36 | N4: 175.44 | O4: =IF(P4-SUM(K4:N4)<=2000,0,IF(P4-SUM(K4:N4)<=4000,0+(P4-SUM(K4:N4)-2000)*0.03,IF(P4-SUM(K4:N4)<=8000,0+2000*0.03+(P4-SUM(K4:N4)-4000)*0.08,0+2000*0.03+4000*0.08+(P4-SUM(K4:N4)-8000)*0.1))) -> 188.3696 | P4: =D4+E4+F4+G4+H4+I4-J4 -> 6781 | Q4: =K4+L4+M4+N4+O4 -> 1364.7496 | R4: =P4-Q4 -> 5416.2504
A5: A006 | B5: =VLOOKUP(A5,员工资料!A:C,2,FALSE) -> 女 | C5: =VLOOKUP(A5,员工资料!A:C,3,FALSE) -> 合同工 | D5: 3892 | E5: 579 | F5: 50 | G5: 722 | H5: 582 | I5: 354 | J5: 62 | K5: 494.32 | L5: 370.74 | M5: 46.98 | N5: 141.6 | O5: =IF(P5-SUM(K5:N5)<=2000,0,IF(P5-SUM(K5:N5)<=4000,0+(P5-SUM(K5:N5)-2000)*0.03,IF(P5-SUM(K5:N5)<=8000,0+2000*0.03+(P5-SUM(K5:N5)-4000)*0.08,0+2000*0.03+4000*0.08+(P5-SUM(K5:N5)-8000)*0.1))) -> 145.0688 | P5: =D5+E5+F5+G5+H5+I5-J5 -> 6117 | Q5: =K5+L5+M5+N5+O5 -> 1198.7088 | R5: =P5-Q5 -> 4918.2912
A6: A008 | B6: =VLOOKUP(A6,员工资料!A:C,2,FALSE) -> 男 | C6: =VLOOKUP(A6,员工资料!A:C,3,FALSE) -> 合同工 | D6: 5210 | E6: 378 | F6: 190 | G6: 1029 | H6: 518 | I6: 210 | J6: 53 | K6: 602.8 | L6: 452.1 | M6: 47.56 | N6: 160 | O6: =IF(P6-SUM(K6:N6)<=2000,0,IF(P6-SUM(K6:N6)<=4000,0+(P6-SUM(K6:N6)-2000)*0.03,IF(P6-SUM(K6:N6)<=8000,0+2000*0.03+(P6-SUM(K6:N6)-4000)*0.08,0+2000*0.03+4000*0.08+(P6-SUM(K6:N6)-8000)*0.1))) -> 237.5632 | P6: =D6+E6+F6+G6+H6+I6-J6 -> 7482 | Q6: =K6+L6+M6+N6+O6 -> 1500.0232 | R6: =P6-Q6 -> 5981.9768
A7: A010 | B7: =VLOOKUP(A7,员工资料!A:C,2,FALSE) -> 男 | C7: =VLOOKUP(A7,员工资料!A:C,3,FALSE) -> 合同工 | D7: 6335 | E7: 348 | F7: 130 | G7: 922 | H7: 495 | I7: 475 | J7: 29 | K7: 696.4 | L7: 522.3 | M7: 47.4 | N7: 161.76 | O7: =IF(P7-SUM(K7:N7)<=2000,0,IF(P7-SUM(K7:N7)<=4000,0+(P7-SUM(K7:N7)-2000)*0.03,IF(P7-SUM(K7:N7)<=8000,0+2000*0.03+(P7-SUM(K7:N7)-4000)*0.08,0+2000*0.03+4000*0.08+(P7-SUM(K7:N7)-8000)*0.1))) -> 319.8512 | P7: =D7+E7+F7+G7+H7+I7-J7 -> 8676 | Q7: =K7+L7+M7+N7+O7 -> 1747.7112 | R7: =P7-Q7 -> 6928.2888
A8: A016 | B8: =VLOOKUP(A8,员工资料!A:C,2,FALSE) -> 女 | C8: =VLOOKUP(A8,员工资料!A:C,3,FALSE) -> 合同工 | D8: 5649 | E8: 374 | F8: 260 | G8: 746 | H8: 252 | I8: 331 | J8: 130 | K8: 608.96 | L8: 456.72 | M8: 40.22 | N8: 135.2 | O8: =IF(P8-SUM(K8:N8)<=2000,0,IF(P8-SUM(K8:N8)<=4000,0+(P8-SUM(K8:N8)-2000)*0.03,IF(P8-SUM(K8:N8)<=8000,0+2000*0.03+(P8-SUM(K8:N8)-4000)*0.08,0+2000*0.03+4000*0.08+(P8-SUM(K8:N8)-8000)*0.1))) -> 239.272 | P8: =D8+E8+F8+G8+H8+I8-J8 -> 7482 | Q8: =K8+L8+M8+N8+O8 -> 1480.372 | R8: =P8-Q8 -> 6001.628
A9: A002 | B9: =VLOOKUP(A9,员工资料!A:C,2,FALSE) -> 男 | C9: =VLOOKUP(A9,员工资料!A:C,3,FALSE) -> 合同工 | D9: 5381 | E9: 240 | F9: 250 | G9: 742 | H9: 451 | I9: 592 | J9: 0 | K9: 612.48 | L9: 459.36 | M9: 45.5 | N9: 162.8 | O9: =IF(P9-SUM(K9:N9)<=2000,0,IF(P9-SUM(K9:N9)<=4000,0+(P9-SUM(K9:N9)-2000)*0.03,IF(P9-SUM(K9:N9)<=8000,0+2000*0.03+(P9-SUM(K9:N9)-4000)*0.08,0+2000*0.03+4000*0.08+(P9-SUM(K9:N9)-8000)*0.1))) -> 250.0688 | P9: =D9+E9+F9+G9+H9+I9-J9 -> 7656 | Q9: =K9+L9+M9+N9+O9 -> 1530.2088 | R9: =P9-Q9 -> 6125.7912
A10: A007 | B10: =VLOOKUP(A10,员工资料!A:C,2,FALSE) -> 男 | C10: =VLOOKUP(A10,员工资料!A:C,3,FALSE) -> 劳务工 | D10: 2583 | E10: 563 | F10: 190 | G10: 814 | H10: 589 | I10: 593 | J10: 54 | K10: 426.56 | L10: 319.92 | M10: 54.98 | N10: 178 | O10: =IF(P10-SUM(K10:N10)<=2000,0,IF(P10-SUM(K10:N10)<=4000,0+(P10-SUM(K10:N10)-2000)*0.03,IF(P10-SUM(K10:N10)<=8000,0+2000*0.03+(P10-SUM(K10:N10)-4000)*0.08,0+2000*0.03+4000*0.08+(P10-SUM(K10:N10)-8000)*0.1))) -> 83.8832 | P10: =D10+E10+F10+G10+H10+I10-J10 -> 5278 | Q10: =K10+L10+M10+N10+O10 -> 1063.3432 | R10: =P10-Q10 -> 4214.6568
A11: A013 | B11: =VLOOKUP(A11,员工资料!A:C,2,FALSE) -> 男 | C11: =VLOOKUP(A11,员工资料!A:C,3,FALSE) -> 劳务工 | D11: 5511 | E11: 328 | F11: 180 | G11: 1114 | H11: 566 | I11: 580 | J11: 76 | K11: 662.32 | L11: 496.74 | M11: 56.88 | N11: 201.28 | O11: =IF(P11-SUM(K11:N11)<=2000,0,IF(P11-SUM(K11:N11)<=4000,0+(P11-SUM(K11:N11)-2000)*0.03,IF(P11-SUM(K11:N11)<=8000,0+2000*0.03+(P11-SUM(K11:N11)-4000)*0.08,0+2000*0.03+4000*0.08+(P11-SUM(K11:N11)-8000)*0.1))) -> 282.8624 | P11: =D11+E11+F11+G11+H11+I11-J11 -> 8203 | Q11: =K11+L11+M11+N11+O11 -> 1700.0824 | R11: =P11-Q11 -> 6502.9176
A12: A009 | B12: =VLOOKUP(A12,员工资料!A:C,2,FALSE) -> 男 | C12: =VLOOKUP(A12,员工资料!A:C,3,FALSE) -> 劳务工 | D12: 4812 | E12: 483 | F12: 230 | G12: 1167 | H12: 371 | I12: 372 | J12: 51 | K12: 594.8 | L12: 446.1 | M12: 53.24 | N12: 175.28 | O12: =IF(P12-SUM(K12:N12)<=2000,0,IF(P12-SUM(K12:N12)<=4000,0+(P12-SUM(K12:N12)-2000)*0.03,IF(P12-SUM(K12:N12)<=8000,0+2000*0.03+(P12-SUM(K12:N12)-4000)*0.08,0+2000*0.03+4000*0.08+(P12-SUM(K12:N12)-8000)*0.1))) -> 229.1664 | P12: =D12+E12+F12+G12+H12+I12-J12 -> 7384 | Q12: =K12+L12+M12+N12+O12 -> 1498.5864 | R12: =P12-Q12 -> 5885.4136
A13: A011 | B13: =VLOOKUP(A13,员工资料!A:C,2,FALSE) -> 女 | C13: =VLOOKUP(A13,员工资料!A:C,3,FALSE) -> 劳务工 | D13: 5401 | E13: 552 | F13: 70 | G13: 1014 | H13: 367 | I13: 505 | J13: 46 | K13: 632.72 | L13: 474.54 | M13: 50.16 | N13: 156.48 | O13: =IF(P13-SUM(K13:N13)<=2000,0,IF(P13-SUM(K13:N13)<=4000,0+(P13-SUM(K13:N13)-2000)*0.03,IF(P13-SUM(K13:N13)<=8000,0+2000*0.03+(P13-SUM(K13:N13)-4000)*0.08,0+2000*0.03+4000*0.08+(P13-SUM(K13:N13)-8000)*0.1))) -> 263.928 | P13: =D13+E13+F13+G13+H13+I13-J13 -> 7863 | Q13: =K13+L13+M13+N13+O13 -> 1577.828 | R13: =P13-Q13 -> 6285.172
... A17: A015 | B17: =VLOOKUP(A17,员工资料!A:C,2,FALSE) -> 男 | C17: =VLOOKUP(A17,员工资料!A:C,3,FALSE) -> 劳务工 | D17: 6508 | E17: 499 | F17: 170 | G17: 909 | H17: 307 | I17: 424 | J17: 87 | K17: 705.36 | L17: 529.02 | M17: 46.18 | N17: 151.76 | O17: =IF(P17-SUM(K17:N17)<=2000,0,IF(P17-SUM(K17:N17)<=4000,0+(P17-SUM(K17:N17)-2000)*0.03,IF(P17-SUM(K17:N17)<=8000,0+2000*0.03+(P17-SUM(K17:N17)-4000)*0.08,0+2000*0.03+4000*0.08+(P17-SUM(K17:N17)-8000)*0.1))) -> 323.8144 | P17: =D17+E17+F17+G17+H17+I17-J17 -> 8730 | Q17: =K17+L17+M17+N17+O17 -> 1756.1344 | R17: =P17-Q17 -> 6973.8656

Sheet 5月
A1: 姓名 | B1: 性别 | C1: 合同种类 | D1: 基本工资 | E1: 岗位工资 | F1: 工龄工资 | G1: 补贴 | H1: 医疗补助 | I1: 奖金 | J1: 考勤扣款 | K1: 住房公积金 | L1: 养老保险 | M1: 医疗保险 | N1: 失业保险 | O1: 个人所得税 | P1: 应发合计 | Q1: 应扣合计 | R1: 实发合计
A2: A001 | B2: =VLOOKUP(A2,员工资料!A:C,2,FALSE) -> 男 | C2: =VLOOKUP(A2,员工资料!A:C,3,FALSE) -> 合同工 | D2: 4782 | E2: 484 | F2: 210 | G2: 1115 | H2: 514 | I2: 307 | J2: 100 | K2: 592.96 | L2: 444.72 | M2: 54.6 | N2: 179.68 | O2: =IF(P2-SUM(K2:N2)<=2000,0,IF(P2-SUM(K2:N2)<=4000,0+(P2-SUM(K2:N2)-2000)*0.03,IF(P2-SUM(K2:N2)<=8000,0+2000*0.03+(P2-SUM(K2:N2)-4000)*0.08,0+2000*0.03+4000*0.08+(P2-SUM(K2:N2)-8000)*0.1))) -> 223.2032 | P2: =D2+E2+F2+G2+H2+I2-J2 -> 7312 | Q2: =K2+L2+M2+N2+O2 -> 1495.1632 | R2: =P2-Q2 -> 5816.8368
A3: A004 | B3: =VLOOKUP(A3,员工资料!A:C,2,FALSE) -> 男 | C3: =VLOOKUP(A3,员工资料!A:C,3,FALSE) -> 劳务工 | D3: 4631 | E3: 437 | F3: 240 | G3: 908 | H3: 342 | I3: 267 | J3: 81 | K3: 546 | L3: 409.5 | M3: 43.88 | N3: 140.56 | O3: =IF(P3-SUM(K3:N3)<=2000,0,IF(P3-SUM(K3:N3)<=4000,0+(P3-SUM(K3:N3)-2000)*0.03,IF(P3-SUM(K3:N3)<=8000,0+2000*0.03+(P3-SUM(K3:N3)-4000)*0.08,0+2000*0.03+4000*0.08+(P3-SUM(K3:N3)-8000)*0.1))) -> 188.3248 | P3: =D3+E3+F3+G3+H3+I3-J3 -> 6744 | Q3: =K3+L3+M3+N3+O3 -> 1328.2648 | R3: =P3-Q3 -> 5415.7352
A4: A005 | B4: =VLOOKUP(A4,员工资料!A:C,2,FALSE) -> 女 | C4: =VLOOKUP(A4,员工资料!A:C,3,FALSE) -> 合同工 | D4: 2769 | E4: 405 | F4: 110 | G4: 884 | H4: 215 | I4: 518 | J4: 16 | K4: 392.08 | L4: 294.06 | M4: 42.64 | N4: 138.16 | O4: =IF(P4-SUM(K4:N4)<=2000,0,IF(P4-SUM(K4:N4)<=4000,0+(P4-SUM(K4:N4)-2000)*0.03,IF(P4-SUM(K4:N4)<=8000,0+2000*0.03+(P4-SUM(K4:N4)-4000)*0.08,0+2000*0.03+4000*0.08+(P4-SUM(K4:N4)-8000)*0.1))) -> 61.4448 | P4: =D4+E4+F4+G4+H4+I4-J4 -> 4885 | Q4: =K4+L4+M4+N4+O4 -> 928.3848 | R4: =P4-Q4 -> 3956.6152
A5: A006 | B5: =VLOOKUP(A5,员工资料!A:C,2,FALSE) -> 女 | C5: =VLOOKUP(A5,员工资料!A:C,3,FALSE) -> 合同工 | D5: 2674 | E5: 409 | F5: 270 | G5: 936 | H5: 269 | I5: 544 | J5: 62 | K5: 408.16 | L5: 306.12 | M5: 49.8 | N5: 166.48 | O5: =IF(P5-SUM(K5:N5)<=2000,0,IF(P5-SUM(K5:N5)<=4000,0+(P5-SUM(K5:N5)-2000)*0.03,IF(P5-SUM(K5:N5)<=8000,0+2000*0.03+(P5-SUM(K5:N5)-4000)*0.08,0+2000*0.03+4000*0.08+(P5-SUM(K5:N5)-8000)*0.1))) -> 68.7552 | P5: =D5+E5+F5+G5+H5+I5-J5 -> 5040 | Q5: =K5+L5+M5+N5+O5 -> 999.3152 | R5: =P5-Q5 -> 4040.6848
A6: A008 | B6: =VLOOKUP(A6,员工资料!A:C,2,FALSE) -> 男 | C6: =VLOOKUP(A6,员工资料!A:C,3,FALSE) -> 合同工 | D6: 5181 | E6: 508 | F6: 190 | G6: 995 | H6: 554 | I6: 334 | J6: 53 | K6: 620.96 | L6: 465.72 | M6: 52.68 | N6: 170.08 | O6: =IF(P6-SUM(K6:N6)<=2000,0,IF(P6-SUM(K6:N6)<=4000,0+(P6-SUM(K6:N6)-2000)*0.03,IF(P6-SUM(K6:N6)<=8000,0+2000*0.03+(P6-SUM(K6:N6)-4000)*0.08,0+2000*0.03+4000*0.08+(P6-SUM(K6:N6)-8000)*0.1))) -> 251.9648 | P6: =D6+E6+F6+G6+H6+I6-J6 -> 7709 | Q6: =K6+L6+M6+N6+O6 -> 1561.4048 | R6: =P6-Q6 -> 6147.5952
A7: A010 | B7: =VLOOKUP(A7,员工资料!A:C,2,FALSE) -> 男 | C7: =VLOOKUP(A7,员工资料!A:C,3,FALSE) -> 合同工 | D7: 2893 | E7: 416 | F7: 190 | G7: 745 | H7: 342 | I7: 518 | J7: 29 | K7: 408.32 | L7: 306.24 | M7: 44.22 | N7: 143.6 | O7: =IF(P7-SUM(K7:N7)<=2000,0,IF(P7-SUM(K7:N7)<=4000,0+(P7-SUM(K7:N7)-2000)*0.03,IF(P7-SUM(K7:N7)<=8000,0+2000*0.03+(P7-SUM(K7:N7)-4000)*0.08,0+2000*0.03+4000*0.08+(P7-SUM(K7:N7)-8000)*0.1))) -> 73.8096 | P7: =D7+E7+F7+G7+H7+I7-J7 -> 5075 | Q7: =K7+L7+M7+N7+O7 -> 976.1896 | R7: =P7-Q7 -> 4098.8104
A8: A016 | B8: =VLOOKUP(A8,员工资料!A:C,2,FALSE) -> 女 | C8: =VLOOKUP(A8,员工资料!A:C,3,FALSE) -> 合同工 | D8: 4445 | E8: 557 | F8: 150 | G8: 984 | H8: 205 | I8: 535 | J8: 130 | K8: 550.08 | L8: 412.56 | M8: 49.58 | N8: 158 | O8: =IF(P8-SUM(K8:N8)<=2000,0,IF(P8-SUM(K8:N8)<=4000,0+(P8-SUM(K8:N8)-2000)*0.03,IF(P8-SUM(K8:N8)<=8000,0+2000*0.03+(P8-SUM(K8:N8)-4000)*0.08,0+2000*0.03+4000*0.08+(P8-SUM(K8:N8)-8000)*0.1))) -> 186.0624 | P8: =D8+E8+F8+G8+H8+I8-J8 -> 6746 | Q8: =K8+L8+M8+N8+O8 -> 1356.2824 | R8: =P8-Q8 -> 5389.7176
A9: A002 | B9: =VLOOKUP(A9,员工资料!A:C,2,FALSE) -> 男 | C9: =VLOOKUP(A9,员工资料!A:C,3,FALSE) -> 合同工 | D9: 4053 | E9: 250 | F9: 100 | G9: 781 | H9: 367 | I9: 558 | J9: 0 | K9: 488.72 | L9: 366.54 | M9: 41.12 | N9: 144.48 | O9: =IF(P9-SUM(K9:N9)<=2000,0,IF(P9-SUM(K9:N9)<=4000,0+(P9-SUM(K9:N9)-2000)*0.03,IF(P9-SUM(K9:N9)<=8000,0+2000*0.03+(P9-SUM(K9:N9)-4000)*0.08,0+2000*0.03+4000*0.08+(P9-SUM(K9:N9)-8000)*0.1))) -> 145.4512 | P9: =D9+E9+F9+G9+H9+I9-J9 -> 6109 | Q9: =K9+L9+M9+N9+O9 -> 1186.3112 | R9: =P9-Q9 -> 4922.6888
A10: A007 | B10: =VLOOKUP(A10,员工资料!A:C,2,FALSE) -> 男 | C10: =VLOOKUP(A10,员工资料!A:C,3,FALSE) -> 劳务工 | D10: 2571 | E10: 571 | F10: 120 | G10: 914 | H10: 375 | I10: 592 | J10: 54 | K10: 411.44 | L10: 308.58 | M10: 51.44 | N10: 163.2 | O10: =IF(P10-SUM(K10:N10)<=2000,0,IF(P10-SUM(K10:N10)<=4000,0+(P10-SUM(K10:N10)-2000)*0.03,IF(P10-SUM(K10:N10)<=8000,0+2000*0.03+(P10-SUM(K10:N10)-4000)*0.08,0+2000*0.03+4000*0.08+(P10-SUM(K10:N10)-8000)*0.1))) -> 72.3472 | P10: =D10+E10+F10+G10+H10+I10-J10 -> 5089 | Q10: =K10+L10+M10+N10+O10 -> 1007.0072 | R10: =P10-Q10 -> 4081.9928
A11: A013 | B11: =VLOOKUP(A11,员工资料!A:C,2,FALSE) -> 男 | C11: =VLOOKUP(A11,员工资料!A:C,3,FALSE) -> 劳务工 | D11: 2605 | E11: 579 | F11: 270 | G11: 749 | H11: 534 | I11: 355 | J11: 76 | K11: 407.36 | L11: 305.52 | M11: 51.26 | N11: 158.72 | O11: =IF(P11-SUM(K11:N11)<=2000,0,IF(P11-SUM(K11:N11)<=4000,0+(P11-SUM(K11:N11)-2000)*0.03,IF(P11-SUM(K11:N11)<=8000,0+2000*0.03+(P11-SUM(K11:N11)-4000)*0.08,0+2000*0.03+4000*0.08+(P11-SUM(K11:N11)-8000)*0.1))) -> 67.4512 | P11: =D11+E11+F11+G11+H11+I11-J11 -> 5016 | Q11: =K11+L11+M11+N11+O11 -> 990.3112 | R11: =P11-Q11 -> 4025.6888
A12: A009 | B12: =VLOOKUP(A12,员工资料!A:C,2,FALSE) -> 男 | C12: =VLOOKUP(A12,员工资料!A:C,3,FALSE) -> 劳务工 | D12: 4932 | E12: 598 | F12: 70 | G12: 884 | H12: 443 | I12: 239 | J12: 51 | K12: 573.28 | L12: 429.96 | M12: 45.46 | N12: 134.96 | O12: =IF(P12-SUM(K12:N12)<=2000,0,IF(P12-SUM(K12:N12)<=4000,0+(P12-SUM(K12:N12)-2000)*0.03,IF(P12-SUM(K12:N12)<=8000,0+2000*0.03+(P12-SUM(K12:N12)-4000)*0.08,0+2000*0.03+4000*0.08+(P12-SUM(K12:N12)-8000)*0.1))) -> 214.5072 | P12: =D12+E12+F12+G12+H12+I12-J12 -> 7115 | Q12: =K12+L12+M12+N12+O12 -> 1398.1672 | R12: =P12-Q12 -> 5716.8328
A13: A011 | B13: =VLOOKUP(A13,员工资料!A:C,2,FALSE) -> 女 | C13: =VLOOKUP(A13,员工资料!A:C,3,FALSE) -> 劳务工 | D13: 4774 | E13: 453 | F13: 260 | G13: 919 | H13: 577 | I13: 487 | J13: 46 | K13: 597.6 | L13: 448.2 | M13: 53.92 | N13: 179.44 | O13: =IF(P13-SUM(K13:N13)<=2000,0,IF(P13-SUM(K13:N13)<=4000,0+(P13-SUM(K13:N13)-2000)*0.03,IF(P13-SUM(K13:N13)<=8000,0+2000*0.03+(P13-SUM(K13:N13)-4000)*0.08,0+2000*0.03+4000*0.08+(P13-SUM(K13:N13)-8000)*0.1))) -> 231.5872 | P13: =D13+E13+F13+G13+H13+I13-J13 -> 7424 | Q13: =K13+L13+M13+N13+O13 -> 1510.7472 | R13: =P13-Q13 -> 5913.2528
... A17: A015 | B17: =VLOOKUP(A17,员工资料!A:C,2,FALSE) -> 男 | C17: =VLOOKUP(A17,员工资料!A:C,3,FALSE) -> 劳务工 | D17: 4847 | E17: 407 | F17: 130 | G17: 1016 | H17: 389 | I17: 428 | J17: 87 | K17: 577.36 | L17: 433.02 | M17: 47.4 | N17: 164 | O17: =IF(P17-SUM(K17:N17)<=2000,0,IF(P17-SUM(K17:N17)<=4000,0+(P17-SUM(K17:N17)-2000)*0.03,IF(P17-SUM(K17:N17)<=8000,0+2000*0.03+(P17-SUM(K17:N17)-4000)*0.08,0+2000*0.03+4000*0.08+(P17-SUM(K17:N17)-8000)*0.1))) -> 212.6576 | P17: =D17+E17+F17+G17+H17+I17-J17 -> 7130 | Q17: =K17+L17+M17+N17+O17 -> 1434.4376 | R17: =P17-Q17 -> 5695.5624

Sheet 6月
A1: 姓名 | B1: 性别 | C1: 合同种类 | D1: 基本工资 | E1: 岗位工资 | F1: 工龄工资 | G1: 补贴 | H1: 医疗补助 | I1: 奖金 | J1: 考勤扣款 | K1: 住房公积金 | L1: 养老保险 | M1: 医疗保险 | N1: 失业保险 | O1: 个人所得税 | P1: 应发合计 | Q1: 应扣合计 | R1: 实发合计
A2: A001 | B2: =VLOOKUP(A2,员工资料!A:C,2,FALSE) -> 男 | C2: =VLOOKUP(A2,员工资料!A:C,3,FALSE) -> 合同工 | D2: 5482 | E2: 288 | F2: 240 | G2: 1029 | H2: 357 | I2: 497 | J2: 100 | K2: 631.44 | L2: 473.58 | M2: 50.22 | N2: 177.84 | O2: =IF(P2-SUM(K2:N2)<=2000,0,IF(P2-SUM(K2:N2)<=4000,0+(P2-SUM(K2:N2)-2000)*0.03,IF(P2-SUM(K2:N2)<=8000,0+2000*0.03+(P2-SUM(K2:N2)-4000)*0.08,0+2000*0.03+4000*0.08+(P2-SUM(K2:N2)-8000)*0.1))) -> 256.7936 | P2: =D2+E2+F2+G2+H2+I2-J2 -> 7793 | Q2: =K2+L2+M2+N2+O2 -> 1589.8736 | R2: =P2-Q2 -> 6203.1264
A3: A006 | B3: =VLOOKUP(A3,员工资料!A:C,2,FALSE) -> 女 | C3: =VLOOKUP(A3,员工资料!A:C,3,FALSE) -> 合同工 | D3: 3509 | E3: 236 | F3: 150 | G3: 1202 | H3: 521 | I3: 256 | J3: 81 | K3: 469.92 | L3: 352.44 | M3: 47.3 | N3: 170.32 | O3: =IF(P3-SUM(K3:N3)<=2000,0,IF(P3-SUM(K3:N3)<=4000,0+(P3-SUM(K3:N3)-2000)*0.03,IF(P3-SUM(K3:N3)<=8000,0+2000*0.03+(P3-SUM(K3:N3)-4000)*0.08,0+2000*0.03+4000*0.08+(P3-SUM(K3:N3)-8000)*0.1))) -> 120.2416 | P3: =D3+E3+F3+G3+H3+I3-J3 -> 5793 | Q3: =K3+L3+M3+N3+O3 -> 1160.2216 | R3: =P3-Q3 -> 4632.7784
A4: A007 | B4: =VLOOKUP(A4,员工资料!A:C,2,FALSE) -> 男 | C4: =VLOOKUP(A4,员工资料!A:C,3,FALSE) -> 劳务工 | D4: 4449 | E4: 452 | F4: 170 | G4: 957 | H4: 500 | I4: 557 | J4: 16 | K4: 566.8 | L4: 425.1 | M4: 52.72 | N4: 174.72 | O4: =IF(P4-SUM(K4:N4)<=2000,0,IF(P4-SUM(K4:N4)<=4000,0+(P4-SUM(K4:N4)-2000)*0.03,IF(P4-SUM(K4:N4)<=8000,0+2000*0.03+(P4-SUM(K4:N4)-4000)*0.08,0+2000*0.03+4000*0.08+(P4-SUM(K4:N4)-8000)*0.1))) -> 207.9728 | P4: =D4+E4+F4+G4+H4+I4-J4 -> 7069 | Q4: =K4+L4+M4+N4+O4 -> 1427.3128 | R4: =P4-Q4 -> 5641.6872
A5: A008 | B5: =VLOOKUP(A5,员工资料!A:C,2,FALSE) -> 男 | C5: =VLOOKUP(A5,员工资料!A:C,3,FALSE) -> 合同工 | D5: 3863 | E5: 486 | F5: 290 | G5: 1048 | H5: 283 | I5: 515 | J5: 62 | K5: 518.8 | L5: 389.1 | M5: 53.68 | N5: 175.84 | O5: =IF(P5-SUM(K5:N5)<=2000,0,IF(P5-SUM(K5:N5)<=4000,0+(P5-SUM(K5:N5)-2000)*0.03,IF(P5-SUM(K5:N5)<=8000,0+2000*0.03+(P5-SUM(K5:N5)-4000)*0.08,0+2000*0.03+4000*0.08+(P5-SUM(K5:N5)-8000)*0.1))) -> 162.8464 | P5: =D5+E5+F5+G5+H5+I5-J5 -> 6423 | Q5: =K5+L5+M5+N5+O5 -> 1300.2664 | R5: =P5-Q5 -> 5122.7336
A6: A009 | B6: =VLOOKUP(A6,员工资料!A:C,2,FALSE) -> 男 | C6: =VLOOKUP(A6,员工资料!A:C,3,FALSE) -> 劳务工 | D6: 3600 | E6: 257 | F6: 110 | G6: 1077 | H6: 285 | I6: 364 | J6: 53 | K6: 455.44 | L6: 341.58 | M6: 42.92 | N6: 151.12 | O6: =IF(P6-SUM(K6:N6)<=2000,0,IF(P6-SUM(K6:N6)<=4000,0+(P6-SUM(K6:N6)-2000)*0.03,IF(P6-SUM(K6:N6)<=8000,0+2000*0.03+(P6-SUM(K6:N6)-4000)*0.08,0+2000*0.03+4000*0.08+(P6-SUM(K6:N6)-8000)*0.1))) -> 111.9152 | P6: =D6+E6+F6+G6+H6+I6-J6 -> 5640 | Q6: =K6+L6+M6+N6+O6 -> 1102.9752 | R6: =P6-Q6 -> 4537.0248
A7: A010 | B7: =VLOOKUP(A7,员工资料!A:C,2,FALSE) -> 男 | C7: =VLOOKUP(A7,员工资料!A:C,3,FALSE) -> 合同工 | D7: 5325 | E7: 583 | F7: 250 | G7: 866 | H7: 452 | I7: 470 | J7: 29 | K7: 635.68 | L7: 476.76 | M7: 52.42 | N7: 163.04 | O7: =IF(P7-SUM(K7:N7)<=2000,0,IF(P7-SUM(K7:N7)<=4000,0+(P7-SUM(K7:N7)-2000)*0.03,IF(P7-SUM(K7:N7)<=8000,0+2000*0.03+(P7-SUM(K7:N7)-4000)*0.08,0+2000*0.03+4000*0.08+(P7-SUM(K7:N7)-8000)*0.1))) -> 267.128 | P7: =D7+E7+F7+G7+H7+I7-J7 -> 7917 | Q7: =K7+L7+M7+N7+O7 -> 1595.028 | R7: =P7-Q7 -> 6321.972
A8: A016 | B8: =VLOOKUP(A8,员工资料!A:C,2,FALSE) -> 女 | C8: =VLOOKUP(A8,员工资料!A:C,3,FALSE) -> 合同工 | D8: 6265 | E8: 442 | F8: 120 | G8: 833 | H8: 542 | I8: 232 | J8: 130 | K8: 674.72 | L8: 506.04 | M8: 44.34 | N8: 146.24 | O8: =IF(P8-SUM(K8:N8)<=2000,0,IF(P8-SUM(K8:N8)<=4000,0+(P8-SUM(K8:N8)-2000)*0.03,IF(P8-SUM(K8:N8)<=8000,0+2000*0.03+(P8-SUM(K8:N8)-4000)*0.08,0+2000*0.03+4000*0.08+(P8-SUM(K8:N8)-8000)*0.1))) -> 294.6128 | P8: =D8+E8+F8+G8+H8+I8-J8 -> 8304 | Q8: =K8+L8+M8+N8+O8 -> 1665.9528 | R8: =P8-Q8 -> 6638.0472
A9: A003 | B9: =VLOOKUP(A9,员工资料!A:C,2,FALSE) -> 女 | C9: =VLOOKUP(A9,员工资料!A:C,3,FALSE) -> 劳务工 | D9: 3121 | E9: 260 | F9: 250 | G9: 822 | H9: 589 | I9: 536 | J9: 0 | K9: 446.24 | L9: 334.68 | M9: 49.14 | N9: 175.76 | O9: =IF(P9-SUM(K9:N9)<=2000,0,IF(P9-SUM(K9:N9)<=4000,0+(P9-SUM(K9:N9)-2000)*0.03,IF(P9-SUM(K9:N9)<=8000,0+2000*0.03+(P9-SUM(K9:N9)-4000)*0.08,0+2000*0.03+4000*0.08+(P9-SUM(K9:N9)-8000)*0.1))) -> 105.7744 | P9: =D9+E9+F9+G9+H9+I9-J9 -> 5578 | Q9: =K9+L9+M9+N9+O9 -> 1111.5944 | R9: =P9-Q9 -> 4466.4056
A10: A004 | B10: =VLOOKUP(A10,员工资料!A:C,2,FALSE) -> 男 | C10: =VLOOKUP(A10,员工资料!A:C,3,FALSE) -> 劳务工 | D10: 4277 | E10: 519 | F10: 90 | G10: 733 | H10: 424 | I10: 305 | J10: 54 | K10: 507.84 | L10: 380.88 | M10: 41.42 | N10: 127.28 | O10: =IF(P10-SUM(K10:N10)<=2000,0,IF(P10-SUM(K10:N10)<=4000,0+(P10-SUM(K10:N10)-2000)*0.03,IF(P10-SUM(K10:N10)<=8000,0+2000*0.03+(P10-SUM(K10:N10)-4000)*0.08,0+2000*0.03+4000*0.08+(P10-SUM(K10:N10)-8000)*0.1))) -> 158.9264 | P10: =D10+E10+F10+G10+H10+I10-J10 -> 6294 | Q10: =K10+L10+M10+N10+O10 -> 1216.3464 | R10: =P10-Q10 -> 5077.6536
A11: A002 | B11: =VLOOKUP(A11,员工资料!A:C,2,FALSE) -> 男 | C11: =VLOOKUP(A11,员工资料!A:C,3,FALSE) -> 合同工 | D11: 4056 | E11: 523 | F11: 180 | G11: 995 | H11: 420 | I11: 418 | J11: 76 | K11: 527.36 | L11: 395.52 | M11: 52.24 | N11: 167.12 | O11: =IF(P11-SUM(K11:N11)<=2000,0,IF(P11-SUM(K11:N11)<=4000,0+(P11-SUM(K11:N11)-2000)*0.03,IF(P11-SUM(K11:N11)<=8000,0+2000*0.03+(P11-SUM(K11:N11)-4000)*0.08,0+2000*0.03+4000*0.08+(P11-SUM(K11:N11)-8000)*0.1))) -> 169.9008 | P11: =D11+E11+F11+G11+H11+I11-J11 -> 6516 | Q11: =K11+L11+M11+N11+O11 -> 1312.1408 | R11: =P11-Q11 -> 5203.8592
A12: A015 | B12: =VLOOKUP(A12,员工资料!A:C,2,FALSE) -> 男 | C12: =VLOOKUP(A12,员工资料!A:C,3,FALSE) -> 劳务工 | D12: 4073 | E12: 287 | F12: 70 | G12: 1100 | H12: 493 | I12: 248 | J12: 51 | K12: 501.68 | L12: 376.26 | M12: 44.74 | N12: 156.96 | O12: =IF(P12-SUM(K12:N12)<=2000,0,IF(P12-SUM(K12:N12)<=4000,0+(P12-SUM(K12:N12)-2000)*0.03,IF(P12-SUM(K12:N12)<=8000,0+2000*0.03+(P12-SUM(K12:N12)-4000)*0.08,0+2000*0.03+4000*0.08+(P12-SUM(K12:N12)-8000)*0.1))) -> 151.2288 | P12: =D12+E12+F12+G12+H12+I12-J12 -> 6220 | Q12: =K12+L12+M12+N12+O12 -> 1230.8688 | R12: =P12-Q12 -> 4989.1312
A13: A011 | B13: =VLOOKUP(A13,员工资料!A:C,2,FALSE) -> 女 | C13: =VLOOKUP(A13,员工资料!A:C,3,FALSE) -> 劳务工 | D13: 3656 | E13: 252 | F13: 200 | G13: 1015 | H13: 403 | I13: 361 | J13: 46 | K13: 470.96 | L13: 353.22 | M13: 44.62 | N13: 158.32 | O13: =IF(P13-SUM(K13:N13)<=2000,0,IF(P13-SUM(K13:N13)<=4000,0+(P13-SUM(K13:N13)-2000)*0.03,IF(P13-SUM(K13:N13)<=8000,0+2000*0.03+(P13-SUM(K13:N13)-4000)*0.08,0+2000*0.03+4000*0.08+(P13-SUM(K13:N13)-8000)*0.1))) -> 125.1104 | P13: =D13+E13+F13+G13+H13+I13-J13 -> 5841 | Q13: =K13+L13+M13+N13+O13 -> 1152.2304 | R13: =P13-Q13 -> 4688.7696
... A17: A005 | B17: =VLOOKUP(A17,员工资料!A:C,2,FALSE) -> 女 | C17: =VLOOKUP(A17,员工资料!A:C,3,FALSE) -> 合同工 | D17: 4763 | E17: 227 | F17: 120 | G17: 952 | H17: 404 | I17: 569 | J17: 87 | K17: 562.8 | L17: 422.1 | M17: 45.44 | N17: 170.56 | O17: =IF(P17-SUM(K17:N17)<=2000,0,IF(P17-SUM(K17:N17)<=4000,0+(P17-SUM(K17:N17)-2000)*0.03,IF(P17-SUM(K17:N17)<=8000,0+2000*0.03+(P17-SUM(K17:N17)-4000)*0.08,0+2000*0.03+4000*0.08+(P17-SUM(K17:N17)-8000)*0.1))) -> 199.768 | P17: =D17+E17+F17+G17+H17+I17-J17 -> 6948 | Q17: =K17+L17+M17+N17+O17 -> 1400.668 | R17: =P17-Q17 -> 5547.332

Sheet 7月
A1: 姓名 | B1: 性别 | C1: 合同种类 | D1: 基本工资 | E1: 岗位工资 | F1: 工龄工资 | G1: 补贴 | H1: 医疗补助 | I1: 奖金 | J1: 考勤扣款 | K1: 住房公积金 | L1: 养老保险 | M1: 医疗保险 | N1: 失业保险 | O1: 个人所得税 | P1: 应发合计 | Q1: 应扣合计 | R1: 实发合计
A2: A001 | B2: =VLOOKUP(A2,员工资料!A:C,2,FALSE) -> 男 | C2: =VLOOKUP(A2,员工资料!A:C,3,FALSE) -> 合同工 | D2: 2779 | E2: 531 | F2: 90 | G2: 847 | H2: 376 | I2: 497 | J2: 100 | K2: 409.6 | L2: 307.2 | M2: 48.82 | N2: 152.8 | O2: =IF(P2-SUM(K2:N2)<=2000,0,IF(P2-SUM(K2:N2)<=4000,0+(P2-SUM(K2:N2)-2000)*0.03,IF(P2-SUM(K2:N2)<=8000,0+2000*0.03+(P2-SUM(K2:N2)-4000)*0.08,0+2000*0.03+4000*0.08+(P2-SUM(K2:N2)-8000)*0.1))) -> 68.1264 | P2: =D2+E2+F2+G2+H2+I2-J2 -> 5020 | Q2: =K2+L2+M2+N2+O2 -> 986.5464 | R2: =P2-Q2 -> 4033.4536
A3: A002 | B3: =VLOOKUP(A3,员工资料!A:C,2,FALSE) -> 男 | C3: =VLOOKUP(A3,员工资料!A:C,3,FALSE) -> 合同工 | D3: 5793 | E3: 354 | F3: 160 | G3: 950 | H3: 554 | I3: 215 | J3: 81 | K3: 642.08 | L3: 481.56 | M3: 44.66 | N3: 150.32 | O3: =IF(P3-SUM(K3:N3)<=2000,0,IF(P3-SUM(K3:N3)<=4000,0+(P3-SUM(K3:N3)-2000)*0.03,IF(P3-SUM(K3:N3)<=8000,0+2000*0.03+(P3-SUM(K3:N3)-4000)*0.08,0+2000*0.03+4000*0.08+(P3-SUM(K3:N3)-8000)*0.1))) -> 270.1104 | P3: =D3+E3+F3+G3+H3+I3-J3 -> 7945 | Q3: =K3+L3+M3+N3+O3 -> 1588.7304 | R3: =P3-Q3 -> 6356.2696
A4: A005 | B4: =VLOOKUP(A4,员工资料!A:C,2,FALSE) -> 女 | C4: =VLOOKUP(A4,员工资料!A:C,3,FALSE) -> 合同工 | D4: 2598 | E4: 584 | F4: 220 | G4: 1105 | H4: 306 | I4: 514 | J4: 16 | K4: 426.16 | L4: 319.62 | M4: 54.58 | N4: 171.6 | O4: =IF(P4-SUM(K4:N4)<=2000,0,IF(P4-SUM(K4:N4)<=4000,0+(P4-SUM(K4:N4)-2000)*0.03,IF(P4-SUM(K4:N4)<=8000,0+2000*0.03+(P4-SUM(K4:N4)-4000)*0.08,0+2000*0.03+4000*0.08+(P4-SUM(K4:N4)-8000)*0.1))) -> 87.1232 | P4: =D4+E4+F4+G4+H4+I4-J4 -> 5311 | Q4: =K4+L4+M4+N4+O4 -> 1059.0832 | R4: =P4-Q4 -> 4251.9168
A5: A006 | B5: =VLOOKUP(A5,员工资料!A:C,2,FALSE) -> 女 | C5: =VLOOKUP(A5,员工资料!A:C,3,FALSE) -> 合同工 | D5: 3976 | E5: 458 | F5: 120 | G5: 828 | H5: 443 | I5: 245 | J5: 62 | K5: 485.6 | L5: 364.2 | M5: 43.12 | N5: 135.84 | O5: =IF(P5-SUM(K5:N5)<=2000,0,IF(P5-SUM(K5:N5)<=4000,0+(P5-SUM(K5:N5)-2000)*0.03,IF(P5-SUM(K5:N5)<=8000,0+2000*0.03+(P5-SUM(K5:N5)-4000)*0.08,0+2000*0.03+4000*0.08+(P5-SUM(K5:N5)-8000)*0.1))) -> 138.3392 | P5: =D5+E5+F5+G5+H5+I5-J5 -> 6008 | Q5: =K5+L5+M5+N5+O5 -> 1167.0992 | R5: =P5-Q5 -> 4840.9008
A6: A008 | B6: =VLOOKUP(A6,员工资料!A:C,2,FALSE) -> 男 | C6: =VLOOKUP(A6,员工资料!A:C,3,FALSE) -> 合同工 | D6: 2720 | E6: 581 | F6: 50 | G6: 1048 | H6: 445 | I6: 589 | J6: 53 | K6: 434.64 | L6: 325.98 | M6: 55.32 | N6: 174.8 | O6: =IF(P6-SUM(K6:N6)<=2000,0,IF(P6-SUM(K6:N6)<=4000,0+(P6-SUM(K6:N6)-2000)*0.03,IF(P6-SUM(K6:N6)<=8000,0+2000*0.03+(P6-SUM(K6:N6)-4000)*0.08,0+2000*0.03+4000*0.08+(P6-SUM(K6:N6)-8000)*0.1))) -> 91.1408 | P6: =D6+E6+F6+G6+H6+I6-J6 -> 5380 | Q6: =K6+L6+M6+N6+O6 -> 1081.8808 | R6: =P6-Q6 -> 4298.1192
A7: A010 | B7: =VLOOKUP(A7,员工资料!A:C,2,FALSE) -> 男 | C7: =VLOOKUP(A7,员工资料!A:C,3,FALSE) -> 合同工 | D7: 6537 | E7: 342 | F7: 150 | G7: 1130 | H7: 307 | I7: 501 | J7: 29 | K7: 717.36 | L7: 538.02 | M7: 48.6 | N7: 167.04 | O7: =IF(P7-SUM(K7:N7)<=2000,0,IF(P7-SUM(K7:N7)<=4000,0+(P7-SUM(K7:N7)-2000)*0.03,IF(P7-SUM(K7:N7)<=8000,0+2000*0.03+(P7-SUM(K7:N7)-4000)*0.08,0+2000*0.03+4000*0.08+(P7-SUM(K7:N7)-8000)*0.1))) -> 337.3584 | P7: =D7+E7+F7+G7+H7+I7-J7 -> 8938 | Q7: =K7+L7+M7+N7+O7 -> 1808.3784 | R7: =P7-Q7 -> 7129.6216
A8: A016 | B8: =VLOOKUP(A8,员工资料!A:C,2,FALSE) -> 女 | C8: =VLOOKUP(A8,员工资料!A:C,3,FALSE) -> 合同工 | D8: 3031 | E8: 478 | F8: 210 | G8: 807 | H8: 425 | I8: 282 | J8: 130 | K8: 418.64 | L8: 313.98 | M8: 45 | N8: 146 | O8: =IF(P8-SUM(K8:N8)<=2000,0,IF(P8-SUM(K8:N8)<=4000,0+(P8-SUM(K8:N8)-2000)*0.03,IF(P8-SUM(K8:N8)<=8000,0+2000*0.03+(P8-SUM(K8:N8)-4000)*0.08,0+2000*0.03+4000*0.08+(P8-SUM(K8:N8)-8000)*0.1))) -> 74.3504 | P8: =D8+E8+F8+G8+H8+I8-J8 -> 5103 | Q8: =K8+L8+M8+N8+O8 -> 997.9704 | R8: =P8-Q8 -> 4105.0296
A9: A003 | B9: =VLOOKUP(A9,员工资料!A:C,2,FALSE) -> 女 | C9: =VLOOKUP(A9,员工资料!A:C,3,FALSE) -> 劳务工 | D9: 5152 | E9: 376 | F9: 100 | G9: 753 | H9: 224 | I9: 306 | J9: 0 | K9: 552.88 | L9: 414.66 | M9: 35.18 | N9: 110.64 | O9: =IF(P9-SUM(K9:N9)<=2000,0,IF(P9-SUM(K9:N9)<=4000,0+(P9-SUM(K9:N9)-2000)*0.03,IF(P9-SUM(K9:N9)<=8000,0+2000*0.03+(P9-SUM(K9:N9)-4000)*0.08,0+2000*0.03+4000*0.08+(P9-SUM(K9:N9)-8000)*0.1))) -> 203.8112 | P9: =D9+E9+F9+G9+H9+I9-J9 -> 6911 | Q9: =K9+L9+M9+N9+O9 -> 1317.1712 | R9: =P9-Q9 -> 5593.8288
A10: A004 | B10: =VLOOKUP(A10,员工资料!A:C,2,FALSE) -> 男 | C10: =VLOOKUP(A10,员工资料!A:C,3,FALSE) -> 劳务工 | D10: 6347 | E10: 206 | F10: 260 | G10: 668 | H10: 551 | I10: 242 | J10: 54 | K10: 661.92 | L10: 496.44 | M10: 38.54 | N10: 140.8 | O10: =IF(P10-SUM(K10:N10)<=2000,0,IF(P10-SUM(K10:N10)<=4000,0+(P10-SUM(K10:N10)-2000)*0.03,IF(P10-SUM(K10:N10)<=8000,0+2000*0.03+(P10-SUM(K10:N10)-4000)*0.08,0+2000*0.03+4000*0.08+(P10-SUM(K10:N10)-8000)*0.1))) -> 290.584 | P10: =D10+E10+F10+G10+H10+I10-J10 -> 8220 | Q10: =K10+L10+M10+N10+O10 -> 1628.284 | R10: =P10-Q10 -> 6591.716
A11: A007 | B11: =VLOOKUP(A11,员工资料!A:C,2,FALSE) -> 男 | C11: =VLOOKUP(A11,员工资料!A:C,3,FALSE) -> 劳务工 | D11: 5775 | E11: 309 | F11: 90 | G11: 1048 | H11: 201 | I11: 465 | J11: 76 | K11: 631.04 | L11: 473.28 | M11: 43.78 | N11: 150.4 | O11: =IF(P11-SUM(K11:N11)<=2000,0,IF(P11-SUM(K11:N11)<=4000,0+(P11-SUM(K11:N11)-2000)*0.03,IF(P11-SUM(K11:N11)<=8000,0+2000*0.03+(P11-SUM(K11:N11)-4000)*0.08,0+2000*0.03+4000*0.08+(P11-SUM(K11:N11)-8000)*0.1))) -> 261.08 | P11: =D11+E11+F11+G11+H11+I11-J11 -> 7812 | Q11: =K11+L11+M11+N11+O11 -> 1559.58 | R11: =P11-Q11 -> 6252.42
A12: A009 | B12: =VLOOKUP(A12,员工资料!A:C,2,FALSE) -> 男 | C12: =VLOOKUP(A12,员工资料!A:C,3,FALSE) -> 劳务工 | D12: 6554 | E12: 541 | F12: 70 | G12: 986 | H12: 453 | I12: 550 | J12: 51 | K12: 732.32 | L12: 549.24 | M12: 52.78 | N12: 168.8 | O12: =IF(P12-SUM(K12:N12)<=2000,0,IF(P12-SUM(K12:N12)<=4000,0+(P12-SUM(K12:N12)-2000)*0.03,IF(P12-SUM(K12:N12)<=8000,0+2000*0.03+(P12-SUM(K12:N12)-4000)*0.08,0+2000*0.03+4000*0.08+(P12-SUM(K12:N12)-8000)*0.1))) -> 347.9888 | P12: =D12+E12+F12+G12+H12+I12-J12 -> 9103 | Q12: =K12+L12+M12+N12+O12 -> 1851.1288 | R12: =P12-Q12 -> 7251.8712
A13: A011 | B13: =VLOOKUP(A13,员工资料!A:C,2,FALSE) -> 女 | C13: =VLOOKUP(A13,员工资料!A:C,3,FALSE) -> 劳务工 | D13: 3180 | E13: 286 | F13: 80 | G13: 759 | H13: 562 | I13: 412 | J13: 46 | K13: 422.32 | L13: 316.74 | M13: 41.98 | N13: 145.04 | O13: =IF(P13-SUM(K13:N13)<=2000,0,IF(P13-SUM(K13:N13)<=4000,0+(P13-SUM(K13:N13)-2000)*0.03,IF(P13-SUM(K13:N13)<=8000,0+2000*0.03+(P13-SUM(K13:N13)-4000)*0.08,0+2000*0.03+4000*0.08+(P13-SUM(K13:N13)-8000)*0.1))) -> 84.5536 | P13: =D13+E13+F13+G13+H13+I13-J13 -> 5233 | Q13: =K13+L13+M13+N13+O13 -> 1010.6336 | R13: =P13-Q13 -> 4222.3664
... A17: A015 | B17: =VLOOKUP(A17,员工资料!A:C,2,FALSE) -> 男 | C17: =VLOOKUP(A17,员工资料!A:C,3,FALSE) -> 劳务工 | D17: 3570 | E17: 311 | F17: 280 | G17: 1194 | H17: 412 | I17: 284 | J17: 87 | K17: 484.08 | L17: 363.06 | M17: 49.62 | N17: 180.56 | O17: =IF(P17-SUM(K17:N17)<=2000,0,IF(P17-SUM(K17:N17)<=4000,0+(P17-SUM(K17:N17)-2000)*0.03,IF(P17-SUM(K17:N17)<=8000,0+2000*0.03+(P17-SUM(K17:N17)-4000)*0.08,0+2000*0.03+4000*0.08+(P17-SUM(K17:N17)-8000)*0.1))) -> 130.9344 | P17: =D17+E17+F17+G17+H17+I17-J17 -> 5964 | Q17: =K17+L17+M17+N17+O17 -> 1208.2544 | R17: =P17-Q17 -> 4755.7456

Sheet 8月
A1: 姓名 | B1: 性别 | C1: 合同种类 | D1: 基本工资 | E1: 岗位工资 | F1: 工龄工资 | G1: 补贴 | H1: 医疗补助 | I1: 奖金 | J1: 考勤扣款 | K1: 住房公积金 | L1: 养老保险 | M1: 医疗保险 | N1: 失业保险 | O1: 个人所得税 | P1: 应发合计 | Q1: 应扣合计 | R1: 实发合计
A2: A001 | B2: =VLOOKUP(A2,员工资料!A:C,2,FALSE) -> 男 | C2: =VLOOKUP(A2,员工资料!A:C,3,FALSE) -> 合同工 | D2: 3350 | E2: 236 | F2: 120 | G2: 984 | H2: 371 | I2: 594 | J2: 100 | K2: 452.4 | L2: 339.3 | M2: 48.1 | N2: 173.52 | O2: =IF(P2-SUM(K2:N2)<=2000,0,IF(P2-SUM(K2:N2)<=4000,0+(P2-SUM(K2:N2)-2000)*0.03,IF(P2-SUM(K2:N2)<=8000,0+2000*0.03+(P2-SUM(K2:N2)-4000)*0.08,0+2000*0.03+4000*0.08+(P2-SUM(K2:N2)-8000)*0.1))) -> 103.3344 | P2: =D2+E2+F2+G2+H2+I2-J2 -> 5555 | Q2: =K2+L2+M2+N2+O2 -> 1116.6544 | R2: =P2-Q2 -> 4438.3456
A3: A006 | B3: =VLOOKUP(A3,员工资料!A:C,2,FALSE) -> 女 | C3: =VLOOKUP(A3,员工资料!A:C,3,FALSE) -> 合同工 | D3: 6585 | E3: 578 | F3: 140 | G3: 855 | H3: 474 | I3: 383 | J3: 81 | K3: 721.2 | L3: 540.9 | M3: 48.6 | N3: 148.16 | O3: =IF(P3-SUM(K3:N3)<=2000,0,IF(P3-SUM(K3:N3)<=4000,0+(P3-SUM(K3:N3)-2000)*0.03,IF(P3-SUM(K3:N3)<=8000,0+2000*0.03+(P3-SUM(K3:N3)-4000)*0.08,0+2000*0.03+4000*0.08+(P3-SUM(K3:N3)-8000)*0.1))) -> 338.0112 | P3: =D3+E3+F3+G3+H3+I3-J3 -> 8934 | Q3: =K3+L3+M3+N3+O3 -> 1796.8712 | R3: =P3-Q3 -> 7137.1288
A4: A007 | B4: =VLOOKUP(A4,员工资料!A:C,2,FALSE) -> 男 | C4: =VLOOKUP(A4,员工资料!A:C,3,FALSE) -> 劳务工 | D4: 5516 | E4: 278 | F4: 230 | G4: 1113 | H4: 233 | I4: 405 | J4: 16 | K4: 622 | L4: 466.5 | M4: 45.18 | N4: 158.48 | O4: =IF(P4-SUM(K4:N4)<=2000,0,IF(P4-SUM(K4:N4)<=4000,0+(P4-SUM(K4:N4)-2000)*0.03,IF(P4-SUM(K4:N4)<=8000,0+2000*0.03+(P4-SUM(K4:N4)-4000)*0.08,0+2000*0.03+4000*0.08+(P4-SUM(K4:N4)-8000)*0.1))) -> 257.3472 | P4: =D4+E4+F4+G4+H4+I4-J4 -> 7759 | Q4: =K4+L4+M4+N4+O4 -> 1549.5072 | R4: =P4-Q4 -> 6209.4928
A5: A008 | B5: =VLOOKUP(A5,员工资料!A:C,2,FALSE) -> 男 | C5: =VLOOKUP(A5,员工资料!A:C,3,FALSE) -> 合同工 | D5: 3348 | E5: 422 | F5: 140 | G5: 764 | H5: 370 | I5: 472 | J5: 62 | K5: 441.28 | L5: 330.96 | M5: 44.6 | N5: 144.64 | O5: =IF(P5-SUM(K5:N5)<=2000,0,IF(P5-SUM(K5:N5)<=4000,0+(P5-SUM(K5:N5)-2000)*0.03,IF(P5-SUM(K5:N5)<=8000,0+2000*0.03+(P5-SUM(K5:N5)-4000)*0.08,0+2000*0.03+4000*0.08+(P5-SUM(K5:N5)-8000)*0.1))) -> 99.4016 | P5: =D5+E5+F5+G5+H5+I5-J5 -> 5454 | Q5: =K5+L5+M5+N5+O5 -> 1060.8816 | R5: =P5-Q5 -> 4393.1184
A6: A009 | B6: =VLOOKUP(A6,员工资料!A:C,2,FALSE) -> 男 | C6: =VLOOKUP(A6,员工资料!A:C,3,FALSE) -> 劳务工 | D6: 6426 | E6: 546 | F6: 170 | G6: 1131 | H6: 317 | I6: 226 | J6: 53 | K6: 705.28 | L6: 528.96 | M6: 48.86 | N6: 151.76 | O6: =IF(P6-SUM(K6:N6)<=2000,0,IF(P6-SUM(K6:N6)<=4000,0+(P6-SUM(K6:N6)-2000)*0.03,IF(P6-SUM(K6:N6)<=8000,0+2000*0.03+(P6-SUM(K6:N6)-4000)*0.08,0+2000*0.03+4000*0.08+(P6-SUM(K6:N6)-8000)*0.1))) -> 326.2512 | P6: =D6+E6+F6+G6+H6+I6-J6 -> 8763 | Q6: =K6+L6+M6+N6+O6 -> 1761.1112 | R6: =P6-Q6 -> 7001.8888
A7: A010 | B7: =VLOOKUP(A7,员工资料!A:C,2,FALSE) -> 男 | C7: =VLOOKUP(A7,员工资料!A:C,3,FALSE) -> 合同工 | D7: 2991 | E7: 252 | F7: 110 | G7: 1148 | H7: 250 | I7: 224 | J7: 29 | K7: 398 | L7: 298.5 | M7: 39.68 | N7: 138.56 | O7: =IF(P7-SUM(K7:N7)<=2000,0,IF(P7-SUM(K7:N7)<=4000,0+(P7-SUM(K7:N7)-2000)*0.03,IF(P7-SUM(K7:N7)<=8000,0+2000*0.03+(P7-SUM(K7:N7)-4000)*0.08,0+2000*0.03+4000*0.08+(P7-SUM(K7:N7)-8000)*0.1))) -> 65.7008 | P7: =D7+E7+F7+G7+H7+I7-J7 -> 4946 | Q7: =K7+L7+M7+N7+O7 -> 940.4408 | R7: =P7-Q7 -> 4005.5592
A8: A016 | B8: =VLOOKUP(A8,员工资料!A:C,2,FALSE) -> 女 | C8: =VLOOKUP(A8,员工资料!A:C,3,FALSE) -> 合同工 | D8: 3886 | E8: 429 | F8: 290 | G8: 907 | H8: 364 | I8: 508 | J8: 130 | K8: 510.72 | L8: 383.04 | M8: 50.92 | N8: 173.6 | O8: =IF(P8-SUM(K8:N8)<=2000,0,IF(P8-SUM(K8:N8)<=4000,0+(P8-SUM(K8:N8)-2000)*0.03,IF(P8-SUM(K8:N8)<=8000,0+2000*0.03+(P8-SUM(K8:N8)-4000)*0.08,0+2000*0.03+4000*0.08+(P8-SUM(K8:N8)-8000)*0.1))) -> 150.8576 | P8: =D8+E8+F8+G8+H8+I8-J8 -> 6254 | Q8: =K8+L8+M8+N8+O8 -> 1269.1376 | R8: =P8-Q8 -> 4984.8624
A9: A003 | B9: =VLOOKUP(A9,员工资料!A:C,2,FALSE) -> 女 | C9: =VLOOKUP(A9,员工资料!A:C,3,FALSE) -> 劳务工 | D9: 6551 | E9: 532 | F9: 160 | G9: 1063 | H9: 319 | I9: 554 | J9: 0 | K9: 734.32 | L9: 550.74 | M9: 52.56 | N9: 167.68 | O9: =IF(P9-SUM(K9:N9)<=2000,0,IF(P9-SUM(K9:N9)<=4000,0+(P9-SUM(K9:N9)-2000)*0.03,IF(P9-SUM(K9:N9)<=8000,0+2000*0.03+(P9-SUM(K9:N9)-4000)*0.08,0+2000*0.03+4000*0.08+(P9-SUM(K9:N9)-8000)*0.1))) -> 353.896 | P9: =D9+E9+F9+G9+H9+I9-J9 -> 9179 | Q9: =K9+L9+M9+N9+O9 -> 1859.196 | R9: =P9-Q9 -> 7319.804
A10: A004 | B10: =VLOOKUP(A10,员工资料!A:C,2,FALSE) -> 男 | C10: =VLOOKUP(A10,员工资料!A:C,3,FALSE) -> 劳务工 | D10: 2755 | E10: 416 | F10: 190 | G10: 1191 | H10: 313 | I10: 265 | J10: 54 | K10: 410.4 | L10: 307.8 | M10: 47.5 | N10: 159.84 | O10: =IF(P10-SUM(K10:N10)<=2000,0,IF(P10-SUM(K10:N10)<=4000,0+(P10-SUM(K10:N10)-2000)*0.03,IF(P10-SUM(K10:N10)<=8000,0+2000*0.03+(P10-SUM(K10:N10)-4000)*0.08,0+2000*0.03+4000*0.08+(P10-SUM(K10:N10)-8000)*0.1))) -> 72.0368 | P10: =D10+E10+F10+G10+H10+I10-J10 -> 5076 | Q10: =K10+L10+M10+N10+O10 -> 997.5768 | R10: =P10-Q10 -> 4078.4232
A11: A002 | B11: =VLOOKUP(A11,员工资料!A:C,2,FALSE) -> 男 | C11: =VLOOKUP(A11,员工资料!A:C,3,FALSE) -> 合同工 | D11: 5865 | E11: 206 | F11: 300 | G11: 1151 | H11: 469 | I11: 301 | J11: 76 | K11: 663.36 | L11: 497.52 | M11: 50.06 | N11: 183.76 | O11: =IF(P11-SUM(K11:N11)<=2000,0,IF(P11-SUM(K11:N11)<=4000,0+(P11-SUM(K11:N11)-2000)*0.03,IF(P11-SUM(K11:N11)<=8000,0+2000*0.03+(P11-SUM(K11:N11)-4000)*0.08,0+2000*0.03+4000*0.08+(P11-SUM(K11:N11)-8000)*0.1))) -> 285.704 | P11: =D11+E11+F11+G11+H11+I11-J11 -> 8216 | Q11: =K11+L11+M11+N11+O11 -> 1680.404 | R11: =P11-Q11 -> 6535.596
A12: A015 | B12: =VLOOKUP(A12,员工资料!A:C,2,FALSE) -> 男 | C12: =VLOOKUP(A12,员工资料!A:C,3,FALSE) -> 劳务工 | D12: 5338 | E12: 569 | F12: 160 | G12: 771 | H12: 485 | I12: 526 | J12: 51 | K12: 627.92 | L12: 470.94 | M12: 51 | N12: 159.44 | O12: =IF(P12-SUM(K12:N12)<=2000,0,IF(P12-SUM(K12:N12)<=4000,0+(P12-SUM(K12:N12)-2000)*0.03,IF(P12-SUM(K12:N12)<=8000,0+2000*0.03+(P12-SUM(K12:N12)-4000)*0.08,0+2000*0.03+4000*0.08+(P12-SUM(K12:N12)-8000)*0.1))) -> 259.096 | P12: =D12+E12+F12+G12+H12+I12-J12 -> 7798 | Q12: =K12+L12+M12+N12+O12 -> 1568.396 | R12: =P12-Q12 -> 6229.604
A13: A011 | B13: =VLOOKUP(A13,员工资料!A:C,2,FALSE) -> 女 | C13: =VLOOKUP(A13,员工资料!A:C,3,FALSE) -> 劳务工 | D13: 6428 | E13: 561 | F13: 250 | G13: 1264 | H13: 335 | I13: 518 | J13: 46 | K13: 748.48 | L13: 561.36 | M13: 58.56 | N13: 189.36 | O13: =IF(P13-SUM(K13:N13)<=2000,0,IF(P13-SUM(K13:N13)<=4000,0+(P13-SUM(K13:N13)-2000)*0.03,IF(P13-SUM(K13:N13)<=8000,0+2000*0.03+(P13-SUM(K13:N13)-4000)*0.08,0+2000*0.03+4000*0.08+(P13-SUM(K13:N13)-8000)*0.1))) -> 360.1792 | P13: =D13+E13+F13+G13+H13+I13-J13 -> 9310 | Q13: =K13+L13+M13+N13+O13 -> 1917.9392 | R13: =P13-Q13 -> 7392.0608
... A17: A005 | B17: =VLOOKUP(A17,员工资料!A:C,2,FALSE) -> 女 | C17: =VLOOKUP(A17,员工资料!A:C,3,FALSE) -> 合同工 | D17: 4631 | E17: 597 | F17: 200 | G17: 1278 | H17: 459 | I17: 517 | J17: 87 | K17: 614.56 | L17: 460.92 | M17: 61.02 | N17: 203.28 | O17: =IF(P17-SUM(K17:N17)<=2000,0,IF(P17-SUM(K17:N17)<=4000,0+(P17-SUM(K17:N17)-2000)*0.03,IF(P17-SUM(K17:N17)<=8000,0+2000*0.03+(P17-SUM(K17:N17)-4000)*0.08,0+2000*0.03+4000*0.08+(P17-SUM(K17:N17)-8000)*0.1))) -> 240.4176 | P17: =D17+E17+F17+G17+H17+I17-J17 -> 7595 | Q17: =K17+L17+M17+N17+O17 -> 1580.1976 | R17: =P17-Q17 -> 6014.8024

Sheet 9月
A1: 姓名 | B1: 性别 | C1: 合同种类 | D1: 基本工资 | E1: 岗位工资 | F1: 工龄工资 | G1: 补贴 | H1: 医疗补助 | I1: 奖金 | J1: 考勤扣款 | K1: 住房公积金 | L1: 养老保险 | M1: 医疗保险 | N1: 失业保险 | O1: 个人所得税 | P1: 应发合计 | Q1: 应扣合计 | R1: 实发合计 | S1: 实发排行榜
A2: A001 | B2: =VLOOKUP(A2,员工资料!A:C,2,FALSE) -> 男 | C2: =VLOOKUP(A2,员工资料!A:C,3,FALSE) -> 合同工 | D2: 5596 | E2: 315 | F2: 110 | G2: 1071 | H2: 464 | I2: 221 | J2: 100 | K2: 622.16 | L2: 466.62 | M2: 45.62 | N2: 157.28 | O2: =IF(P2-SUM(K2:N2)<=2000,0,IF(P2-SUM(K2:N2)<=4000,0+(P2-SUM(K2:N2)-2000)*0.03,IF(P2-SUM(K2:N2)<=8000,0+2000*0.03+(P2-SUM(K2:N2)-4000)*0.08,0+2000*0.03+4000*0.08+(P2-SUM(K2:N2)-8000)*0.1))) -> 250.8256 | P2: =D2+E2+F2+G2+H2+I2-J2 -> 7677 | Q2: =K2+L2+M2+N2+O2 -> 1542.5056 | R2: =P2-Q2 -> 6134.4944 | S2: ="第"&RANK(R2,$R$2:$R$21)&"名" -> 第8名
A3: A002 | B3: =VLOOKUP(A3,员工资料!A:C,2,FALSE) -> 男 | C3: =VLOOKUP(A3,员工资料!A:C,3,FALSE) -> 合同工 | D3: 2980 | E3: 578 | F3: 100 | G3: 955 | H3: 486 | I3: 397 | J3: 81 | K3: 439.68 | L3: 329.76 | M3: 50.32 | N3: 155.04 | O3: =IF(P3-SUM(K3:N3)<=2000,0,IF(P3-SUM(K3:N3)<=4000,0+(P3-SUM(K3:N3)-2000)*0.03,IF(P3-SUM(K3:N3)<=8000,0+2000*0.03+(P3-SUM(K3:N3)-4000)*0.08,0+2000*0.03+4000*0.08+(P3-SUM(K3:N3)-8000)*0.1))) -> 95.216 | P3: =D3+E3+F3+G3+H3+I3-J3 -> 5415 | Q3: =K3+L3+M3+N3+O3 -> 1070.016 | R3: =P3-Q3 -> 4344.984 | S3: ="第"&RANK(R3,$R$2:$R$21)&"名" -> 第18名
A4: A003 | B4: =VLOOKUP(A4,员工资料!A:C,2,FALSE) -> 女 | C4: =VLOOKUP(A4,员工资料!A:C,3,FALSE) -> 劳务工 | D4: 2812 | E4: 456 | F4: 130 | G4: 866 | H4: 504 | I4: 209 | J4: 0 | K4: 398.16 | L4: 298.62 | M4: 43.3 | N4: 136.72 | O4: =IF(P4-SUM(K4:N4)<=2000,0,IF(P4-SUM(K4:N4)<=4000,0+(P4-SUM(K4:N4)-2000)*0.03,IF(P4-SUM(K4:N4)<=8000,0+2000*0.03+(P4-SUM(K4:N4)-4000)*0.08,0+2000*0.03+4000*0.08+(P4-SUM(K4:N4)-8000)*0.1))) -> 68.016 | P4: =D4+E4+F4+G4+H4+I4-J4 -> 4977 | Q4: =K4+L4+M4+N4+O4 -> 944.816 | R4: =P4-Q4 -> 4032.184 | S4: ="第"&RANK(R4,$R$2:$R$21)&"名" -> 第19名
A5: A004 | B5: =VLOOKUP(A5,员工资料!A:C,2,FALSE) -> 男 | C5: =VLOOKUP(A5,员工资料!A:C,3,FALSE) -> 劳务工 | D5: 4146 | E5: 348 | F5: 160 | G5: 1169 | H5: 447 | I5: 328 | J5: 54 | K5: 527.84 | L5: 395.88 | M5: 49.04 | N5: 171.44 | O5: =IF(P5-SUM(K5:N5)<=2000,0,IF(P5-SUM(K5:N5)<=4000,0+(P5-SUM(K5:N5)-2000)*0.03,IF(P5-SUM(K5:N5)<=8000,0+2000*0.03+(P5-SUM(K5:N5)-4000)*0.08,0+2000*0.03+4000*0.08+(P5-SUM(K5:N5)-8000)*0.1))) -> 171.984 | P5: =D5+E5+F5+G5+H5+I5-J5 -> 6544 | Q5: =K5+L5+M5+N5+O5 -> 1316.184 | R5: =P5-Q5 -> 5227.816 | S5: ="第"&RANK(R5,$R$2:$R$21)&"名" -> 第14名
